Workbook
Name MesEntrada: 'Configuración'!$C$4
Name InicioCiclo: 'Configuración'!$C$5
Name FechaRef: 'Configuración'!$C$6
Name SemanaActual: 'Configuración'!$C$7
Name SemanaManual: 'Configuración'!$C$8
Name DiasAlerta: 'Configuración'!$C$9
Name ObsObligatoria: 'Configuración'!$C$10
Name MetaFinal: 'Configuración'!$C$11
Name HistInicio: 'Configuración'!$C$12
Name PlanRef: 'Configuración'!$C$15:$C$18
Name ListaPuestos: 'Configuración'!$B$22:$B$25
Name ListaEstados: 'Configuración'!$B$28:$B$30
Name ListaSemanas: 'Configuración'!$B$33:$B$36
Name ListaSiNo: 'Configuración'!$B$39:$B$40
Name rFLim_RO: 'Cronograma R. Operacional'!$AS$5:$AS$1000
Name rIni_RO: 'Cronograma R. Operacional'!$E$5:$E$1000
Name rLim_RO: 'Cronograma R. Operacional'!$F$5:$F$1000
Name rDname_RO: 'Cronograma R. Operacional'!$AP$5:$AP$1000
Name rPeso_RO: 'Cronograma R. Operacional'!$AL$5:$AL$1000
Name rPesoEscrito_RO: 'Cronograma R. Operacional'!$H$5:$H$1000
Name rS1_RO: 'Cronograma R. Operacional'!$I$5:$I$1000
Name rS2_RO: 'Cronograma R. Operacional'!$J$5:$J$1000
Name rS3_RO: 'Cronograma R. Operacional'!$K$5:$K$1000
Name rS4_RO: 'Cronograma R. Operacional'!$L$5:$L$1000
Name rAvance_RO: 'Cronograma R. Operacional'!$M$5:$M$1000
Name rEstado_RO: 'Cronograma R. Operacional'!$N$5:$N$1000
Name rAlerta_RO: 'Cronograma R. Operacional'!$O$5:$O$1000
Name rValid_RO: 'Cronograma R. Operacional'!$R$5:$R$1000
Name rMes_RO: 'Cronograma R. Operacional'!$S$5:$S$1000
Name rOrden_RO: 'Cronograma R. Operacional'!$T$5:$T$1000
Name rTipo_RO: 'Cronograma R. Operacional'!$V$5:$V$1000
Name rEf1_RO: 'Cronograma R. Operacional'!$AH$5:$AH$1000
Name rEf2_RO: 'Cronograma R. Operacional'!$AI$5:$AI$1000
Name rEf3_RO: 'Cronograma R. Operacional'!$AJ$5:$AJ$1000
Name rEf4_RO: 'Cronograma R. Operacional'!$AK$5:$AK$1000
Name rAct_RO: 'Cronograma R. Operacional'!$C$5:$C$1000
Name rDeleg_RO: 'Cronograma R. Operacional'!$D$5:$D$1000
Name rDkey_RO: 'Cronograma R. Operacional'!$AO$5:$AO$1000
Name rFLim_RN: 'Cronograma R. Normativo'!$AS$5:$AS$1000
Name rIni_RN: 'Cronograma R. Normativo'!$E$5:$E$1000
Name rLim_RN: 'Cronograma R. Normativo'!$F$5:$F$1000
Name rDname_RN: 'Cronograma R. Normativo'!$AP$5:$AP$1000
Name rPeso_RN: 'Cronograma R. Normativo'!$AL$5:$AL$1000
Name rPesoEscrito_RN: 'Cronograma R. Normativo'!$H$5:$H$1000
Name rS1_RN: 'Cronograma R. Normativo'!$I$5:$I$1000
Name rS2_RN: 'Cronograma R. Normativo'!$J$5:$J$1000
Name rS3_RN: 'Cronograma R. Normativo'!$K$5:$K$1000
Name rS4_RN: 'Cronograma R. Normativo'!$L$5:$L$1000
Name rAvance_RN: 'Cronograma R. Normativo'!$M$5:$M$1000
Name rEstado_RN: 'Cronograma R. Normativo'!$N$5:$N$1000
Name rAlerta_RN: 'Cronograma R. Normativo'!$O$5:$O$1000
Name rValid_RN: 'Cronograma R. Normativo'!$R$5:$R$1000
Name rMes_RN: 'Cronograma R. Normativo'!$S$5:$S$1000
Name rOrden_RN: 'Cronograma R. Normativo'!$T$5:$T$1000
Name rTipo_RN: 'Cronograma R. Normativo'!$V$5:$V$1000
Name rEf1_RN: 'Cronograma R. Normativo'!$AH$5:$AH$1000
Name rEf2_RN: 'Cronograma R. Normativo'!$AI$5:$AI$1000
Name rEf3_RN: 'Cronograma R. Normativo'!$AJ$5:$AJ$1000
Name rEf4_RN: 'Cronograma R. Normativo'!$AK$5:$AK$1000
Name rAct_RN: 'Cronograma R. Normativo'!$C$5:$C$1000

Sheet Dashboard - Consolidado
B1: Dashboard Consolidado – Gestión de Riesgos · Ciclo mensual de 4 semanas
B2: Período: | C2: =MesCiclo | D2: Semana actual: | E2: =SemanaActual | F2: Fecha de corte: | G2: =FechaRef | H2: Se actualiza solo con las hojas «Cronograma …» y «Actividades …» de cada puesto. El período y la semana se calculan con la fecha de hoy (ver Configuración).
B4: Avance general de las actividades | E4: Meta de cumplimiento | H4: Macroactividades registradas | K4: Actividades completadas
B5: =IF('Calculos'!$E$8,'Calculos'!$F$8,"No definitivo") | E5: =MetaFinal | H5: ='Calculos'!$B$11 | K5: ='Calculos'!$N$8
B6: =IF('Calculos'!$E$8,"Promedio simple de los 4 puestos",IF('Calculos'!$C$8=0,"Ningún puesto con datos válidos","Provisional "&TEXT('Calculos'!$D$8,"0%")&" ("&'Calculos'!$C$8&" de 4 puestos válidos)")) | E6: Al cierre de la Semana 4 | H6: ="En los 4 cronogramas · "&'Calculos'!$U$8&" delegada(s) por la jefatura" | K6: =IF('Calculos'!$B$11=0,"—",TEXT('Calculos'!$N$8/'Calculos'!$B$11,"0%")&" del total")
B8: Actividades en curso | E8: Actividades pendientes | H8: Puestos que alcanzaron el 100% | K8: Actividades con alertas
B9: ='Calculos'!$O$8 | E9: ='Calculos'!$P$8 | H9: ='Calculos'!$B$12 | K9: ='Calculos'!$R$8
B10: Avance > 0% y < 100% | E10: ="De todas las actividades, vencidas: "&'Calculos'!$Q$8 | H10: Con ponderación válida | K10: ="Próximas a vencer: "&'Calculos'!$B$13
B12: =IF('Calculos'!$E$8,"Avance general vs meta 100%","Avance PROVISIONAL vs meta") | C12: =IF('Calculos'!$E$8,'Calculos'!$F$8,N('Calculos'!$D$8)) | G12: =IF('Calculos'!$B$11=0,"⚠ No hay actividades registradas en este mes. Cada puesto registra sus actividades y pesos en su hoja «Cronograma …».",IF(NOT('Calculos'!$E$8),"⚠ Avance general NO definitivo: "&(4-'Calculos'!$C$8)&" puesto(s) sin actividades válidas o con pesos que no suman 100%.",IF('Calculos'!$M$8,"Actividades del mes: ¡Enhorabuena, completado anticipadamente!",IF('Calculos'!$L$8,"Actividades del mes completadas: meta del 100% alcanzada.","Actividades del mes en ejecución – Semana "&SemanaActual&" de 4."))))
B14: Avance individual por puesto (ponderado por el peso de cada actividad)
B15: Puesto | C15: Avance ponderado | D15: Progreso | E15: Total actividades | F15: Completadas | G15: En curso | H15: Pendientes | I15: Vencidas | J15: Con alertas | K15: Estado general | L15: Mensaje de finalización
B16: ='Calculos'!A4 | C16: =IF('Calculos'!B4=0,"Sin actividades",IF(NOT('Calculos'!E4),"Revisar pesos",'Calculos'!F4)) | D16: =IF(ISNUMBER(C16),C16,0) | E16: ='Calculos'!B4 | F16: ='Calculos'!N4 | G16: ='Calculos'!O4 | H16: ='Calculos'!P4 | I16: ='Calculos'!Q4 | J16: ='Calculos'!R4 | K16: =IF('Calculos'!B4=0,"Sin actividades",IF(NOT('Calculos'!E4),"Pesos no válidos",IF('Calculos'!L4,"Completado",IF('Calculos'!F4>0,"En curso","Pendiente")))) | L16: =IF('Calculos'!B4=0,"⚠ Registrar actividades",IF(NOT('Calculos'!E4),"⚠ Corregir pesos no válidos",IF('Calculos'!M4,"¡Enhorabuena, completado anticipadamente!",IF('Calculos'!L4,"Completado","En ejecución")))) | P16: R. Operacional
B17: ='Calculos'!A5 | C17: =IF('Calculos'!B5=0,"Sin actividades",IF(NOT('Calculos'!E5),"Revisar pesos",'Calculos'!F5)) | D17: =IF(ISNUMBER(C17),C17,0) | E17: ='Calculos'!B5 | F17: ='Calculos'!N5 | G17: ='Calculos'!O5 | H17: ='Calculos'!P5 | I17: ='Calculos'!Q5 | J17: ='Calculos'!R5 | K17: =IF('Calculos'!B5=0,"Sin actividades",IF(NOT('Calculos'!E5),"Pesos no válidos",IF('Calculos'!L5,"Completado",IF('Calculos'!F5>0,"En curso","Pendiente")))) | L17: =IF('Calculos'!B5=0,"⚠ Registrar actividades",IF(NOT('Calculos'!E5),"⚠ Corregir pesos no válidos",IF('Calculos'!M5,"¡Enhorabuena, completado anticipadamente!",IF('Calculos'!L5,"Completado","En ejecución")))) | P17: R. Normativo
B18: ='Calculos'!A6 | C18: =IF('Calculos'!B6=0,"Sin actividades",IF(NOT('Calculos'!E6),"Revisar pesos",'Calculos'!F6)) | D18: =IF(ISNUMBER(C18),C18,0) | E18: ='Calculos'!B6 | F18: ='Calculos'!N6 | G18: ='Calculos'!O6 | H18: ='Calculos'!P6 | I18: ='Calculos'!Q6 | J18: ='Calculos'!R6 | K18: =IF('Calculos'!B6=0,"Sin actividades",IF(NOT('Calculos'!E6),"Pesos no válidos",IF('Calculos'!L6,"Completado",IF('Calculos'!F6>0,"En curso","Pendiente")))) | L18: =IF('Calculos'!B6=0,"⚠ Registrar actividades",IF(NOT('Calculos'!E6),"⚠ Corregir pesos no válidos",IF('Calculos'!M6,"¡Enhorabuena, completado anticipadamente!",IF('Calculos'!L6,"Completado","En ejecución")))) | P18: R. Financiero
B19: ='Calculos'!A7 | C19: =IF('Calculos'!B7=0,"Sin actividades",IF(NOT('Calculos'!E7),"Revisar pesos",'Calculos'!F7)) | D19: =IF(ISNUMBER(C19),C19,0) | E19: ='Calculos'!B7 | F19: ='Calculos'!N7 | G19: ='Calculos'!O7 | H19: ='Calculos'!P7 | I19: ='Calculos'!Q7 | J19: ='Calculos'!R7 | K19: =IF('Calculos'!B7=0,"Sin actividades",IF(NOT('Calculos'!E7),"Pesos no válidos",IF('Calculos'!L7,"Completado",IF('Calculos'!F7>0,"En curso","Pendiente")))) | L19: =IF('Calculos'!B7=0,"⚠ Registrar actividades",IF(NOT('Calculos'!E7),"⚠ Corregir pesos no válidos",IF('Calculos'!M7,"¡Enhorabuena, completado anticipadamente!",IF('Calculos'!L7,"Completado","En ejecución")))) | P19: Asistente Técnico
B20: Total actividades | C20: =IF('Calculos'!$E$8,'Calculos'!$F$8,"No definitivo") | D20: =IF(ISNUMBER(C20),C20,0) | E20: ='Calculos'!B11 | F20: ='Calculos'!N8 | G20: ='Calculos'!O8 | H20: ='Calculos'!P8 | I20: ='Calculos'!Q8 | J20: ='Calculos'!R8 | K20: =IF('Calculos'!$E$8,"Promedio 4 puestos","No definitivo") | L20: =IF(NOT('Calculos'!$E$8),"⚠ Completar configuración de todos los puestos",IF('Calculos'!$M$8,"¡Enhorabuena, completado anticipadamente!",IF('Calculos'!$L$8,"Completado","En ejecución")))
B22: Seguimiento semanal: avance acumulado ponderado e incremento semanal
C23: Avance ACUMULADO ponderado al cierre de cada semana | H23: INCREMENTO respecto a la semana anterior (puntos %) | L23: Brecha vs meta 100%
B24: Puesto / Indicador | C24: Semana 1 | D24: Semana 2 | E24: Semana 3 | F24: Semana 4 | H24: Semana 1 | I24: Semana 2 | J24: Semana 3 | K24: Semana 4 | L24: Pendiente para la meta
B25: ='Calculos'!A4 | C25: =IF(NOT('Calculos'!G$10),"",IF('Calculos'!$E4,'Calculos'!G4,"–")) | D25: =IF(NOT('Calculos'!H$10),"",IF('Calculos'!$E4,'Calculos'!H4,"–")) | E25: =IF(NOT('Calculos'!I$10),"",IF('Calculos'!$E4,'Calculos'!I4,"–")) | F25: =IF(NOT('Calculos'!J$10),"",IF('Calculos'!$E4,'Calculos'!J4,"–")) | H25: =IF(ISNUMBER(C25),C25,"") | I25: =IF(AND(ISNUMBER(D25),ISNUMBER(C25)),D25-C25,"") | J25: =IF(AND(ISNUMBER(E25),ISNUMBER(D25)),E25-D25,"") | K25: =IF(AND(ISNUMBER(F25),ISNUMBER(E25)),F25-E25,"") | L25: =IFERROR(MetaFinal-LOOKUP(2,1/ISNUMBER(C25:F25),C25:F25),"") | P25: R. Operacional
B26: ='Calculos'!A5 | C26: =IF(NOT('Calculos'!G$10),"",IF('Calculos'!$E5,'Calculos'!G5,"–")) | D26: =IF(NOT('Calculos'!H$10),"",IF('Calculos'!$E5,'Calculos'!H5,"–")) | E26: =IF(NOT('Calculos'!I$10),"",IF('Calculos'!$E5,'Calculos'!I5,"–")) | F26: =IF(NOT('Calculos'!J$10),"",IF('Calculos'!$E5,'Calculos'!J5,"–")) | H26: =IF(ISNUMBER(C26),C26,"") | I26: =IF(AND(ISNUMBER(D26),ISNUMBER(C26)),D26-C26,"") | J26: =IF(AND(ISNUMBER(E26),ISNUMBER(D26)),E26-D26,"") | K26: =IF(AND(ISNUMBER(F26),ISNUMBER(E26)),F26-E26,"") | L26: =IFERROR(MetaFinal-LOOKUP(2,1/ISNUMBER(C26:F26),C26:F26),"") | P26: R. Normativo
B27: ='Calculos'!A6 | C27: =IF(NOT('Calculos'!G$10),"",IF('Calculos'!$E6,'Calculos'!G6,"–")) | D27: =IF(NOT('Calculos'!H$10),"",IF('Calculos'!$E6,'Calculos'!H6,"–")) | E27: =IF(NOT('Calculos'!I$10),"",IF('Calculos'!$E6,'Calculos'!I6,"–")) | F27: =IF(NOT('Calculos'!J$10),"",IF('Calculos'!$E6,'Calculos'!J6,"–")) | H27: =IF(ISNUMBER(C27),C27,"") | I27: =IF(AND(ISNUMBER(D27),ISNUMBER(C27)),D27-C27,"") | J27: =IF(AND(ISNUMBER(E27),ISNUMBER(D27)),E27-D27,"") | K27: =IF(AND(ISNUMBER(F27),ISNUMBER(E27)),F27-E27,"") | L27: =IFERROR(MetaFinal-LOOKUP(2,1/ISNUMBER(C27:F27),C27:F27),"") | P27: R. Financiero
B28: ='Calculos'!A7 | C28: =IF(NOT('Calculos'!G$10),"",IF('Calculos'!$E7,'Calculos'!G7,"–")) | D28: =IF(NOT('Calculos'!H$10),"",IF('Calculos'!$E7,'Calculos'!H7,"–")) | E28: =IF(NOT('Calculos'!I$10),"",IF('Calculos'!$E7,'Calculos'!I7,"–")) | F28: =IF(NOT('Calculos'!J$10),"",IF('Calculos'!$E7,'Calculos'!J7,"–")) | H28: =IF(ISNUMBER(C28),C28,"") | I28: =IF(AND(ISNUMBER(D28),ISNUMBER(C28)),D28-C28,"") | J28: =IF(AND(ISNUMBER(E28),ISNUMBER(D28)),E28-D28,"") | K28: =IF(AND(ISNUMBER(F28),ISNUMBER(E28)),F28-E28,"") | L28: =IFERROR(MetaFinal-LOOKUP(2,1/ISNUMBER(C28:F28),C28:F28),"") | P28: Asistente Técnico
B29: Avance general de las actividades | C29: =IF(NOT('Calculos'!G$10),"",IF('Calculos'!$E$8,'Calculos'!G8,"n/d")) | D29: =IF(NOT('Calculos'!H$10),"",IF('Calculos'!$E$8,'Calculos'!H8,"n/d")) | E29: =IF(NOT('Calculos'!I$10),"",IF('Calculos'!$E$8,'Calculos'!I8,"n/d")) | F29: =IF(NOT('Calculos'!J$10),"",IF('Calculos'!$E$8,'Calculos'!J8,"n/d")) | H29: =IF(ISNUMBER(C29),C29,"") | I29: =IF(AND(ISNUMBER(D29),ISNUMBER(C29)),D29-C29,"") | J29: =IF(AND(ISNUMBER(E29),ISNUMBER(D29)),E29-D29,"") | K29: =IF(AND(ISNUMBER(F29),ISNUMBER(E29)),F29-E29,"") | L29: =IFERROR(MetaFinal-LOOKUP(2,1/ISNUMBER(C29:F29),C29:F29),"")
B30: Plan de referencia (supuesto) | C30: =INDEX(PlanRef,1) | D30: =INDEX(PlanRef,2) | E30: =INDEX(PlanRef,3) | F30: =INDEX(PlanRef,4) | P30: Plan de referencia
B31: Meta final | C31: =MetaFinal | D31: =MetaFinal | E31: =MetaFinal | F31: =MetaFinal
B33: Lectura: el acumulado NO se suma entre semanas; el incremento es la diferencia entre semanas consecutivas. «–» = puesto sin configuración válida; «n/d» = avance general no definitivo; celda vacía = semana aún no alcanzada. Ámbar = acumulado por debajo del plan de referencia.
B68: Control de calidad de datos
B69: Verificación | G69: Casos | H69: Resultado | I69: Acción sugerida
B70: Puestos sin actividades registradas | G70: =COUNTIF('Calculos'!B4:B7,0) | H70: =IF(G70=0,"✔ OK",IF("crit"="warn","● Atención","⚠ Revisar")) | I70: Registrar al menos una macroactividad por puesto.
B71: Puestos con pesos no válidos (fuera de 0–100%) | G71: =COUNTIFS('Calculos'!B4:B7,">0",'Calculos'!E4:E7,FALSE) | H71: =IF(G71=0,"✔ OK",IF("crit"="warn","● Atención","⚠ Revisar")) | I71: Corregir el peso (los pesos se ajustan solos a 100%).
B72: Actividades con peso vacío o fuera de rango | G72: =SUMPRODUCT((rMes_RO=MesCiclo)*((ISNUMBER(SEARCH("Peso vacío",rValid_RO))+ISNUMBER(SEARCH("Peso fuera de rango",rValid_RO)))>0))+SUMPRODUCT((rMes_RN=MesCiclo)*((ISNUMBER(SEARCH("Peso vacío",rValid_RN))+ISNUMBER(SEARCH("Peso fuera de rango",rValid_RN)))>0))+SUMPRODUCT((rMes_RF=MesCiclo)*((ISNUMBER(SEARCH("Peso vacío",rValid_RF))+ISNUMBER(SEARCH("Peso fuera de rango",rValid_RF)))>0))+SUMPRODUCT((rMes_ATR=MesCiclo)*((ISNUMBER(SEARCH("Peso vacío",rValid_ATR))+ISNUMBER(SEARCH("Peso fuera de rango",rValid_ATR)))>0)) | H72: =IF(G72=0,"✔ OK",IF("crit"="warn","● Atención","⚠ Revisar")) | I72: Ingresar un peso entre 0% y 100% (mayor que 0).
B73: Actividades sin fecha límite | G73: =SUMPRODUCT((rMes_RO=MesCiclo)*((ISNUMBER(SEARCH("Sin fecha límite",rValid_RO)))>0))+SUMPRODUCT((rMes_RN=MesCiclo)*((ISNUMBER(SEARCH("Sin fecha límite",rValid_RN)))>0))+SUMPRODUCT((rMes_RF=MesCiclo)*((ISNUMBER(SEARCH("Sin fecha límite",rValid_RF)))>0))+SUMPRODUCT((rMes_ATR=MesCiclo)*((ISNUMBER(SEARCH("Sin fecha límite",rValid_ATR)))>0)) | H73: =IF(G73=0,"✔ OK",IF("crit"="warn","● Atención","⚠ Revisar")) | I73: Registrar la fecha límite.
B74: Fechas incoherentes o no válidas (incluye sin fecha de inicio) | G74: =SUMPRODUCT((rMes_RO=MesCiclo)*((ISNUMBER(SEARCH("Inicio posterior",rValid_RO))+ISNUMBER(SEARCH("Fecha no válida",rValid_RO))+ISNUMBER(SEARCH("Sin fecha de inicio",rValid_RO)))>0))+SUMPRODUCT((rMes_RN=MesCiclo)*((ISNUMBER(SEARCH("Inicio posterior",rValid_RN))+ISNUMBER(SEARCH("Fecha no válida",rValid_RN))+ISNUMBER(SEARCH("Sin fecha de inicio",rValid_RN)))>0))+SUMPRODUCT((rMes_RF=MesCiclo)*((ISNUMBER(SEARCH("Inicio posterior",rValid_RF))+ISNUMBER(SEARCH("Fecha no válida",rValid_RF))+ISNUMBER(SEARCH("Sin fecha de inicio",rValid_RF)))>0))+SUMPRODUCT((rMes_ATR=MesCiclo)*((ISNUMBER(SEARCH("Inicio posterior",rValid_ATR))+ISNUMBER(SEARCH("Fecha no válida",rValid_ATR))+ISNUMBER(SEARCH("Sin fecha de inicio",rValid_ATR)))>0)) | H74: =IF(G74=0,"✔ OK",IF("crit"="warn","● Atención","⚠ Revisar")) | I74: La fecha de inicio debe ser anterior o igual a la fecha límite.
B75: Porcentajes de avance > 100%, < 0% o no numéricos | G75: =SUMPRODUCT((rMes_RO=MesCiclo)*((ISNUMBER(SEARCH("Avance fuera de rango",rValid_RO)))>0))+SUMPRODUCT((rMes_RN=MesCiclo)*((ISNUMBER(SEARCH("Avance fuera de rango",rValid_RN)))>0))+SUMPRODUCT((rMes_RF=MesCiclo)*((ISNUMBER(SEARCH("Avance fuera de rango",rValid_RF)))>0))+SUMPRODUCT((rMes_ATR=MesCiclo)*((ISNUMBER(SEARCH("Avance fuera de rango",rValid_ATR)))>0)) | H75: =IF(G75=0,"✔ OK",IF("crit"="warn","● Atención","⚠ Revisar")) | I75: Corregir: los avances deben estar entre 0% y 100%.
B76: Avance semanal menor que el de una semana anterior | G76: =SUMPRODUCT((rMes_RO=MesCiclo)*((ISNUMBER(SEARCH("decreciente",rValid_RO)))>0))+SUMPRODUCT((rMes_RN=MesCiclo)*((ISNUMBER(SEARCH("decreciente",rValid_RN)))>0))+SUMPRODUCT((rMes_RF=MesCiclo)*((ISNUMBER(SEARCH("decreciente",rValid_RF)))>0))+SUMPRODUCT((rMes_ATR=MesCiclo)*((ISNUMBER(SEARCH("decreciente",rValid_ATR)))>0)) | H76: =IF(G76=0,"✔ OK",IF("crit"="warn","● Atención","⚠ Revisar")) | I76: Revisar: el avance es acumulado y no debería disminuir.
B77: Actividades vencidas no completadas | G77: ='Calculos'!Q8 | H77: =IF(G77=0,"✔ OK",IF("crit"="warn","● Atención","⚠ Revisar")) | I77: Actualizar avance o reprogramar con justificación en Observaciones.
B78: Actividades próximas a vencer (no completadas) | G78: ='Calculos'!B13 | H78: =IF(G78=0,"✔ OK",IF("warn"="warn","● Atención","⚠ Revisar")) | I78: Alerta preventiva: priorizar seguimiento.
B79: Filas con datos pero sin nombre de macroactividad | G79: =SUMPRODUCT((rMes_RO=MesCiclo)*((ISNUMBER(SEARCH("Macroactividad vacía",rValid_RO)))>0))+SUMPRODUCT((rMes_RN=MesCiclo)*((ISNUMBER(SEARCH("Macroactividad vacía",rValid_RN)))>0))+SUMPRODUCT((rMes_RF=MesCiclo)*((ISNUMBER(SEARCH("Macroactividad vacía",rValid_RF)))>0))+SUMPRODUCT((rMes_ATR=MesCiclo)*((ISNUMBER(SEARCH("Macroactividad vacía",rValid_ATR)))>0)) | H79: =IF(G79=0,"✔ OK",IF("crit"="warn","● Atención","⚠ Revisar")) | I79: Escribir el nombre de la actividad.
B80: Actividades vencidas sin observación que explique el incumplimiento | G80: =SUMPRODUCT((rMes_RO=MesCiclo)*((ISNUMBER(SEARCH("sin observación",rValid_RO)))>0))+SUMPRODUCT((rMes_RN=MesCiclo)*((ISNUMBER(SEARCH("sin observación",rValid_RN)))>0))+SUMPRODUCT((rMes_RF=MesCiclo)*((ISNUMBER(SEARCH("sin observación",rValid_RF)))>0))+SUMPRODUCT((rMes_ATR=MesCiclo)*((ISNUMBER(SEARCH("sin observación",rValid_ATR)))>0)) | H80: =IF(G80=0,"✔ OK",IF("crit"="warn","● Atención","⚠ Revisar")) | I80: Escribir en Observaciones por qué no se cumplió y la nueva fecha prevista.
...

Sheet Administración
A1: Administración (jefatura) – Actividades de la jefatura
A2: Llene solo las celdas GRIS SUAVE; las AZUL CLARO son automáticas. En «Tipo» elija Macroactividad o Subactividad: las subactividades van en las filas de ABAJO de su macroactividad (se ven con ↳); a cada una póngale su avance en las semanas o, cuando la termine, su FECHA DE CUMPLIMIENTO, y la macroactividad se llena sola. Cuando termine algo, escriba la FECHA DE CUMPLIMIENTO: queda al 100% y ya no aparece vencido. Si quiere registrar avances parciales, escriba en cada semana el % total logrado hasta esa semana. Cada mes agregue sus actividades debajo de las anteriores (no borre los meses pasados: quedan como historial).
A3: Llenar | B3: Automático | C3: Macroactividad (fila resaltada) | E3: Peso: macro = cuánto vale en el mes (opcional). Subactividad = su % dentro de la macro. Fechas de cada semana → | I3: =TEXT(DAY((InicioCiclo+0)),"00")&"/"&TEXT(MONTH((InicioCiclo+0)),"00")&" – "&TEXT(DAY((InicioCiclo+0)+6),"00")&"/"&TEXT(MONTH((InicioCiclo+0)+6),"00") | J3: =TEXT(DAY((InicioCiclo+7)),"00")&"/"&TEXT(MONTH((InicioCiclo+7)),"00")&" – "&TEXT(DAY((InicioCiclo+7)+6),"00")&"/"&TEXT(MONTH((InicioCiclo+7)+6),"00") | K3: =TEXT(DAY((InicioCiclo+14)),"00")&"/"&TEXT(MONTH((InicioCiclo+14)),"00")&" – "&TEXT(DAY((InicioCiclo+14)+6),"00")&"/"&TEXT(MONTH((InicioCiclo+14)+6),"00") | L3: =TEXT(DAY((InicioCiclo+21)),"00")&"/"&TEXT(MONTH((InicioCiclo+21)),"00")&" – "&TEXT(DAY((InicioCiclo+21)+6),"00")&"/"&TEXT(MONTH((InicioCiclo+21)+6),"00") | M3: ="Plazos del mes: "&COUNTIFS($S$5:$S$1000,MesCiclo,$O$5:$O$1000,"Vencida*")&" vencida(s) · "&COUNTIFS($S$5:$S$1000,MesCiclo,$O$5:$O$1000,"Vence*")&" por vencer" | Q3: En «Delegar a» elija el puesto: la actividad le llega a su Cronograma y aquí verá su avance.
A4: N° | B4: Tipo | C4: Actividad | D4: Delegar a | E4: Fecha de inicio | F4: Fecha límite | G4: Fecha de cumplimiento | H4: Peso / % de la subactividad | I4: Avance Semana 1 (%) | J4: Avance Semana 2 (%) | K4: Avance Semana 3 (%) | L4: Avance Semana 4 (%) | M4: % de Avance Total Actual | N4: Estado | O4: Alerta de plazo | P4: Seguimiento de la delegación | Q4: Observaciones | R4: Revisión automática (alertas) | S4: Mes | T4: Orden en el mes (aux) | U4: Grupo (aux) | V4: Tipo (aux) | W4: N subactividades (aux) | X4: % efectivo de la subactividad (aux) | Y4: Avance propio (aux) | Z4: Propio S1 (aux) | AA4: Propio S2 (aux) | AB4: Propio S3 (aux) | AC4: Propio S4 (aux) | AD4: Sub cumplida S1 (aux) | AE4: Sub cumplida S2 (aux) | AF4: Sub cumplida S3 (aux) | AG4: Sub cumplida S4 (aux) | AH4: Efectivo S1 (aux) | AI4: Efectivo S2 (aux) | AJ4: Efectivo S3 (aux) | AK4: Efectivo S4 (aux) | AL4: Peso efectivo (aux) | AM4: Fila en el puesto (aux) | AN4: N° delegada en el mes (aux) | AO4: Clave delegada (aux) | AP4: Clave puesto-actividad (aux) | AQ4: Fila en Administración (aux) | AR4: Inicio efectivo (aux) | AS4: Límite efectivo (aux)
A5: =IF(NOT((COUNTA($B5:$D5)+COUNTA($G5:$H5)+COUNTA($Q5))>0),"",IF($V5="Macro",COUNTIFS($V$5:$V5,"Macro",$S$5:$S5,$S5),IF(N($U5)=0,"?",COUNTIFS(INDEX($V$5:$V$1000,1):INDEX($V$5:$V$1000,$U5-4),"Macro",INDEX($S$5:$S$1000,1):INDEX($S$5:$S$1000,$U5-4),INDEX($S$5:$S$1000,$U5-4))&"."&COUNTIFS($U$5:$U5,$U5,$V$5:$V5,"Sub")))) | I5: =IF(N($W5)=0,"",IF(AND($S5=MesCiclo,1>SemanaActual),"",MIN(1,SUMIFS(OFFSET($A$1,ROW(),29,1000-ROW(),1),OFFSET($A$1,ROW(),20,1000-ROW(),1),ROW(),OFFSET($A$1,ROW(),21,1000-ROW(),1),"Sub")))) | J5: =IF(N($W5)=0,"",IF(AND($S5=MesCiclo,2>SemanaActual),"",MIN(1,SUMIFS(OFFSET($A$1,ROW(),30,1000-ROW(),1),OFFSET($A$1,ROW(),20,1000-ROW(),1),ROW(),OFFSET($A$1,ROW(),21,1000-ROW(),1),"Sub")))) | K5: =IF(N($W5)=0,"",IF(AND($S5=MesCiclo,3>SemanaActual),"",MIN(1,SUMIFS(OFFSET($A$1,ROW(),31,1000-ROW(),1),OFFSET($A$1,ROW(),20,1000-ROW(),1),ROW(),OFFSET($A$1,ROW(),21,1000-ROW(),1),"Sub")))) | L5: =IF(N($W5)=0,"",IF(AND($S5=MesCiclo,4>SemanaActual),"",MIN(1,SUMIFS(OFFSET($A$1,ROW(),32,1000-ROW(),1),OFFSET($A$1,ROW(),20,1000-ROW(),1),ROW(),OFFSET($A$1,ROW(),21,1000-ROW(),1),"Sub")))) | M5: =IF(NOT((COUNTA($B5:$D5)+COUNTA($G5:$H5)+COUNTA($Q5))>0),"",IF(AND($D5<>"",$V5="Macro"),IF(N($AM5)>0,N(CHOOSE(MATCH($D5,ListaPuestos,0),INDEX('Cronograma R. Operacional'!$M$5:$M$1000,$AM5),INDEX('Cronograma R. Normativo'!$M$5:$M$1000,$AM5),INDEX('Cronograma R. Financiero'!$M$5:$M$1000,$AM5),INDEX('Cronograma Asistente Técnico'!$M$5:$M$1000,$AM5))),0),IF(ISNUMBER($G5),1,IF(N($W5)>0,MIN(1,SUMIFS($Y$5:$Y$1000,$U$5:$U$1000,ROW(),$V$5:$V$1000,"Sub")),$Y5)))) | N5: =IF(OR($M5="",$V5="Sub"),"",IF($M5>=1,"Completado",IF($M5>0,"En curso","Pendiente"))) | O5: =IF(NOT((COUNTA($B5:$D5)+COUNTA($G5:$H5)+COUNTA($Q5))>0),"",IF(AND(AND($D5<>"",$V5="Macro"),N($AM5)>0),CHOOSE(MATCH($D5,ListaPuestos,0),INDEX('Cronograma R. Operacional'!$O$5:$O$1000,$AM5),INDEX('Cronograma R. Normativo'!$O$5:$O$1000,$AM5),INDEX('Cronograma R. Financiero'!$O$5:$O$1000,$AM5),INDEX('Cronograma Asistente Técnico'!$O$5:$O$1000,$AM5))&"",IF(ISNUMBER($G5),IF(AND(ISNUMBER($AS5),$G5>$AS5),"Cumplida con "&($G5-$AS5)&IF($G5-$AS5=1," día"," días")&" de retraso","Cumplida"),IF(N($M5)>=1,"Cumplida",IF(NOT(ISNUMBER($AS5)),"Sin fecha límite",IF($AS5<FechaRef,"Vencida hace "&(FechaRef-$AS5)&IF(FechaRef-$AS5=1," día"," días"),IF($AS5=FechaRef,"Vence hoy",IF($AS5-FechaRef<=DiasAlerta,"Vence en "&($AS5-FechaRef)&IF($AS5-FechaRef=1," día"," días"),"En plazo")))))))) | P5: =IF(NOT((COUNTA($B5:$D5)+COUNTA($G5:$H5)+COUNTA($Q5))>0),"",IF($D5="","Propia",IF($V5<>"Macro","Solo se delegan macroactividades",IF(N($AM5)>0,"✔ Recibida por "&$D5,"⚠ "&$D5&" aún no la agrega")))) | R5: =IF(NOT((COUNTA($B5:$D5)+COUNTA($G5:$H5)+COUNTA($Q5))>0),"",IF((IF($C5="","Falta el nombre de la actividad"&" · ","")&IF(AND($V5="Sub",N($U5)=0),"Subactividad sin macroactividad arriba"&" · ","")&IF(AND($V5="Macro",$AR5=""),"Sin fecha de inicio"&" · ","")&IF(AND($V5="Macro",$AS5=""),"Sin fecha límite"&" · ","")&IF(AND(LEFT($C5,11)="[Jefatura] ",N($AQ5)=0),"No se encuentra en la hoja de la jefatura (elíjala de nuevo en la lista)"&" · ","")&IF(OR(AND($E5<>"",NOT(ISNUMBER($E5))),AND($F5<>"",NOT(ISNUMBER($F5))),AND($G5<>"",NOT(ISNUMBER($G5)))),"Fecha no válida"&" · ","")&IF(AND(ISNUMBER($AR5),ISNUMBER($AS5),$AR5>$AS5),"Inicio posterior a fecha límite"&" · ","")&IF(AND($V5="Macro",$H5<>"",OR(NOT(ISNUMBER($H5)),$H5<0,$H5>1)),"Peso fuera de rango"&" · ","")&IF(AND($V5="Sub",$H5<>"",OR(NOT(ISNUMBER($H5)),$H5<0,$H5>1)),"% de la subactividad fuera de rango 0-100%"&" · ","")&IF(AND(N($W5)>0,SUMIFS($H$5:$H$1000,$U$5:$U$1000,ROW(),$V$5:$V$1000,"Sub")>1.0001),"Las subactividades suman más de 100%"&" · ","")&IF(AND(N($W5)>0,OR(IF(ISNUMBER($I5),ROUND($I5,6)<>ROUND(MIN(1,SUMIFS($AD$5:$AD$1000,$U$5:$U$1000,ROW(),$V$5:$V$1000,"Sub")),6),FALSE),IF(ISNUMBER($J5),ROUND($J5,6)<>ROUND(MIN(1,SUMIFS($AE$5:$AE$1000,$U$5:$U$1000,ROW(),$V$5:$V$1000,"Sub")),6),FALSE),IF(ISNUMBER($K5),ROUND($K5,6)<>ROUND(MIN(1,SUMIFS($AF$5:$AF$1000,$U$5:$U$1000,ROW(),$V$5:$V$1000,"Sub")),6),FALSE),IF(ISNUMBER($L5),ROUND($L5,6)<>ROUND(MIN(1,SUMIFS($AG$5:$AG$1000,$U$5:$U$1000,ROW(),$V$5:$V$1000,"Sub")),6),FALSE))),"Con subactividades: no escriba en las semanas (se llenan solas)"&" · ","")&IF((COUNTIF($I5:$L5,">1")+COUNTIF($I5:$L5,"<0")+SUMPRODUCT((LEN($I5:$L5)>0)*NOT(ISNUMBER($I5:$L5))))>0,"Avance fuera de rango 0-100%"&" · ","")&IF(OR(AND(ISNUMBER($J5),$J5<N($I5)),AND(ISNUMBER($K5),$K5<MAX($I5:$J5)),AND(ISNUMBER($L5),$L5<MAX($I5:$K5))),"Avance semanal decreciente"&" · ","")&IF(AND(ISNUMBER($AS5),$AS5<FechaRef,IF($V5="Sub",1,N($M5))<1),"Vencida"&" · ","")&IF(AND(ObsObligatoria="Sí",ISNUMBER($AS5),$AS5<FechaRef,IF($V5="Sub",1,N($M5))<1,$Q5=""),"Vencida sin observación"&" · ",""))="","✔ OK","⚠ "&LEFT(IF($C5="","Falta el nombre de la actividad"&" · ","")&IF(AND($V5="Sub",N($U5)=0),"Subactividad sin macroactividad arriba"&" · ","")&IF(AND($V5="Macro",$AR5=""),"Sin fecha de inicio"&" · ","")&IF(AND($V5="Macro",$AS5=""),"Sin fecha límite"&" · ","")&IF(AND(LEFT($C5,11)="[Jefatura] ",N($AQ5)=0),"No se encuentra en la hoja de la jefatura (elíjala de nuevo en la lista)"&" · ","")&IF(OR(AND($E5<>"",NOT(ISNUMBER($E5))),AND($F5<>"",NOT(ISNUMBER($F5))),AND($G5<>"",NOT(ISNUMBER($G5)))),"Fecha no válida"&" · ","")&IF(AND(ISNUMBER($AR5),ISNUMBER($AS5),$AR5>$AS5),"Inicio posterior a fecha límite"&" · ","")&IF(AND($V5="Macro",$H5<>"",OR(NOT(ISNUMBER($H5)),$H5<0,$H5>1)),"Peso fuera de rango"&" · ","")&IF(AND($V5="Sub",$H5<>"",OR(NOT(ISNUMBER($H5)),$H5<0,$H5>1)),"% de la subactividad fuera de rango 0-100%"&" · ","")&IF(AND(N($W5)>0,SUMIFS($H$5:$H$1000,$U$5:$U$1000,ROW(),$V$5:$V$1000,"Sub")>1.0001),"Las subactividades suman más de 100%"&" · ","")&IF(AND(N($W5)>0,OR(IF(ISNUMBER($I5),ROUND($I5,6)<>ROUND(MIN(1,SUMIFS($AD$5:$AD$1000,$U$5:$U$1000,ROW(),$V$5:$V$1000,"Sub")),6),FALSE),IF(ISNUMBER($J5),ROUND($J5,6)<>ROUND(MIN(1,SUMIFS($AE$5:$AE$1000,$U$5:$U$1000,ROW(),$V$5:$V$1000,"Sub")),6),FALSE),IF(ISNUMBER($K5),ROUND($K5,6)<>ROUND(MIN(1,SUMIFS($AF$5:$AF$1000,$U$5:$U$1000,ROW(),$V$5:$V$1000,"Sub")),6),FALSE),IF(ISNUMBER($L5),ROUND($L5,6)<>ROUND(MIN(1,SUMIFS($AG$5:$AG$1000,$U$5:$U$1000,ROW(),$V$5:$V$1000,"Sub")),6),FALSE))),"Con subactividades: no escriba en las semanas (se llenan solas)"&" · ","")&IF((COUNTIF($I5:$L5,">1")+COUNTIF($I5:$L5,"<0")+SUMPRODUCT((LEN($I5:$L5)>0)*NOT(ISNUMBER($I5:$L5))))>0,"Avance fuera de rango 0-100%"&" · ","")&IF(OR(AND(ISNUMBER($J5),$J5<N($I5)),AND(ISNUMBER($K5),$K5<MAX($I5:$J5)),AND(ISNUMBER($L5),$L5<MAX($I5:$K5))),"Avance semanal decreciente"&" · ","")&IF(AND(ISNUMBER($AS5),$AS5<FechaRef,IF($V5="Sub",1,N($M5))<1),"Vencida"&" · ","")&IF(AND(ObsObligatoria="Sí",ISNUMBER($AS5),$AS5<FechaRef,IF($V5="Sub",1,N($M5))<1,$Q5=""),"Vencida sin observación"&" · ",""),LEN(IF($C5="","Falta el nombre de la actividad"&" · ","")&IF(AND($V5="Sub",N($U5)=0),"Subactividad sin macroactividad arriba"&" · ","")&IF(AND($V5="Macro",$AR5=""),"Sin fecha de inicio"&" · ","")&IF(AND($V5="Macro",$AS5=""),"Sin fecha límite"&" · ","")&IF(AND(LEFT($C5,11)="[Jefatura] ",N($AQ5)=0),"No se encuentra en la hoja de la jefatura (elíjala de nuevo en la lista)"&" · ","")&IF(OR(AND($E5<>"",NOT(ISNUMBER($E5))),AND($F5<>"",NOT(ISNUMBER($F5))),AND($G5<>"",NOT(ISNUMBER($G5)))),"Fecha no válida"&" · ","")&IF(AND(ISNUMBER($AR5),ISNUMBER($AS5),$AR5>$AS5),"Inicio posterior a fecha límite"&" · ","")&IF(AND($V5="Macro",$H5<>"",OR(NOT(ISNUMBER($H5)),$H5<0,$H5>1)),"Peso fuera de rango"&" · ","")&IF(AND($V5="Sub",$H5<>"",OR(NOT(ISNUMBER($H5)),$H5<0,$H5>1)),"% de la subactividad fuera de rango 0-100%"&" · ","")&IF(AND(N($W5)>0,SUMIFS($H$5:$H$1000,$U$5:$U$1000,ROW(),$V$5:$V$1000,"Sub")>1.0001),"Las subactividades suman más de 100%"&" · ","")&IF(AND(N($W5)>0,OR(IF(ISNUMBER($I5),ROUND($I5,6)<>ROUND(MIN(1,SUMIFS($AD$5:$AD$1000,$U$5:$U$1000,ROW(),$V$5:$V$1000,"Sub")),6),FALSE),IF(ISNUMBER($J5),ROUND($J5,6)<>ROUND(MIN(1,SUMIFS($AE$5:$AE$1000,$U$5:$U$1000,ROW(),$V$5:$V$1000,"Sub")),6),FALSE),IF(ISNUMBER($K5),ROUND($K5,6)<>ROUND(MIN(1,SUMIFS($AF$5:$AF$1000,$U$5:$U$1000,ROW(),$V$5:$V$1000,"Sub")),6),FALSE),IF(ISNUMBER($L5),ROUND($L5,6)<>ROUND(MIN(1,SUMIFS($AG$5:$AG$1000,$U$5:$U$1000,ROW(),$V$5:$V$1000,"Sub")),6),FALSE))),"Con subactividades: no escriba en las semanas (se llenan solas)"&" · ","")&IF((COUNTIF($I5:$L5,">1")+COUNTIF($I5:$L5,"<0")+SUMPRODUCT((LEN($I5:$L5)>0)*NOT(ISNUMBER($I5:$L5))))>0,"Avance fuera de rango 0-100%"&" · ","")&IF(OR(AND(ISNUMBER($J5),$J5<N($I5)),AND(ISNUMBER($K5),$K5<MAX($I5:$J5)),AND(ISNUMBER($L5),$L5<MAX($I5:$K5))),"Avance semanal decreciente"&" · ","")&IF(AND(ISNUMBER($AS5),$AS5<FechaRef,IF($V5="Sub",1,N($M5))<1),"Vencida"&" · ","")&IF(AND(ObsObligatoria="Sí",ISNUMBER($AS5),$AS5<FechaRef,IF($V5="Sub",1,N($M5))<1,$Q5=""),"Vencida sin observación"&" · ",""))-3))) | S5: =IF(NOT((COUNTA($B5:$D5)+COUNTA($G5:$H5)+COUNTA($Q5))>0),"",IF(AND($V5="Sub",N($U5)>0),IF(ISNUMBER(INDEX($AR$5:$AR$1000,$U5-4)),DATE(YEAR(INDEX($AR$5:$AR$1000,$U5-4)),MONTH(INDEX($AR$5:$AR$1000,$U5-4)),1),IF(ISNUMBER(INDEX($AS$5:$AS$1000,$U5-4)),DATE(YEAR(INDEX($AS$5:$AS$1000,$U5-4)),MONTH(INDEX($AS$5:$AS$1000,$U5-4)),1),MesCiclo)),IF(ISNUMBER($AR5),DATE(YEAR($AR5),MONTH($AR5),1),IF(ISNUMBER($AS5),DATE(YEAR($AS5),MONTH($AS5),1),MesCiclo)))) | T5: =IF(OR($S5="",$S5<>MesCiclo,$V5<>"Macro"),"",COUNTIFS($S$5:$S5,MesCiclo,$V$5:$V5,"Macro")) | U5: =IF($V5="","",IF($V5="Macro",ROW(),IFERROR(LOOKUP(2,1/($V$5:$V5="Macro"),ROW($V$5:$V5)),0))) | V5: =IF(NOT((COUNTA($B5:$D5)+COUNTA($G5:$H5)+COUNTA($Q5))>0),"",IF($B5="Subactividad","Sub","Macro")) | W5: =IF($V5="Macro",COUNTIFS($U$5:$U$1000,ROW(),$V$5:$V$1000,"Sub"),"") | X5: =IF($V5<>"Sub","",IF(AND(ISNUMBER($H5),N($H5)>0),$H5,IFERROR(MAX(0,1-SUMIFS($H$5:$H$1000,$U$5:$U$1000,$U5,$V$5:$V$1000,"Sub"))/(COUNTIFS($U$5:$U$1000,$U5,$V$5:$V$1000,"Sub")-COUNTIFS($U$5:$U$1000,$U5,$V$5:$V$1000,"Sub",$H$5:$H$1000,">0")),0))) | Y5: =IF($V5="","",IF($V5="Sub",N($X5)*IF(ISNUMBER($G5),1,MIN(1,MAX(0,IFERROR(LOOKUP(2,1/ISNUMBER($I5:$L5),$I5:$L5),0)))),IF(ISNUMBER($G5),1,IFERROR(LOOKUP(2,1/($I5:$L5<>""),$I5:$L5),0)))) | Z5: =IF($V5="","",IF(AND(ISNUMBER($G5),$G5<=IF($S5=MesCiclo,InicioCiclo,$S5+MOD(2-WEEKDAY($S5),7))+6),1,IF(ISNUMBER($I5),$I5,0))) | AA5: =IF($V5="","",IF(AND(ISNUMBER($G5),$G5<=IF($S5=MesCiclo,InicioCiclo,$S5+MOD(2-WEEKDAY($S5),7))+13),1,IF(ISNUMBER($J5),$J5,$Z5))) | AB5: =IF($V5="","",IF(AND(ISNUMBER($G5),$G5<=IF($S5=MesCiclo,InicioCiclo,$S5+MOD(2-WEEKDAY($S5),7))+20),1,IF(ISNUMBER($K5),$K5,$AA5))) | AC5: =IF($V5="","",IF(AND(ISNUMBER($G5),$G5<=IF($S5=MesCiclo,InicioCiclo,$S5+MOD(2-WEEKDAY($S5),7))+27),1,IF(ISNUMBER($L5),$L5,$AB5))) | AD5: =IF($V5<>"Sub","",N($X5)*IF(AND(ISNUMBER($G5),$G5<=IF($S5=MesCiclo,InicioCiclo,$S5+MOD(2-WEEKDAY($S5),7))+6),1,MIN(1,MAX(0,IF(ISNUMBER(OFFSET($A$1,ROW()-1,8)),OFFSET($A$1,ROW()-1,8),0))))) | AE5: =IF($V5<>"Sub","",N($X5)*IF(AND(ISNUMBER($G5),$G5<=IF($S5=MesCiclo,InicioCiclo,$S5+MOD(2-WEEKDAY($S5),7))+13),1,MIN(1,MAX(0,IF(ISNUMBER(OFFSET($A$1,ROW()-1,9)),OFFSET($A$1,ROW()-1,9),IF(ISNUMBER(OFFSET($A$1,ROW()-1,8)),OFFSET($A$1,ROW()-1,8),0)))))) | AF5: =IF($V5<>"Sub","",N($X5)*IF(AND(ISNUMBER($G5),$G5<=IF($S5=MesCiclo,InicioCiclo,$S5+MOD(2-WEEKDAY($S5),7))+20),1,MIN(1,MAX(0,IF(ISNUMBER(OFFSET($A$1,ROW()-1,10)),OFFSET($A$1,ROW()-1,10),IF(ISNUMBER(OFFSET($A$1,ROW()-1,9)),OFFSET($A$1,ROW()-1,9),IF(ISNUMBER(OFFSET($A$1,ROW()-1,8)),OFFSET($A$1,ROW()-1,8),0))))))) | AG5: =IF($V5<>"Sub","",N($X5)*IF(AND(ISNUMBER($G5),$G5<=IF($S5=MesCiclo,InicioCiclo,$S5+MOD(2-WEEKDAY($S5),7))+27),1,MIN(1,MAX(0,IF(ISNUMBER(OFFSET($A$1,ROW()-1,11)),OFFSET($A$1,ROW()-1,11),IF(ISNUMBER(OFFSET($A$1,ROW()-1,10)),OFFSET($A$1,ROW()-1,10),IF(ISNUMBER(OFFSET($A$1,ROW()-1,9)),OFFSET($A$1,ROW()-1,9),IF(ISNUMBER(OFFSET($A$1,ROW()-1,8)),OFFSET($A$1,ROW()-1,8),0)))))))) | AH5: =IF($V5="","",IF(AND(ISNUMBER($G5),$G5<=IF($S5=MesCiclo,InicioCiclo,$S5+MOD(2-WEEKDAY($S5),7))+6),1,IF(N($W5)>0,MIN(1,SUMIFS($AD$5:$AD$1000,$U$5:$U$1000,ROW(),$V$5:$V$1000,"Sub")),$Z5))) | AI5: =IF($V5="","",IF(AND(ISNUMBER($G5),$G5<=IF($S5=MesCiclo,InicioCiclo,$S5+MOD(2-WEEKDAY($S5),7))+13),1,IF(N($W5)>0,MIN(1,SUMIFS($AE$5:$AE$1000,$U$5:$U$1000,ROW(),$V$5:$V$1000,"Sub")),$AA5))) | AJ5: =IF($V5="","",IF(AND(ISNUMBER($G5),$G5<=IF($S5=MesCiclo,InicioCiclo,$S5+MOD(2-WEEKDAY($S5),7))+20),1,IF(N($W5)>0,MIN(1,SUMIFS($AF$5:$AF$1000,$U$5:$U$1000,ROW(),$V$5:$V$1000,"Sub")),$AB5))) | AK5: =IF($V5="","",IF(AND(ISNUMBER($G5),$G5<=IF($S5=MesCiclo,InicioCiclo,$S5+MOD(2-WEEKDAY($S5),7))+27),1,IF(N($W5)>0,MIN(1,SUMIFS($AG$5:$AG$1000,$U$5:$U$1000,ROW(),$V$5:$V$1000,"Sub")),$AC5))) | AL5: =IF($V5<>"Macro","",IF(COUNTIFS($S$5:$S$1000,$S5,$V$5:$V$1000,"Macro",$H$5:$H$1000,">0")=0,1/COUNTIFS($S$5:$S$1000,$S5,$V$5:$V$1000,"Macro"),IF(AND(ISNUMBER($H5),N($H5)>0),$H5,SUMIFS($H$5:$H$1000,$S$5:$S$1000,$S5,$V$5:$V$1000,"Macro")/COUNTIFS($S$5:$S$1000,$S5,$V$5:$V$1000,"Macro",$H$5:$H$1000,">0"))/(COUNTIFS($S$5:$S$1000,$S5,$V$5:$V$1000,"Macro")*SUMIFS($H$5:$H$1000,$S$5:$S$1000,$S5,$V$5:$V$1000,"Macro")/COUNTIFS($S$5:$S$1000,$S5,$V$5:$V$1000,"Macro",$H$5:$H$1000,">0")))) | AM5: =IF(NOT(AND($D5<>"",$V5="Macro")),"",IFERROR(CHOOSE(MATCH($D5,ListaPuestos,0),MATCH("[Jefatura] "&$C5,'Cronograma R. Operacional'!$C$5:$C$1000,0),MATCH("[Jefatura] "&$C5,'Cronograma R. Normativo'!$C$5:$C$1000,0),MATCH("[Jefatura] "&$C5,'Cronograma R. Financiero'!$C$5:$C$1000,0),MATCH("[Jefatura] "&$C5,'Cronograma Asistente Técnico'!$C$5:$C$1000,0)),0)) | AN5: =IF(AND(AND($D5<>"",$V5="Macro"),$S5=MesCiclo),COUNTIFS($D$5:$D5,$D5,$S$5:$S5,MesCiclo,$V$5:$V5,"Macro"),"") | AO5: =IF($AN5="","",$D5&"|"&$AN5) | AP5: =IF(AND($D5<>"",$V5="Macro"),$D5&"|"&$C5,"") | AQ5: ="" | AR5: =IF(N($AQ5)>0,INDEX(rIni_ADM,$AQ5),IF(ISNUMBER($E5),$E5,"")) | AS5: =IF(N($AQ5)>0,INDEX(rLim_ADM,$AQ5),IF(ISNUMBER($F5),$F5,""))
A6: =IF(NOT((COUNTA($B6:$D6)+COUNTA($G6:$H6)+COUNTA($Q6))>0),"",IF($V6="Macro",COUNTIFS($V$5:$V6,"Macro",$S$5:$S6,$S6),IF(N($U6)=0,"?",COUNTIFS(INDEX($V$5:$V$1000,1):INDEX($V$5:$V$1000,$U6-4),"Macro",INDEX($S$5:$S$1000,1):INDEX($S$5:$S$1000,$U6-4),INDEX($S$5:$S$1000,$U6-4))&"."&COUNTIFS($U$5:$U6,$U6,$V$5:$V6,"Sub")))) | I6: =IF(N($W6)=0,"",IF(AND($S6=MesCiclo,1>SemanaActual),"",MIN(1,SUMIFS(OFFSET($A$1,ROW(),29,1000-ROW(),1),OFFSET($A$1,ROW(),20,1000-ROW(),1),ROW(),OFFSET($A$1,ROW(),21,1000-ROW(),1),"Sub")))) | J6: =IF(N($W6)=0,"",IF(AND($S6=MesCiclo,2>SemanaActual),"",MIN(1,SUMIFS(OFFSET($A$1,ROW(),30,1000-ROW(),1),OFFSET($A$1,ROW(),20,1000-ROW(),1),ROW(),OFFSET($A$1,ROW(),21,1000-ROW(),1),"Sub")))) | K6: =IF(N($W6)=0,"",IF(AND($S6=MesCiclo,3>SemanaActual),"",MIN(1,SUMIFS(OFFSET($A$1,ROW(),31,1000-ROW(),1),OFFSET($A$1,ROW(),20,1000-ROW(),1),ROW(),OFFSET($A$1,ROW(),21,1000-ROW(),1),"Sub")))) | L6: =IF(N($W6)=0,"",IF(AND($S6=MesCiclo,4>SemanaActual),"",MIN(1,SUMIFS(OFFSET($A$1,ROW(),32,1000-ROW(),1),OFFSET($A$1,ROW(),20,1000-ROW(),1),ROW(),OFFSET($A$1,ROW(),21,1000-ROW(),1),"Sub")))) | M6: =IF(NOT((COUNTA($B6:$D6)+COUNTA($G6:$H6)+COUNTA($Q6))>0),"",IF(AND($D6<>"",$V6="Macro"),IF(N($AM6)>0,N(CHOOSE(MATCH($D6,ListaPuestos,0),INDEX('Cronograma R. Operacional'!$M$5:$M$1000,$AM6),INDEX('Cronograma R. Normativo'!$M$5:$M$1000,$AM6),INDEX('Cronograma R. Financiero'!$M$5:$M$1000,$AM6),INDEX('Cronograma Asistente Técnico'!$M$5:$M$1000,$AM6))),0),IF(ISNUMBER($G6),1,IF(N($W6)>0,MIN(1,SUMIFS($Y$5:$Y$1000,$U$5:$U$1000,ROW(),$V$5:$V$1000,"Sub")),$Y6)))) | N6: =IF(OR($M6="",$V6="Sub"),"",IF($M6>=1,"Completado",IF($M6>0,"En curso","Pendiente"))) | O6: =IF(NOT((COUNTA($B6:$D6)+COUNTA($G6:$H6)+COUNTA($Q6))>0),"",IF(AND(AND($D6<>"",$V6="Macro"),N($AM6)>0),CHOOSE(MATCH($D6,ListaPuestos,0),INDEX('Cronograma R. Operacional'!$O$5:$O$1000,$AM6),INDEX('Cronograma R. Normativo'!$O$5:$O$1000,$AM6),INDEX('Cronograma R. Financiero'!$O$5:$O$1000,$AM6),INDEX('Cronograma Asistente Técnico'!$O$5:$O$1000,$AM6))&"",IF(ISNUMBER($G6),IF(AND(ISNUMBER($AS6),$G6>$AS6),"Cumplida con "&($G6-$AS6)&IF($G6-$AS6=1," día"," días")&" de retraso","Cumplida"),IF(N($M6)>=1,"Cumplida",IF(NOT(ISNUMBER($AS6)),"Sin fecha límite",IF($AS6<FechaRef,"Vencida hace "&(FechaRef-$AS6)&IF(FechaRef-$AS6=1," día"," días"),IF($AS6=FechaRef,"Vence hoy",IF($AS6-FechaRef<=DiasAlerta,"Vence en "&($AS6-FechaRef)&IF($AS6-FechaRef=1," día"," días"),"En plazo")))))))) | P6: =IF(NOT((COUNTA($B6:$D6)+COUNTA($G6:$H6)+COUNTA($Q6))>0),"",IF($D6="","Propia",IF($V6<>"Macro","Solo se delegan macroactividades",IF(N($AM6)>0,"✔ Recibida por "&$D6,"⚠ "&$D6&" aún no la agrega")))) | R6: =IF(NOT((COUNTA($B6:$D6)+COUNTA($G6:$H6)+COUNTA($Q6))>0),"",IF((IF($C6="","Falta el nombre de la actividad"&" · ","")&IF(AND($V6="Sub",N($U6)=0),"Subactividad sin macroactividad arriba"&" · ","")&IF(AND($V6="Macro",$AR6=""),"Sin fecha de inicio"&" · ","")&IF(AND($V6="Macro",$AS6=""),"Sin fecha límite"&" · ","")&IF(AND(LEFT($C6,11)="[Jefatura] ",N($AQ6)=0),"No se encuentra en la hoja de la jefatura (elíjala de nuevo en la lista)"&" · ","")&IF(OR(AND($E6<>"",NOT(ISNUMBER($E6))),AND($F6<>"",NOT(ISNUMBER($F6))),AND($G6<>"",NOT(ISNUMBER($G6)))),"Fecha no válida"&" · ","")&IF(AND(ISNUMBER($AR6),ISNUMBER($AS6),$AR6>$AS6),"Inicio posterior a fecha límite"&" · ","")&IF(AND($V6="Macro",$H6<>"",OR(NOT(ISNUMBER($H6)),$H6<0,$H6>1)),"Peso fuera de rango"&" · ","")&IF(AND($V6="Sub",$H6<>"",OR(NOT(ISNUMBER($H6)),$H6<0,$H6>1)),"% de la subactividad fuera de rango 0-100%"&" · ","")&IF(AND(N($W6)>0,SUMIFS($H$5:$H$1000,$U$5:$U$1000,ROW(),$V$5:$V$1000,"Sub")>1.0001),"Las subactividades suman más de 100%"&" · ","")&IF(AND(N($W6)>0,OR(IF(ISNUMBER($I6),ROUND($I6,6)<>ROUND(MIN(1,SUMIFS($AD$5:$AD$1000,$U$5:$U$1000,ROW(),$V$5:$V$1000,"Sub")),6),FALSE),IF(ISNUMBER($J6),ROUND($J6,6)<>ROUND(MIN(1,SUMIFS($AE$5:$AE$1000,$U$5:$U$1000,ROW(),$V$5:$V$1000,"Sub")),6),FALSE),IF(ISNUMBER($K6),ROUND($K6,6)<>ROUND(MIN(1,SUMIFS($AF$5:$AF$1000,$U$5:$U$1000,ROW(),$V$5:$V$1000,"Sub")),6),FALSE),IF(ISNUMBER($L6),ROUND($L6,6)<>ROUND(MIN(1,SUMIFS($AG$5:$AG$1000,$U$5:$U$1000,ROW(),$V$5:$V$1000,"Sub")),6),FALSE))),"Con subactividades: no escriba en las semanas (se llenan solas)"&" · ","")&IF((COUNTIF($I6:$L6,">1")+COUNTIF($I6:$L6,"<0")+SUMPRODUCT((LEN($I6:$L6)>0)*NOT(ISNUMBER($I6:$L6))))>0,"Avance fuera de rango 0-100%"&" · ","")&IF(OR(AND(ISNUMBER($J6),$J6<N($I6)),AND(ISNUMBER($K6),$K6<MAX($I6:$J6)),AND(ISNUMBER($L6),$L6<MAX($I6:$K6))),"Avance semanal decreciente"&" · ","")&IF(AND(ISNUMBER($AS6),$AS6<FechaRef,IF($V6="Sub",1,N($M6))<1),"Vencida"&" · ","")&IF(AND(ObsObligatoria="Sí",ISNUMBER($AS6),$AS6<FechaRef,IF($V6="Sub",1,N($M6))<1,$Q6=""),"Vencida sin observación"&" · ",""))="","✔ OK","⚠ "&LEFT(IF($C6="","Falta el nombre de la actividad"&" · ","")&IF(AND($V6="Sub",N($U6)=0),"Subactividad sin macroactividad arriba"&" · ","")&IF(AND($V6="Macro",$AR6=""),"Sin fecha de inicio"&" · ","")&IF(AND($V6="Macro",$AS6=""),"Sin fecha límite"&" · ","")&IF(AND(LEFT($C6,11)="[Jefatura] ",N($AQ6)=0),"No se encuentra en la hoja de la jefatura (elíjala de nuevo en la lista)"&" · ","")&IF(OR(AND($E6<>"",NOT(ISNUMBER($E6))),AND($F6<>"",NOT(ISNUMBER($F6))),AND($G6<>"",NOT(ISNUMBER($G6)))),"Fecha no válida"&" · ","")&IF(AND(ISNUMBER($AR6),ISNUMBER($AS6),$AR6>$AS6),"Inicio posterior a fecha límite"&" · ","")&IF(AND($V6="Macro",$H6<>"",OR(NOT(ISNUMBER($H6)),$H6<0,$H6>1)),"Peso fuera de rango"&" · ","")&IF(AND($V6="Sub",$H6<>"",OR(NOT(ISNUMBER($H6)),$H6<0,$H6>1)),"% de la subactividad fuera de rango 0-100%"&" · ","")&IF(AND(N($W6)>0,SUMIFS($H$5:$H$1000,$U$5:$U$1000,ROW(),$V$5:$V$1000,"Sub")>1.0001),"Las subactividades suman más de 100%"&" · ","")&IF(AND(N($W6)>0,OR(IF(ISNUMBER($I6),ROUND($I6,6)<>ROUND(MIN(1,SUMIFS($AD$5:$AD$1000,$U$5:$U$1000,ROW(),$V$5:$V$1000,"Sub")),6),FALSE),IF(ISNUMBER($J6),ROUND($J6,6)<>ROUND(MIN(1,SUMIFS($AE$5:$AE$1000,$U$5:$U$1000,ROW(),$V$5:$V$1000,"Sub")),6),FALSE),IF(ISNUMBER($K6),ROUND($K6,6)<>ROUND(MIN(1,SUMIFS($AF$5:$AF$1000,$U$5:$U$1000,ROW(),$V$5:$V$1000,"Sub")),6),FALSE),IF(ISNUMBER($L6),ROUND($L6,6)<>ROUND(MIN(1,SUMIFS($AG$5:$AG$1000,$U$5:$U$1000,ROW(),$V$5:$V$1000,"Sub")),6),FALSE))),"Con subactividades: no escriba en las semanas (se llenan solas)"&" · ","")&IF((COUNTIF($I6:$L6,">1")+COUNTIF($I6:$L6,"<0")+SUMPRODUCT((LEN($I6:$L6)>0)*NOT(ISNUMBER($I6:$L6))))>0,"Avance fuera de rango 0-100%"&" · ","")&IF(OR(AND(ISNUMBER($J6),$J6<N($I6)),AND(ISNUMBER($K6),$K6<MAX($I6:$J6)),AND(ISNUMBER($L6),$L6<MAX($I6:$K6))),"Avance semanal decreciente"&" · ","")&IF(AND(ISNUMBER($AS6),$AS6<FechaRef,IF($V6="Sub",1,N($M6))<1),"Vencida"&" · ","")&IF(AND(ObsObligatoria="Sí",ISNUMBER($AS6),$AS6<FechaRef,IF($V6="Sub",1,N($M6))<1,$Q6=""),"Vencida sin observación"&" · ",""),LEN(IF($C6="","Falta el nombre de la actividad"&" · ","")&IF(AND($V6="Sub",N($U6)=0),"Subactividad sin macroactividad arriba"&" · ","")&IF(AND($V6="Macro",$AR6=""),"Sin fecha de inicio"&" · ","")&IF(AND($V6="Macro",$AS6=""),"Sin fecha límite"&" · ","")&IF(AND(LEFT($C6,11)="[Jefatura] ",N($AQ6)=0),"No se encuentra en la hoja de la jefatura (elíjala de nuevo en la lista)"&" · ","")&IF(OR(AND($E6<>"",NOT(ISNUMBER($E6))),AND($F6<>"",NOT(ISNUMBER($F6))),AND($G6<>"",NOT(ISNUMBER($G6)))),"Fecha no válida"&" · ","")&IF(AND(ISNUMBER($AR6),ISNUMBER($AS6),$AR6>$AS6),"Inicio posterior a fecha límite"&" · ","")&IF(AND($V6="Macro",$H6<>"",OR(NOT(ISNUMBER($H6)),$H6<0,$H6>1)),"Peso fuera de rango"&" · ","")&IF(AND($V6="Sub",$H6<>"",OR(NOT(ISNUMBER($H6)),$H6<0,$H6>1)),"% de la subactividad fuera de rango 0-100%"&" · ","")&IF(AND(N($W6)>0,SUMIFS($H$5:$H$1000,$U$5:$U$1000,ROW(),$V$5:$V$1000,"Sub")>1.0001),"Las subactividades suman más de 100%"&" · ","")&IF(AND(N($W6)>0,OR(IF(ISNUMBER($I6),ROUND($I6,6)<>ROUND(MIN(1,SUMIFS($AD$5:$AD$1000,$U$5:$U$1000,ROW(),$V$5:$V$1000,"Sub")),6),FALSE),IF(ISNUMBER($J6),ROUND($J6,6)<>ROUND(MIN(1,SUMIFS($AE$5:$AE$1000,$U$5:$U$1000,ROW(),$V$5:$V$1000,"Sub")),6),FALSE),IF(ISNUMBER($K6),ROUND($K6,6)<>ROUND(MIN(1,SUMIFS($AF$5:$AF$1000,$U$5:$U$1000,ROW(),$V$5:$V$1000,"Sub")),6),FALSE),IF(ISNUMBER($L6),ROUND($L6,6)<>ROUND(MIN(1,SUMIFS($AG$5:$AG$1000,$U$5:$U$1000,ROW(),$V$5:$V$1000,"Sub")),6),FALSE))),"Con subactividades: no escriba en las semanas (se llenan solas)"&" · ","")&IF((COUNTIF($I6:$L6,">1")+COUNTIF($I6:$L6,"<0")+SUMPRODUCT((LEN($I6:$L6)>0)*NOT(ISNUMBER($I6:$L6))))>0,"Avance fuera de rango 0-100%"&" · ","")&IF(OR(AND(ISNUMBER($J6),$J6<N($I6)),AND(ISNUMBER($K6),$K6<MAX($I6:$J6)),AND(ISNUMBER($L6),$L6<MAX($I6:$K6))),"Avance semanal decreciente"&" · ","")&IF(AND(ISNUMBER($AS6),$AS6<FechaRef,IF($V6="Sub",1,N($M6))<1),"Vencida"&" · ","")&IF(AND(ObsObligatoria="Sí",ISNUMBER($AS6),$AS6<FechaRef,IF($V6="Sub",1,N($M6))<1,$Q6=""),"Vencida sin observación"&" · ",""))-3))) | S6: =IF(NOT((COUNTA($B6:$D6)+COUNTA($G6:$H6)+COUNTA($Q6))>0),"",IF(AND($V6="Sub",N($U6)>0),IF(ISNUMBER(INDEX($AR$5:$AR$1000,$U6-4)),DATE(YEAR(INDEX($AR$5:$AR$1000,$U6-4)),MONTH(INDEX($AR$5:$AR$1000,$U6-4)),1),IF(ISNUMBER(INDEX($AS$5:$AS$1000,$U6-4)),DATE(YEAR(INDEX($AS$5:$AS$1000,$U6-4)),MONTH(INDEX($AS$5:$AS$1000,$U6-4)),1),MesCiclo)),IF(ISNUMBER($AR6),DATE(YEAR($AR6),MONTH($AR6),1),IF(ISNUMBER($AS6),DATE(YEAR($AS6),MONTH($AS6),1),MesCiclo)))) | T6: =IF(OR($S6="",$S6<>MesCiclo,$V6<>"Macro"),"",COUNTIFS($S$5:$S6,MesCiclo,$V$5:$V6,"Macro")) | U6: =IF($V6="","",IF($V6="Macro",ROW(),IFERROR(LOOKUP(2,1/($V$5:$V6="Macro"),ROW($V$5:$V6)),0))) | V6: =IF(NOT((COUNTA($B6:$D6)+COUNTA($G6:$H6)+COUNTA($Q6))>0),"",IF($B6="Subactividad","Sub","Macro")) | W6: =IF($V6="Macro",COUNTIFS($U$5:$U$1000,ROW(),$V$5:$V$1000,"Sub"),"") | X6: =IF($V6<>"Sub","",IF(AND(ISNUMBER($H6),N($H6)>0),$H6,IFERROR(MAX(0,1-SUMIFS($H$5:$H$1000,$U$5:$U$1000,$U6,$V$5:$V$1000,"Sub"))/(COUNTIFS($U$5:$U$1000,$U6,$V$5:$V$1000,"Sub")-COUNTIFS($U$5:$U$1000,$U6,$V$5:$V$1000,"Sub",$H$5:$H$1000,">0")),0))) | Y6: =IF($V6="","",IF($V6="Sub",N($X6)*IF(ISNUMBER($G6),1,MIN(1,MAX(0,IFERROR(LOOKUP(2,1/ISNUMBER($I6:$L6),$I6:$L6),0)))),IF(ISNUMBER($G6),1,IFERROR(LOOKUP(2,1/($I6:$L6<>""),$I6:$L6),0)))) | Z6: =IF($V6="","",IF(AND(ISNUMBER($G6),$G6<=IF($S6=MesCiclo,InicioCiclo,$S6+MOD(2-WEEKDAY($S6),7))+6),1,IF(ISNUMBER($I6),$I6,0))) | AA6: =IF($V6="","",IF(AND(ISNUMBER($G6),$G6<=IF($S6=MesCiclo,InicioCiclo,$S6+MOD(2-WEEKDAY($S6),7))+13),1,IF(ISNUMBER($J6),$J6,$Z6))) | AB6: =IF($V6="","",IF(AND(ISNUMBER($G6),$G6<=IF($S6=MesCiclo,InicioCiclo,$S6+MOD(2-WEEKDAY($S6),7))+20),1,IF(ISNUMBER($K6),$K6,$AA6))) | AC6: =IF($V6="","",IF(AND(ISNUMBER($G6),$G6<=IF($S6=MesCiclo,InicioCiclo,$S6+MOD(2-WEEKDAY($S6),7))+27),1,IF(ISNUMBER($L6),$L6,$AB6))) | AD6: =IF($V6<>"Sub","",N($X6)*IF(AND(ISNUMBER($G6),$G6<=IF($S6=MesCiclo,InicioCiclo,$S6+MOD(2-WEEKDAY($S6),7))+6),1,MIN(1,MAX(0,IF(ISNUMBER(OFFSET($A$1,ROW()-1,8)),OFFSET($A$1,ROW()-1,8),0))))) | AE6: =IF($V6<>"Sub","",N($X6)*IF(AND(ISNUMBER($G6),$G6<=IF($S6=MesCiclo,InicioCiclo,$S6+MOD(2-WEEKDAY($S6),7))+13),1,MIN(1,MAX(0,IF(ISNUMBER(OFFSET($A$1,ROW()-1,9)),OFFSET($A$1,ROW()-1,9),IF(ISNUMBER(OFFSET($A$1,ROW()-1,8)),OFFSET($A$1,ROW()-1,8),0)))))) | AF6: =IF($V6<>"Sub","",N($X6)*IF(AND(ISNUMBER($G6),$G6<=IF($S6=MesCiclo,InicioCiclo,$S6+MOD(2-WEEKDAY($S6),7))+20),1,MIN(1,MAX(0,IF(ISNUMBER(OFFSET($A$1,ROW()-1,10)),OFFSET($A$1,ROW()-1,10),IF(ISNUMBER(OFFSET($A$1,ROW()-1,9)),OFFSET($A$1,ROW()-1,9),IF(ISNUMBER(OFFSET($A$1,ROW()-1,8)),OFFSET($A$1,ROW()-1,8),0))))))) | AG6: =IF($V6<>"Sub","",N($X6)*IF(AND(ISNUMBER($G6),$G6<=IF($S6=MesCiclo,InicioCiclo,$S6+MOD(2-WEEKDAY($S6),7))+27),1,MIN(1,MAX(0,IF(ISNUMBER(OFFSET($A$1,ROW()-1,11)),OFFSET($A$1,ROW()-1,11),IF(ISNUMBER(OFFSET($A$1,ROW()-1,10)),OFFSET($A$1,ROW()-1,10),IF(ISNUMBER(OFFSET($A$1,ROW()-1,9)),OFFSET($A$1,ROW()-1,9),IF(ISNUMBER(OFFSET($A$1,ROW()-1,8)),OFFSET($A$1,ROW()-1,8),0)))))))) | AH6: =IF($V6="","",IF(AND(ISNUMBER($G6),$G6<=IF($S6=MesCiclo,InicioCiclo,$S6+MOD(2-WEEKDAY($S6),7))+6),1,IF(N($W6)>0,MIN(1,SUMIFS($AD$5:$AD$1000,$U$5:$U$1000,ROW(),$V$5:$V$1000,"Sub")),$Z6))) | AI6: =IF($V6="","",IF(AND(ISNUMBER($G6),$G6<=IF($S6=MesCiclo,InicioCiclo,$S6+MOD(2-WEEKDAY($S6),7))+13),1,IF(N($W6)>0,MIN(1,SUMIFS($AE$5:$AE$1000,$U$5:$U$1000,ROW(),$V$5:$V$1000,"Sub")),$AA6))) | AJ6: =IF($V6="","",IF(AND(ISNUMBER($G6),$G6<=IF($S6=MesCiclo,InicioCiclo,$S6+MOD(2-WEEKDAY($S6),7))+20),1,IF(N($W6)>0,MIN(1,SUMIFS($AF$5:$AF$1000,$U$5:$U$1000,ROW(),$V$5:$V$1000,"Sub")),$AB6))) | AK6: =IF($V6="","",IF(AND(ISNUMBER($G6),$G6<=IF($S6=MesCiclo,InicioCiclo,$S6+MOD(2-WEEKDAY($S6),7))+27),1,IF(N($W6)>0,MIN(1,SUMIFS($AG$5:$AG$1000,$U$5:$U$1000,ROW(),$V$5:$V$1000,"Sub")),$AC6))) | AL6: =IF($V6<>"Macro","",IF(COUNTIFS($S$5:$S$1000,$S6,$V$5:$V$1000,"Macro",$H$5:$H$1000,">0")=0,1/COUNTIFS($S$5:$S$1000,$S6,$V$5:$V$1000,"Macro"),IF(AND(ISNUMBER($H6),N($H6)>0),$H6,SUMIFS($H$5:$H$1000,$S$5:$S$1000,$S6,$V$5:$V$1000,"Macro")/COUNTIFS($S$5:$S$1000,$S6,$V$5:$V$1000,"Macro",$H$5:$H$1000,">0"))/(COUNTIFS($S$5:$S$1000,$S6,$V$5:$V$1000,"Macro")*SUMIFS($H$5:$H$1000,$S$5:$S$1000,$S6,$V$5:$V$1000,"Macro")/COUNTIFS($S$5:$S$1000,$S6,$V$5:$V$1000,"Macro",$H$5:$H$1000,">0")))) | AM6: =IF(NOT(AND($D6<>"",$V6="Macro")),"",IFERROR(CHOOSE(MATCH($D6,ListaPuestos,0),MATCH("[Jefatura] "&$C6,'Cronograma R. Operacional'!$C$5:$C$1000,0),MATCH("[Jefatura] "&$C6,'Cronograma R. Normativo'!$C$5:$C$1000,0),MATCH("[Jefatura] "&$C6,'Cronograma R. Financiero'!$C$5:$C$1000,0),MATCH("[Jefatura] "&$C6,'Cronograma Asistente Técnico'!$C$5:$C$1000,0)),0)) | AN6: =IF(AND(AND($D6<>"",$V6="Macro"),$S6=MesCiclo),COUNTIFS($D$5:$D6,$D6,$S$5:$S6,MesCiclo,$V$5:$V6,"Macro"),"") | AO6: =IF($AN6="","",$D6&"|"&$AN6) | AP6: =IF(AND($D6<>"",$V6="Macro"),$D6&"|"&$C6,"") | AQ6: ="" | AR6: =IF(N($AQ6)>0,INDEX(rIni_ADM,$AQ6),IF(ISNUMBER($E6),$E6,"")) | AS6: =IF(N($AQ6)>0,INDEX(rLim_ADM,$AQ6),IF(ISNUMBER($F6),$F6,""))
