Workbook

Sheet Instrucciones
B1: CÓMO ACTUALIZAR ESTE ARCHIVO
B3: 1. AGREGAR UN COLABORADOR (hoja 'Base Oficial')
B4: • | C4: Escriba en la primera fila vacía: Código, Nombre, Fecha de ingreso, Cargo, Grupo SSF, Departamento y Gerencia.
B5: • | C5: Departamento y Gerencia: elíjalos de la lista desplegable para que se escriban igual que los existentes.
B6: • | C6: Si es un departamento o gerencia NUEVO, escríbalo y confirme con 'Sí' en el aviso.
B7: • | C7: El colaborador aparece automáticamente como Pendiente (o Completado si ya tiene examen).
B9: 2. AGREGAR EXÁMENES (hoja 'Base Exámenes')
B10: • | C10: Pegue cada examen en la primera fila vacía, columnas A a E y G a H:
B11: • | C11: A Nombre · B Área · C Código de empleado · D Hora de inicio · E Hora de finalización · G Nota · H Correo.
B12: • | C12: NO escriba en la columna F (Duración): se calcula sola.
B13: • | C13: Desde la exportación de la plataforma: I = Nombre, L = Departamento, O = Código, B = Inicio, C = Fin, F = Total de puntos, D = Correo.
B14: • | C14: Si una persona hace el examen más de una vez, se cuenta su NOTA MÁS ALTA y queda registrado en 'Historial de Intentos'.
B16: 3. QUÉ SE ACTUALIZA SOLO
B17: • | C17: Detalle individual, Consolidado por área, Consolidado por Gerencia (incluye departamentos y gerencias nuevos).
B18: • | C18: Dashboard Gráfico, Dashboard Gerencial, Dashboard Departamentos y Estado por Colaborador.
B19: • | C19: Listado de Pendientes, Listado de Completados, Top 3 (todos) e Historial de Intentos.
B20: • | C20: Capacidad: hasta 996 colaboradores, 996 exámenes, 80 departamentos y 20 gerencias.
B22: 4. CAMBIAR UN DEPARTAMENTO DE GERENCIA
B23: • | C23: En 'Base Oficial' cambie la columna G (Gerencia) de TODAS las personas de ese departamento. Lo demás se ajusta solo.
B25: 5. IMPORTANTE
B26: • | C26: No borre ni escriba en las hojas de resultados (consolidados, listados, top 3, historial): son fórmulas.
B27: • | C27: La hoja oculta 'Cálculos' es necesaria para los dashboards: no la elimine.
B28: • | C28: Si agrega un departamento o gerencia NUEVO, las tablas se actualizan, pero los GRÁFICOS deben ampliarse:
B29: • | C29: aparecerá un aviso rojo en el dashboard. Envíe el archivo para actualizarlos.
B31: 6. SITUACIÓN ESPECIAL (vacaciones, incapacidad, maternidad, renuncia)
B32: • | C32: En 'Base Oficial', columna H, elija la situación de la persona. Déjela vacía si está activa.
B33: • | C33: Si no ha hecho el examen, aparece con esa situación y NO cuenta en el personal esperado ni en el %.
B34: • | C34: Si sí hizo el examen, cuenta como Completado normalmente.
B35: • | C35: La lista de estas personas está en 'Listado de Situación Especial'. Cuando regrese, borre la situación.

Sheet Base Oficial
A1: LISTADO OFICIAL DE COLABORADORES
A2: Base maestra de personal institucional
A4: Código | B4: Nombre del Colaborador | C4: Fecha Ingreso | D4: Cargo | E4: Grupo SSF | F4: Área / Departamento | G4: Gerencia Asignada | H4: Situación especial
A5: 977 | B5: NELSON ULISES CAMPOS FLORES | C5: 10/08/2026 | D5: GERENTE GENERAL | E5: GERENTE | F5: GERENCIA GENERAL | G5: Gerencia General
A6: 349 | B6: CARLA EUGENIA HERNANDEZ MENJIVAR | C6: 08/08/2005 | D6: GERENTE ADMINISTRATIVA | E6: GERENTE | F6: GERENCIA ADMINISTRATIVA | G6: Gerencia Administrativa
A7: 41 | B7: ROQUE RAFAEL REYES ESPINAL | C7: 25/04/1994 | D7: GERENTE DE OPERACIONES | E7: GERENTE | F7: GERENCIA DE OPERACIONES | G7: Gerencia de Operaciones
A8: 524 | B8: JOSE AUGUSTO DE LA O GALLEGOS | C8: 01/04/2013 | D8: GERENTE DE FINANZAS Y PLANIFICACION | E8: GERENTE | F8: GERENCIA DE FINANZAS Y PLANIFICACIÓN | G8: Gerencia de Finanzas y Planificación
A9: 878 | B9: ALEX VIRGILIO AGUILAR ARIAS | C9: 01/07/2024 | D9: GERENTE DE SISTEMAS | E9: GERENTE | F9: GERENCIA DE SISTEMAS | G9: Gerencia de Sistemas
A10: 862 | B10: GEORGI ROBERTO CASTILLO CHACON | C10: 01/04/2024 | D10: GERENTE DE OFICIALIA DE CUMPLIMIENTO | E10: GERENTE | F10: OFICIALIA DE CUMPLIMIENTO | G10: Gerencia de Oficialía de Cumplimiento
A11: 741 | B11: JOSE HUMBERTO BARILLAS BURGOS | C11: 16/03/2022 | D11: GERENTE DE NEGOCIOS | E11: GERENTE | F11: GERENCIA DE NEGOCIOS | G11: Gerencia de Negocios
A12: 570 | B12: ANDREA VICTORIA MAYORGA RODRIGUEZ | C12: 22/07/2016 | D12: GERENTE LEGAL Y DE CUMPLIMIENTO NORMATIVO | E12: GERENTE | F12: GERENCIA LEGAL Y DE CUMPLIMIENTO NORMATIVO | G12: Gerencia Legal y Cumplimiento Normativo
A13: 17 | B13: ANTONIA SARAI BELTRAN CARBALLO | C13: 04/04/1994 | D13: ASISTENTE ADMINISTRATIVO DE GERENCIA GENERAL | E13: EMPLEADO | F13: GERENCIA GENERAL | G13: Gerencia General
A14: 290 | B14: MELVIN ENRIQUE PORTILLO VALLE | C14: 24/07/2002 | D14: ANALISTA DE RIESGOS FINANCIEROS | E14: EMPLEADO | F14: ADMINISTRACION DE RIESGOS | G14: Gerencia General
A15: 408 | B15: SARA PATRICIA GONZALEZ JIMENEZ | C15: 02/07/2007 | D15: ASISTENTE TECNICO DE RIESGOS | E15: EMPLEADO | F15: ADMINISTRACION DE RIESGOS | G15: Gerencia General
A16: 433 | B16: SILVIA IVETH MARTINEZ RAMIREZ | C16: 01/08/2008 | D16: ANALISTA DE RIESGO OPERACIONAL | E16: EMPLEADO | F16: ADMINISTRACION DE RIESGOS | G16: Gerencia General
... A48: 973 | B48: HUGO ROLANDO VELASCO RIVERA | C48: 02/07/2026 | D48: AUXILIAR DE CUSTODIA DE VALORES | E48: EMPLEADO | F48: DEPARTAMENTO DE CUSTODIA DE GARANTÍA Y VALORES | G48: Gerencia Administrativa
A49: 65 | B49: DORA ALICIA CASTILLO | C49: 16/08/1988 | D49: JEFE DE TALENTO HUMANO | E49: EMPLEADO | F49: DEPARTAMENTO DE TALENTO HUMANO | G49: Gerencia Administrativa | H49: Vacaciones
A50: 948 | B50: NELSON KILDER QUIJADA ECHEVERRIA | C50: 20/10/2025 | D50: ASISTENTE TECNICO DE TALENTO HUMANO | E50: EMPLEADO | F50: DEPARTAMENTO DE TALENTO HUMANO | G50: Gerencia Administrativa
A51: 962 | B51: HELEN GLORIBEL PLATERO SANCHEZ | C51: 08/04/2026 | D51: ANALISTA DE DESARROLLO ORGANIZACIONAL | E51: EMPLEADO | F51: DEPARTAMENTO DE TALENTO HUMANO | G51: Gerencia Administrativa
A52: 452 | B52: SERGIO ARTURO CALDERON SALAZAR | C52: 11/01/2010 | D52: COORDINADOR DE SEGURIDAD | E52: EMPLEADO | F52: DEPARTAMENTO DE SEGURIDAD | G52: Gerencia Administrativa
A53: 901 | B53: CARLOS ALEJANDRO MARAVILLA MENDEZ | C53: 14/10/2024 | D53: OPERADOR DE MONITOREO DE LOS SISTEMAS DE SEGURIDAD | E53: EMPLEADO | F53: DEPARTAMENTO DE SEGURIDAD | G53: Gerencia Administrativa
A54: 590 | B54: LORENA ELIZABETH GALDAMEZ NUÑEZ | C54: 23/03/2017 | D54: MEDICO | E54: EMPLEADO | F54: CLINICA EMPRESARIAL | G54: Gerencia Administrativa
A55: 609 | B55: GLADIS OSIRIS VALLE HERNANDEZ | C55: 02/01/2018 | D55: ENFERMERA | E55: EMPLEADO | F55: CLINICA EMPRESARIAL | G55: Gerencia Administrativa
A56: 847 | B56: ZULEYMA ALEJANDRA VASQUEZ MARIN | C56: 18/12/2023 | D56: JEFE DE EDUCACION Y RESPONSABILIDAD SOCIAL | E56: EMPLEADO | F56: DEPARTAMENTO DE EDUCACION Y RESPONSABILIDAD SOCIAL | G56: Gerencia Administrativa
A57: 853 | B57: STEPHANIE CAROLINA MALDONADO FLORES | C57: 05/02/2024 | D57: ASISTENTE TECNICO DEPARTAMENTO DE EDUCACION Y RESPONSABILIDA | E57: EMPLEADO | F57: DEPARTAMENTO DE EDUCACION Y RESPONSABILIDAD SOCIAL | G57: Gerencia Administrativa
A58: 919 | B58: CARLOS EDUARDO SERVELLON PEREZ | C58: 23/04/2025 | D58: AUXILIAR DE EDUCACION Y RESPONSABILIDAD SOCIAL | E58: EMPLEADO | F58: DEPARTAMENTO DE EDUCACION Y RESPONSABILIDAD SOCIAL | G58: Gerencia Administrativa
A59: 34 | B59: YENIS MARILU ESCOBAR SORTO | C59: 06/05/1996 | D59: EJECUTIVO DE SOLUCIONES FINANCIERAS | E59: EMPLEADO | F59: DEPARTAMENTO DE SOLUCIONES FINANCIERAS | G59: Gerencia de Operaciones
A60: 182 | B60: ROSA ELIZABETH RIVAS AGUILUZ | C60: 20/05/1999 | D60: EJECUTIVO DE SOLUCIONES FINANCIERAS | E60: EMPLEADO | F60: DEPARTAMENTO DE SOLUCIONES FINANCIERAS | G60: Gerencia de Operaciones
A61: 263 | B61: XOCHILT VERONICA NOUBLEAU | C61: 27/08/2001 | D61: EJECUTIVO DE SOLUCIONES FINANCIERAS | E61: EMPLEADO | F61: DEPARTAMENTO DE SOLUCIONES FINANCIERAS | G61: Gerencia de Operaciones
... A67: 573 | B67: JUAN PABLO HENRIQUEZ RAMIREZ | C67: 01/09/2016 | D67: EJECUTIVO DE SOLUCIONES FINANCIERAS | E67: EMPLEADO | F67: DEPARTAMENTO DE SOLUCIONES FINANCIERAS | G67: Gerencia de Operaciones
A68: 885 | B68: ALBA BEATRIZ MELENDEZ PRUDENCIO | C68: 19/08/2024 | D68: ASISTENTE DE RECUPERACION JUDICIAL Y CARTERA CASTIGADA | E68: EMPLEADO | F68: DEPARTAMENTO DE SOLUCIONES FINANCIERAS | G68: Gerencia de Operaciones | H68: Renuncia
A69: 389 | B69: CLAUDIA CAROLINA HERNANDEZ DE PAZ | C69: 27/10/2006 | D69: ASISTENTE TECNICO DE INTERCAMBIO DE TARJETAS | E69: EMPLEADO | F69: DEPARTAMENTO DE TARJETA DE CREDITO Y DEBITO | G69: Gerencia de Operaciones
A70: 399 | B70: GEOVANNI LIZAMA PORTILLO | C70: 22/02/2007 | D70: JEFE DE TARJETA DE CREDITO Y DEBITO | E70: EMPLEADO | F70: DEPARTAMENTO DE TARJETA DE CREDITO Y DEBITO | G70: Gerencia de Operaciones | H70: Incapacidad
A71: 459 | B71: LUIS ALEXANDER RAMIREZ MONTALVO | C71: 24/05/2010 | D71: ASISTENTE TECNICO DE EMISION DE TARJETA | E71: EMPLEADO | F71: DEPARTAMENTO DE TARJETA DE CREDITO Y DEBITO | G71: Gerencia de Operaciones
A72: 725 | B72: ANA BEATRIZ QUINTEROS AVELAR | C72: 09/08/2021 | D72: ASISTENTE TECNICO DE OPERACIONES DE TARJETAS | E72: EMPLEADO | F72: DEPARTAMENTO DE TARJETA DE CREDITO Y DEBITO | G72: Gerencia de Operaciones
A73: 952 | B73: ANDREA CAROLINA RUMUALDO MARTINEZ | C73: 16/12/2025 | D73: AUXILIAR DE CONTROL DE CALIDAD | E73: EMPLEADO | F73: DEPARTAMENTO DE TARJETA DE CREDITO Y DEBITO | G73: Gerencia de Operaciones
A74: 980 | B74: FATIMA ELIZABETH LEMUS RODRIGUEZ | C74: 26/08/2026 | D74: AUXILIAR DE EMISION DE TARJETA | E74: EMPLEADO | F74: DEPARTAMENTO DE TARJETA DE CREDITO Y DEBITO | G74: Gerencia de Operaciones
A75: 284 | B75: MARIO ANTONIO NAVARRO PINEDA | C75: 05/05/2008 | D75: JEFE DE DEPOSITOS | E75: EMPLEADO | F75: DEPARTAMENTO DE DEPOSITOS | G75: Gerencia de Operaciones
A76: 632 | B76: LUCILA MARGARITA CORCIO QUINTANILLA | C76: 19/11/2018 | D76: ASISTENTE COMPENSADOR DE CHEQUES | E76: EMPLEADO | F76: DEPARTAMENTO DE DEPOSITOS | G76: Gerencia de Operaciones
A77: 773 | B77: HELLEN ESTEFANI RODRIGUEZ GARCIA | C77: 19/09/2022 | D77: ASISTENTE COMPENSADOR DE CHEQUES | E77: EMPLEADO | F77: DEPARTAMENTO DE DEPOSITOS | G77: Gerencia de Operaciones
...

Sheet Base Exámenes
A1: REGISTROS CRUDOS DEL EXAMEN
A2: Datos exportados de la plataforma de evaluaciones
A4: Nombre en Examen | B4: Área en Examen | C4: Código de Empleado | D4: Hora de Inicio | E4: Hora de Finalización | F4: Duración (min) | G4: Nota | H4: Correo | I4: Clave auxiliar (no editar)
A5: José Augusto De la O Gallegos | B5: Gerencia de Finanzas y Planificación | C5: 524 | D5: 46296.427 | E5: 46296.43 | F5: =IF(OR(D5="",E5=""),"",(E5-D5)*1440) -> 3.6 | G5: 100 | H5: anonymous | I5: =IF(C5="","",C5&"|"&G5) -> 524|100
A6: Henry Oswaldo Pineda García | B6: Seguros | C6: 894 | D6: 46296.426 | E6: 46296.432 | F6: =IF(OR(D6="",E6=""),"",(E6-D6)*1440) -> 7.8666667 | G6: 100 | H6: anonymous | I6: =IF(C6="","",C6&"|"&G6) -> 894|100
A7: Sara Patricia González de Jiménez | B7: Departamento de Riesgos | C7: 408 | D7: 46296.437 | E7: 46296.439 | F7: =IF(OR(D7="",E7=""),"",(E7-D7)*1440) -> 3.05 | G7: 100 | H7: anonymous | I7: =IF(C7="","",C7&"|"&G7) -> 408|100
A8: THELMA ESPERANZA DIGUEROA DE SORTO | B8: AGENCIA SAN MIGUEL | C8: 197 | D8: 46296.435 | E8: 46296.441 | F8: =IF(OR(D8="",E8=""),"",(E8-D8)*1440) -> 8.25 | G8: 100 | H8: anonymous | I8: =IF(C8="","",C8&"|"&G8) -> 197|100
A9: Mauricio Edgardo Miranda Campos | B9: Procesos | C9: 817 | D9: 46296.437 | E9: 46296.441 | F9: =IF(OR(D9="",E9=""),"",(E9-D9)*1440) -> 6.8 | G9: 100 | H9: anonymous | I9: =IF(C9="","",C9&"|"&G9) -> 817|100
A10: Héctor Sebastián López Granados | B10: Procesos | C10: 932 | D10: 46296.437 | E10: 46296.441 | F10: =IF(OR(D10="",E10=""),"",(E10-D10)*1440) -> 6.1166667 | G10: 100 | H10: anonymous | I10: =IF(C10="","",C10&"|"&G10) -> 932|100
A11: Claudia Carolina Henríquez Velasco | B11: Procesos | C11: 318 | D11: 46296.437 | E11: 46296.441 | F11: =IF(OR(D11="",E11=""),"",(E11-D11)*1440) -> 7.0833333 | G11: 100 | H11: anonymous | I11: =IF(C11="","",C11&"|"&G11) -> 318|100
A12: DIEGO GERARDO GUANDIQUE TORRES | B12: AGENCIA SAN MIGUEL | C12: 776 | D12: 46296.443 | E12: 46296.445 | F12: =IF(OR(D12="",E12=""),"",(E12-D12)*1440) -> 3.4 | G12: 100 | H12: anonymous | I12: =IF(C12="","",C12&"|"&G12) -> 776|100
A13: Martha Lorena González González | B13: San Miguel | C13: 390 | D13: 46296.446 | E13: 46296.448 | F13: =IF(OR(D13="",E13=""),"",(E13-D13)*1440) -> 3 | G13: 100 | H13: anonymous | I13: =IF(C13="","",C13&"|"&G13) -> 390|100
A14: Jennifer Georgina Alvarado de Hernández | B14: Seguridad de la Informacion y Ciberseguridad | C14: 907 | D14: 46296.442 | E14: 46296.449 | F14: =IF(OR(D14="",E14=""),"",(E14-D14)*1440) -> 9.0666667 | G14: 85 | H14: anonymous | I14: =IF(C14="","",C14&"|"&G14) -> 907|85
A15: Marvin Alonso Franco Ramirez | B15: Seguridad de la información y ciberseguridad | C15: 918 | D15: 46296.442 | E15: 46296.449 | F15: =IF(OR(D15="",E15=""),"",(E15-D15)*1440) -> 9.6333333 | G15: 100 | H15: anonymous | I15: =IF(C15="","",C15&"|"&G15) -> 918|100
A16: María Azucena Bonilla Rivera | B16: Seguridad de la Información | C16: 710 | D16: 46296.441 | E16: 46296.449 | F16: =IF(OR(D16="",E16=""),"",(E16-D16)*1440) -> 11.733333 | G16: 100 | H16: anonymous | I16: =IF(C16="","",C16&"|"&G16) -> 710|100
... A293: ROQUE RAFAEL REYES ESPINAL | B293: GERENCIA DE OPERACIONES | C293: 41 | D293: 46311.803 | E293: 46311.814 | F293: =IF(OR(D293="",E293=""),"",(E293-D293)*1440) -> 15.85 | G293: 100 | H293: anonymous | I293: =IF(C293="","",C293&"|"&G293) -> 41|100
A294: NELSON ULISES CAMPOS FLORES | B294: GERENCIA GENERAL | C294: 977 | F294: =IF(OR(D294="",E294=""),"",(E294-D294)*1440) | H294: REGISTRO MANUAL: examen realizado (confirmado por la administración; sin nota ni fecha en la plataforma) | I294: =IF(C294="","",C294&"|"&G294) -> 977|
F295: =IF(OR(D295="",E295=""),"",(E295-D295)*1440) | I295: =IF(C295="","",C295&"|"&G295)
F296: =IF(OR(D296="",E296=""),"",(E296-D296)*1440) | I296: =IF(C296="","",C296&"|"&G296)
F297: =IF(OR(D297="",E297=""),"",(E297-D297)*1440) | I297: =IF(C297="","",C297&"|"&G297)
F298: =IF(OR(D298="",E298=""),"",(E298-D298)*1440) | I298: =IF(C298="","",C298&"|"&G298)
F299: =IF(OR(D299="",E299=""),"",(E299-D299)*1440) | I299: =IF(C299="","",C299&"|"&G299)
F300: =IF(OR(D300="",E300=""),"",(E300-D300)*1440) | I300: =IF(C300="","",C300&"|"&G300)
F301: =IF(OR(D301="",E301=""),"",(E301-D301)*1440) | I301: =IF(C301="","",C301&"|"&G301)
F302: =IF(OR(D302="",E302=""),"",(E302-D302)*1440) | I302: =IF(C302="","",C302&"|"&G302)
F303: =IF(OR(D303="",E303=""),"",(E303-D303)*1440) | I303: =IF(C303="","",C303&"|"&G303)
F304: =IF(OR(D304="",E304=""),"",(E304-D304)*1440) | I304: =IF(C304="","",C304&"|"&G304)
F305: =IF(OR(D305="",E305=""),"",(E305-D305)*1440) | I305: =IF(C305="","",C305&"|"&G305)
F306: =IF(OR(D306="",E306=""),"",(E306-D306)*1440) | I306: =IF(C306="","",C306&"|"&G306)
... F1000: =IF(OR(D1000="",E1000=""),"",(E1000-D1000)*1440) | I1000: =IF(C1000="","",C1000&"|"&G1000)

Sheet Detalle individual
A1: DETALLE INDIVIDUAL DE PARTICIPANTES
A2: Cruce oficial por Código de Empleado frente a la Base Oficial y Base Exámenes.
A4: Código de empleado | B4: Nombre del colaborador | C4: Área / Departamento | D4: Gerencia Asignada | E4: Cargo | F4: Estado Examen | G4: Hora de inicio | H4: Hora de finalización | I4: Duración (min) | J4: Nota | K4: Correo | L4: N° de intentos | M4: Situación especial (vigente)
A5: =IF('Base Oficial'!A5="","",TRIM('Base Oficial'!A5)) -> 977 | B5: =IF($A5="","",TRIM('Base Oficial'!B5)) -> NELSON ULISES CAMPOS FLORES | C5: =IF($A5="","",TRIM('Base Oficial'!F5)) -> GERENCIA GENERAL | D5: =IF($A5="","",TRIM('Base Oficial'!G5)) -> Gerencia General | E5: =IF($A5="","",TRIM('Base Oficial'!D5)) -> GERENTE GENERAL | F5: =IF($A5="","",IF(COUNTIF('Base Exámenes'!$C$5:$C$1000, A5)>0, "Completado", IF(M5<>"", M5, "Pendiente"))) -> Completado | G5: =IF(F5="Completado", IFERROR(IF(INDEX('Base Exámenes'!$D$5:$D$1000, MATCH(A5&"|"&J5, 'Base Exámenes'!$I$5:$I$1000, 0))="", "", INDEX('Base Exámenes'!$D$5:$D$1000, MATCH(A5&"|"&J5, 'Base Exámenes'!$I$5:$I$1000, 0))), ""), "") | H5: =IF(F5="Completado", IFERROR(IF(INDEX('Base Exámenes'!$E$5:$E$1000, MATCH(A5&"|"&J5, 'Base Exámenes'!$I$5:$I$1000, 0))="", "", INDEX('Base Exámenes'!$E$5:$E$1000, MATCH(A5&"|"&J5, 'Base Exámenes'!$I$5:$I$1000, 0))), ""), "") | I5: =IF(F5="Completado", IFERROR(IF(INDEX('Base Exámenes'!$F$5:$F$1000, MATCH(A5&"|"&J5, 'Base Exámenes'!$I$5:$I$1000, 0))="", "", INDEX('Base Exámenes'!$F$5:$F$1000, MATCH(A5&"|"&J5, 'Base Exámenes'!$I$5:$I$1000, 0))), ""), "") | J5: =IF(F5="Completado", IF(COUNTIFS('Base Exámenes'!$C$5:$C$1000, A5, 'Base Exámenes'!$G$5:$G$1000, "<>")=0, "", _xlfn.MAXIFS('Base Exámenes'!$G$5:$G$1000, 'Base Exámenes'!$C$5:$C$1000, A5)), "") | K5: =IF(F5="Completado", IFERROR(IF(INDEX('Base Exámenes'!$H$5:$H$1000, MATCH(A5&"|"&J5, 'Base Exámenes'!$I$5:$I$1000, 0))="", "", INDEX('Base Exámenes'!$H$5:$H$1000, MATCH(A5&"|"&J5, 'Base Exámenes'!$I$5:$I$1000, 0))), ""), "") -> REGISTRO MANUAL: examen realizado (confirmado por la administración; sin nota ni fecha en la plataforma) | L5: =IF($A5="","",COUNTIF('Base Exámenes'!$C$5:$C$1000, A5)) -> 1 | M5: =IF($A5="","",IF(COUNTIF('Base Exámenes'!$C$5:$C$1000, A5)>0, "", TRIM('Base Oficial'!H5)))
A6: =IF('Base Oficial'!A6="","",TRIM('Base Oficial'!A6)) -> 349 | B6: =IF($A6="","",TRIM('Base Oficial'!B6)) -> CARLA EUGENIA HERNANDEZ MENJIVAR | C6: =IF($A6="","",TRIM('Base Oficial'!F6)) -> GERENCIA ADMINISTRATIVA | D6: =IF($A6="","",TRIM('Base Oficial'!G6)) -> Gerencia Administrativa | E6: =IF($A6="","",TRIM('Base Oficial'!D6)) -> GERENTE ADMINISTRATIVA | F6: =IF($A6="","",IF(COUNTIF('Base Exámenes'!$C$5:$C$1000, A6)>0, "Completado", IF(M6<>"", M6, "Pendiente"))) -> Completado | G6: =IF(F6="Completado", IFERROR(IF(INDEX('Base Exámenes'!$D$5:$D$1000, MATCH(A6&"|"&J6, 'Base Exámenes'!$I$5:$I$1000, 0))="", "", INDEX('Base Exámenes'!$D$5:$D$1000, MATCH(A6&"|"&J6, 'Base Exámenes'!$I$5:$I$1000, 0))), ""), "") -> 46297.637 | H6: =IF(F6="Completado", IFERROR(IF(INDEX('Base Exámenes'!$E$5:$E$1000, MATCH(A6&"|"&J6, 'Base Exámenes'!$I$5:$I$1000, 0))="", "", INDEX('Base Exámenes'!$E$5:$E$1000, MATCH(A6&"|"&J6, 'Base Exámenes'!$I$5:$I$1000, 0))), ""), "") -> 46297.638 | I6: =IF(F6="Completado", IFERROR(IF(INDEX('Base Exámenes'!$F$5:$F$1000, MATCH(A6&"|"&J6, 'Base Exámenes'!$I$5:$I$1000, 0))="", "", INDEX('Base Exámenes'!$F$5:$F$1000, MATCH(A6&"|"&J6, 'Base Exámenes'!$I$5:$I$1000, 0))), ""), "") -> 2.3 | J6: =IF(F6="Completado", IF(COUNTIFS('Base Exámenes'!$C$5:$C$1000, A6, 'Base Exámenes'!$G$5:$G$1000, "<>")=0, "", _xlfn.MAXIFS('Base Exámenes'!$G$5:$G$1000, 'Base Exámenes'!$C$5:$C$1000, A6)), "") -> 100 | K6: =IF(F6="Completado", IFERROR(IF(INDEX('Base Exámenes'!$H$5:$H$1000, MATCH(A6&"|"&J6, 'Base Exámenes'!$I$5:$I$1000, 0))="", "", INDEX('Base Exámenes'!$H$5:$H$1000, MATCH(A6&"|"&J6, 'Base Exámenes'!$I$5:$I$1000, 0))), ""), "") -> anonymous | L6: =IF($A6="","",COUNTIF('Base Exámenes'!$C$5:$C$1000, A6)) -> 1 | M6: =IF($A6="","",IF(COUNTIF('Base Exámenes'!$C$5:$C$1000, A6)>0, "", TRIM('Base Oficial'!H6)))
A7: =IF('Base Oficial'!A7="","",TRIM('Base Oficial'!A7)) -> 41 | B7: =IF($A7="","",TRIM('Base Oficial'!B7)) -> ROQUE RAFAEL REYES ESPINAL | C7: =IF($A7="","",TRIM('Base Oficial'!F7)) -> GERENCIA DE OPERACIONES | D7: =IF($A7="","",TRIM('Base Oficial'!G7)) -> Gerencia de Operaciones | E7: =IF($A7="","",TRIM('Base Oficial'!D7)) -> GERENTE DE OPERACIONES | F7: =IF($A7="","",IF(COUNTIF('Base Exámenes'!$C$5:$C$1000, A7)>0, "Completado", IF(M7<>"", M7, "Pendiente"))) -> Completado | G7: =IF(F7="Completado", IFERROR(IF(INDEX('Base Exámenes'!$D$5:$D$1000, MATCH(A7&"|"&J7, 'Base Exámenes'!$I$5:$I$1000, 0))="", "", INDEX('Base Exámenes'!$D$5:$D$1000, MATCH(A7&"|"&J7, 'Base Exámenes'!$I$5:$I$1000, 0))), ""), "") -> 46311.803 | H7: =IF(F7="Completado", IFERROR(IF(INDEX('Base Exámenes'!$E$5:$E$1000, MATCH(A7&"|"&J7, 'Base Exámenes'!$I$5:$I$1000, 0))="", "", INDEX('Base Exámenes'!$E$5:$E$1000, MATCH(A7&"|"&J7, 'Base Exámenes'!$I$5:$I$1000, 0))), ""), "") -> 46311.814 | I7: =IF(F7="Completado", IFERROR(IF(INDEX('Base Exámenes'!$F$5:$F$1000, MATCH(A7&"|"&J7, 'Base Exámenes'!$I$5:$I$1000, 0))="", "", INDEX('Base Exámenes'!$F$5:$F$1000, MATCH(A7&"|"&J7, 'Base Exámenes'!$I$5:$I$1000, 0))), ""), "") -> 15.85 | J7: =IF(F7="Completado", IF(COUNTIFS('Base Exámenes'!$C$5:$C$1000, A7, 'Base Exámenes'!$G$5:$G$1000, "<>")=0, "", _xlfn.MAXIFS('Base Exámenes'!$G$5:$G$1000, 'Base Exámenes'!$C$5:$C$1000, A7)), "") -> 100 | K7: =IF(F7="Completado", IFERROR(IF(INDEX('Base Exámenes'!$H$5:$H$1000, MATCH(A7&"|"&J7, 'Base Exámenes'!$I$5:$I$1000, 0))="", "", INDEX('Base Exámenes'!$H$5:$H$1000, MATCH(A7&"|"&J7, 'Base Exámenes'!$I$5:$I$1000, 0))), ""), "") -> anonymous | L7: =IF($A7="","",COUNTIF('Base Exámenes'!$C$5:$C$1000, A7)) -> 1 | M7: =IF($A7="","",IF(COUNTIF('Base Exámenes'!$C$5:$C$1000, A7)>0, "", TRIM('Base Oficial'!H7)))
A8: =IF('Base Oficial'!A8="","",TRIM('Base Oficial'!A8)) -> 524 | B8: =IF($A8="","",TRIM('Base Oficial'!B8)) -> JOSE AUGUSTO DE LA O GALLEGOS | C8: =IF($A8="","",TRIM('Base Oficial'!F8)) -> GERENCIA DE FINANZAS Y PLANIFICACIÓN | D8: =IF($A8="","",TRIM('Base Oficial'!G8)) -> Gerencia de Finanzas y Planificación | E8: =IF($A8="","",TRIM('Base Oficial'!D8)) -> GERENTE DE FINANZAS Y PLANIFICACION | F8: =IF($A8="","",IF(COUNTIF('Base Exámenes'!$C$5:$C$1000, A8)>0, "Completado", IF(M8<>"", M8, "Pendiente"))) -> Completado | G8: =IF(F8="Completado", IFERROR(IF(INDEX('Base Exámenes'!$D$5:$D$1000, MATCH(A8&"|"&J8, 'Base Exámenes'!$I$5:$I$1000, 0))="", "", INDEX('Base Exámenes'!$D$5:$D$1000, MATCH(A8&"|"&J8, 'Base Exámenes'!$I$5:$I$1000, 0))), ""), "") -> 46296.427 | H8: =IF(F8="Completado", IFERROR(IF(INDEX('Base Exámenes'!$E$5:$E$1000, MATCH(A8&"|"&J8, 'Base Exámenes'!$I$5:$I$1000, 0))="", "", INDEX('Base Exámenes'!$E$5:$E$1000, MATCH(A8&"|"&J8, 'Base Exámenes'!$I$5:$I$1000, 0))), ""), "") -> 46296.43 | I8: =IF(F8="Completado", IFERROR(IF(INDEX('Base Exámenes'!$F$5:$F$1000, MATCH(A8&"|"&J8, 'Base Exámenes'!$I$5:$I$1000, 0))="", "", INDEX('Base Exámenes'!$F$5:$F$1000, MATCH(A8&"|"&J8, 'Base Exámenes'!$I$5:$I$1000, 0))), ""), "") -> 3.6 | J8: =IF(F8="Completado", IF(COUNTIFS('Base Exámenes'!$C$5:$C$1000, A8, 'Base Exámenes'!$G$5:$G$1000, "<>")=0, "", _xlfn.MAXIFS('Base Exámenes'!$G$5:$G$1000, 'Base Exámenes'!$C$5:$C$1000, A8)), "") -> 100 | K8: =IF(F8="Completado", IFERROR(IF(INDEX('Base Exámenes'!$H$5:$H$1000, MATCH(A8&"|"&J8, 'Base Exámenes'!$I$5:$I$1000, 0))="", "", INDEX('Base Exámenes'!$H$5:$H$1000, MATCH(A8&"|"&J8, 'Base Exámenes'!$I$5:$I$1000, 0))), ""), "") -> anonymous | L8: =IF($A8="","",COUNTIF('Base Exámenes'!$C$5:$C$1000, A8)) -> 1 | M8: =IF($A8="","",IF(COUNTIF('Base Exámenes'!$C$5:$C$1000, A8)>0, "", TRIM('Base Oficial'!H8)))
A9: =IF('Base Oficial'!A9="","",TRIM('Base Oficial'!A9)) -> 878 | B9: =IF($A9="","",TRIM('Base Oficial'!B9)) -> ALEX VIRGILIO AGUILAR ARIAS | C9: =IF($A9="","",TRIM('Base Oficial'!F9)) -> GERENCIA DE SISTEMAS | D9: =IF($A9="","",TRIM('Base Oficial'!G9)) -> Gerencia de Sistemas | E9: =IF($A9="","",TRIM('Base Oficial'!D9)) -> GERENTE DE SISTEMAS | F9: =IF($A9="","",IF(COUNTIF('Base Exámenes'!$C$5:$C$1000, A9)>0, "Completado", IF(M9<>"", M9, "Pendiente"))) -> Completado | G9: =IF(F9="Completado", IFERROR(IF(INDEX('Base Exámenes'!$D$5:$D$1000, MATCH(A9&"|"&J9, 'Base Exámenes'!$I$5:$I$1000, 0))="", "", INDEX('Base Exámenes'!$D$5:$D$1000, MATCH(A9&"|"&J9, 'Base Exámenes'!$I$5:$I$1000, 0))), ""), "") -> 46310.692 | H9: =IF(F9="Completado", IFERROR(IF(INDEX('Base Exámenes'!$E$5:$E$1000, MATCH(A9&"|"&J9, 'Base Exámenes'!$I$5:$I$1000, 0))="", "", INDEX('Base Exámenes'!$E$5:$E$1000, MATCH(A9&"|"&J9, 'Base Exámenes'!$I$5:$I$1000, 0))), ""), "") -> 46310.697 | I9: =IF(F9="Completado", IFERROR(IF(INDEX('Base Exámenes'!$F$5:$F$1000, MATCH(A9&"|"&J9, 'Base Exámenes'!$I$5:$I$1000, 0))="", "", INDEX('Base Exámenes'!$F$5:$F$1000, MATCH(A9&"|"&J9, 'Base Exámenes'!$I$5:$I$1000, 0))), ""), "") -> 7.1333333 | J9: =IF(F9="Completado", IF(COUNTIFS('Base Exámenes'!$C$5:$C$1000, A9, 'Base Exámenes'!$G$5:$G$1000, "<>")=0, "", _xlfn.MAXIFS('Base Exámenes'!$G$5:$G$1000, 'Base Exámenes'!$C$5:$C$1000, A9)), "") -> 100 | K9: =IF(F9="Completado", IFERROR(IF(INDEX('Base Exámenes'!$H$5:$H$1000, MATCH(A9&"|"&J9, 'Base Exámenes'!$I$5:$I$1000, 0))="", "", INDEX('Base Exámenes'!$H$5:$H$1000, MATCH(A9&"|"&J9, 'Base Exámenes'!$I$5:$I$1000, 0))), ""), "") -> anonymous | L9: =IF($A9="","",COUNTIF('Base Exámenes'!$C$5:$C$1000, A9)) -> 1 | M9: =IF($A9="","",IF(COUNTIF('Base Exámenes'!$C$5:$C$1000, A9)>0, "", TRIM('Base Oficial'!H9)))
A10: =IF('Base Oficial'!A10="","",TRIM('Base Oficial'!A10)) -> 862 | B10: =IF($A10="","",TRIM('Base Oficial'!B10)) -> GEORGI ROBERTO CASTILLO CHACON | C10: =IF($A10="","",TRIM('Base Oficial'!F10)) -> OFICIALIA DE CUMPLIMIENTO | D10: =IF($A10="","",TRIM('Base Oficial'!G10)) -> Gerencia de Oficialía de Cumplimiento | E10: =IF($A10="","",TRIM('Base Oficial'!D10)) -> GERENTE DE OFICIALIA DE CUMPLIMIENTO | F10: =IF($A10="","",IF(COUNTIF('Base Exámenes'!$C$5:$C$1000, A10)>0, "Completado", IF(M10<>"", M10, "Pendiente"))) -> Completado | G10: =IF(F10="Completado", IFERROR(IF(INDEX('Base Exámenes'!$D$5:$D$1000, MATCH(A10&"|"&J10, 'Base Exámenes'!$I$5:$I$1000, 0))="", "", INDEX('Base Exámenes'!$D$5:$D$1000, MATCH(A10&"|"&J10, 'Base Exámenes'!$I$5:$I$1000, 0))), ""), "") -> 46296.47 | H10: =IF(F10="Completado", IFERROR(IF(INDEX('Base Exámenes'!$E$5:$E$1000, MATCH(A10&"|"&J10, 'Base Exámenes'!$I$5:$I$1000, 0))="", "", INDEX('Base Exámenes'!$E$5:$E$1000, MATCH(A10&"|"&J10, 'Base Exámenes'!$I$5:$I$1000, 0))), ""), "") -> 46296.477 | I10: =IF(F10="Completado", IFERROR(IF(INDEX('Base Exámenes'!$F$5:$F$1000, MATCH(A10&"|"&J10, 'Base Exámenes'!$I$5:$I$1000, 0))="", "", INDEX('Base Exámenes'!$F$5:$F$1000, MATCH(A10&"|"&J10, 'Base Exámenes'!$I$5:$I$1000, 0))), ""), "") -> 10.466667 | J10: =IF(F10="Completado", IF(COUNTIFS('Base Exámenes'!$C$5:$C$1000, A10, 'Base Exámenes'!$G$5:$G$1000, "<>")=0, "", _xlfn.MAXIFS('Base Exámenes'!$G$5:$G$1000, 'Base Exámenes'!$C$5:$C$1000, A10)), "") -> 100 | K10: =IF(F10="Completado", IFERROR(IF(INDEX('Base Exámenes'!$H$5:$H$1000, MATCH(A10&"|"&J10, 'Base Exámenes'!$I$5:$I$1000, 0))="", "", INDEX('Base Exámenes'!$H$5:$H$1000, MATCH(A10&"|"&J10, 'Base Exámenes'!$I$5:$I$1000, 0))), ""), "") -> anonymous | L10: =IF($A10="","",COUNTIF('Base Exámenes'!$C$5:$C$1000, A10)) -> 1 | M10: =IF($A10="","",IF(COUNTIF('Base Exámenes'!$C$5:$C$1000, A10)>0, "", TRIM('Base Oficial'!H10)))
A11: =IF('Base Oficial'!A11="","",TRIM('Base Oficial'!A11)) -> 741 | B11: =IF($A11="","",TRIM('Base Oficial'!B11)) -> JOSE HUMBERTO BARILLAS BURGOS | C11: =IF($A11="","",TRIM('Base Oficial'!F11)) -> GERENCIA DE NEGOCIOS | D11: =IF($A11="","",TRIM('Base Oficial'!G11)) -> Gerencia de Negocios | E11: =IF($A11="","",TRIM('Base Oficial'!D11)) -> GERENTE DE NEGOCIOS | F11: =IF($A11="","",IF(COUNTIF('Base Exámenes'!$C$5:$C$1000, A11)>0, "Completado", IF(M11<>"", M11, "Pendiente"))) -> Completado | G11: =IF(F11="Completado", IFERROR(IF(INDEX('Base Exámenes'!$D$5:$D$1000, MATCH(A11&"|"&J11, 'Base Exámenes'!$I$5:$I$1000, 0))="", "", INDEX('Base Exámenes'!$D$5:$D$1000, MATCH(A11&"|"&J11, 'Base Exámenes'!$I$5:$I$1000, 0))), ""), "") -> 46310.616 | H11: =IF(F11="Completado", IFERROR(IF(INDEX('Base Exámenes'!$E$5:$E$1000, MATCH(A11&"|"&J11, 'Base Exámenes'!$I$5:$I$1000, 0))="", "", INDEX('Base Exámenes'!$E$5:$E$1000, MATCH(A11&"|"&J11, 'Base Exámenes'!$I$5:$I$1000, 0))), ""), "") -> 46310.62 | I11: =IF(F11="Completado", IFERROR(IF(INDEX('Base Exámenes'!$F$5:$F$1000, MATCH(A11&"|"&J11, 'Base Exámenes'!$I$5:$I$1000, 0))="", "", INDEX('Base Exámenes'!$F$5:$F$1000, MATCH(A11&"|"&J11, 'Base Exámenes'!$I$5:$I$1000, 0))), ""), "") -> 4.85 | J11: =IF(F11="Completado", IF(COUNTIFS('Base Exámenes'!$C$5:$C$1000, A11, 'Base Exámenes'!$G$5:$G$1000, "<>")=0, "", _xlfn.MAXIFS('Base Exámenes'!$G$5:$G$1000, 'Base Exámenes'!$C$5:$C$1000, A11)), "") -> 100 | K11: =IF(F11="Completado", IFERROR(IF(INDEX('Base Exámenes'!$H$5:$H$1000, MATCH(A11&"|"&J11, 'Base Exámenes'!$I$5:$I$1000, 0))="", "", INDEX('Base Exámenes'!$H$5:$H$1000, MATCH(A11&"|"&J11, 'Base Exámenes'!$I$5:$I$1000, 0))), ""), "") -> anonymous | L11: =IF($A11="","",COUNTIF('Base Exámenes'!$C$5:$C$1000, A11)) -> 1 | M11: =IF($A11="","",IF(COUNTIF('Base Exámenes'!$C$5:$C$1000, A11)>0, "", TRIM('Base Oficial'!H11)))
A12: =IF('Base Oficial'!A12="","",TRIM('Base Oficial'!A12)) -> 570 | B12: =IF($A12="","",TRIM('Base Oficial'!B12)) -> ANDREA VICTORIA MAYORGA RODRIGUEZ | C12: =IF($A12="","",TRIM('Base Oficial'!F12)) -> GERENCIA LEGAL Y DE CUMPLIMIENTO NORMATIVO | D12: =IF($A12="","",TRIM('Base Oficial'!G12)) -> Gerencia Legal y Cumplimiento Normativo | E12: =IF($A12="","",TRIM('Base Oficial'!D12)) -> GERENTE LEGAL Y DE CUMPLIMIENTO NORMATIVO | F12: =IF($A12="","",IF(COUNTIF('Base Exámenes'!$C$5:$C$1000, A12)>0, "Completado", IF(M12<>"", M12, "Pendiente"))) -> Completado | G12: =IF(F12="Completado", IFERROR(IF(INDEX('Base Exámenes'!$D$5:$D$1000, MATCH(A12&"|"&J12, 'Base Exámenes'!$I$5:$I$1000, 0))="", "", INDEX('Base Exámenes'!$D$5:$D$1000, MATCH(A12&"|"&J12, 'Base Exámenes'!$I$5:$I$1000, 0))), ""), "") -> 46304.693 | H12: =IF(F12="Completado", IFERROR(IF(INDEX('Base Exámenes'!$E$5:$E$1000, MATCH(A12&"|"&J12, 'Base Exámenes'!$I$5:$I$1000, 0))="", "", INDEX('Base Exámenes'!$E$5:$E$1000, MATCH(A12&"|"&J12, 'Base Exámenes'!$I$5:$I$1000, 0))), ""), "") -> 46304.695 | I12: =IF(F12="Completado", IFERROR(IF(INDEX('Base Exámenes'!$F$5:$F$1000, MATCH(A12&"|"&J12, 'Base Exámenes'!$I$5:$I$1000, 0))="", "", INDEX('Base Exámenes'!$F$5:$F$1000, MATCH(A12&"|"&J12, 'Base Exámenes'!$I$5:$I$1000, 0))), ""), "") -> 2.5666667 | J12: =IF(F12="Completado", IF(COUNTIFS('Base Exámenes'!$C$5:$C$1000, A12, 'Base Exámenes'!$G$5:$G$1000, "<>")=0, "", _xlfn.MAXIFS('Base Exámenes'!$G$5:$G$1000, 'Base Exámenes'!$C$5:$C$1000, A12)), "") -> 100 | K12: =IF(F12="Completado", IFERROR(IF(INDEX('Base Exámenes'!$H$5:$H$1000, MATCH(A12&"|"&J12, 'Base Exámenes'!$I$5:$I$1000, 0))="", "", INDEX('Base Exámenes'!$H$5:$H$1000, MATCH(A12&"|"&J12, 'Base Exámenes'!$I$5:$I$1000, 0))), ""), "") -> anonymous | L12: =IF($A12="","",COUNTIF('Base Exámenes'!$C$5:$C$1000, A12)) -> 1 | M12: =IF($A12="","",IF(COUNTIF('Base Exámenes'!$C$5:$C$1000, A12)>0, "", TRIM('Base Oficial'!H12)))
A13: =IF('Base Oficial'!A13="","",TRIM('Base Oficial'!A13)) -> 17 | B13: =IF($A13="","",TRIM('Base Oficial'!B13)) -> ANTONIA SARAI BELTRAN CARBALLO | C13: =IF($A13="","",TRIM('Base Oficial'!F13)) -> GERENCIA GENERAL | D13: =IF($A13="","",TRIM('Base Oficial'!G13)) -> Gerencia General | E13: =IF($A13="","",TRIM('Base Oficial'!D13)) -> ASISTENTE ADMINISTRATIVO DE GERENCIA GENERAL | F13: =IF($A13="","",IF(COUNTIF('Base Exámenes'!$C$5:$C$1000, A13)>0, "Completado", IF(M13<>"", M13, "Pendiente"))) -> Completado | G13: =IF(F13="Completado", IFERROR(IF(INDEX('Base Exámenes'!$D$5:$D$1000, MATCH(A13&"|"&J13, 'Base Exámenes'!$I$5:$I$1000, 0))="", "", INDEX('Base Exámenes'!$D$5:$D$1000, MATCH(A13&"|"&J13, 'Base Exámenes'!$I$5:$I$1000, 0))), ""), "") -> 46305.407 | H13: =IF(F13="Completado", IFERROR(IF(INDEX('Base Exámenes'!$E$5:$E$1000, MATCH(A13&"|"&J13, 'Base Exámenes'!$I$5:$I$1000, 0))="", "", INDEX('Base Exámenes'!$E$5:$E$1000, MATCH(A13&"|"&J13, 'Base Exámenes'!$I$5:$I$1000, 0))), ""), "") -> 46305.41 | I13: =IF(F13="Completado", IFERROR(IF(INDEX('Base Exámenes'!$F$5:$F$1000, MATCH(A13&"|"&J13, 'Base Exámenes'!$I$5:$I$1000, 0))="", "", INDEX('Base Exámenes'!$F$5:$F$1000, MATCH(A13&"|"&J13, 'Base Exámenes'!$I$5:$I$1000, 0))), ""), "") -> 4.5 | J13: =IF(F13="Completado", IF(COUNTIFS('Base Exámenes'!$C$5:$C$1000, A13, 'Base Exámenes'!$G$5:$G$1000, "<>")=0, "", _xlfn.MAXIFS('Base Exámenes'!$G$5:$G$1000, 'Base Exámenes'!$C$5:$C$1000, A13)), "") -> 100 | K13: =IF(F13="Completado", IFERROR(IF(INDEX('Base Exámenes'!$H$5:$H$1000, MATCH(A13&"|"&J13, 'Base Exámenes'!$I$5:$I$1000, 0))="", "", INDEX('Base Exámenes'!$H$5:$H$1000, MATCH(A13&"|"&J13, 'Base Exámenes'!$I$5:$I$1000, 0))), ""), "") -> anonymous | L13: =IF($A13="","",COUNTIF('Base Exámenes'!$C$5:$C$1000, A13)) -> 1 | M13: =IF($A13="","",IF(COUNTIF('Base Exámenes'!$C$5:$C$1000, A13)>0, "", TRIM('Base Oficial'!H13)))
A14: =IF('Base Oficial'!A14="","",TRIM('Base Oficial'!A14)) -> 290 | B14: =IF($A14="","",TRIM('Base Oficial'!B14)) -> MELVIN ENRIQUE PORTILLO VALLE | C14: =IF($A14="","",TRIM('Base Oficial'!F14)) -> ADMINISTRACION DE RIESGOS | D14: =IF($A14="","",TRIM('Base Oficial'!G14)) -> Gerencia General | E14: =IF($A14="","",TRIM('Base Oficial'!D14)) -> ANALISTA DE RIESGOS FINANCIEROS | F14: =IF($A14="","",IF(COUNTIF('Base Exámenes'!$C$5:$C$1000, A14)>0, "Completado", IF(M14<>"", M14, "Pendiente"))) -> Completado | G14: =IF(F14="Completado", IFERROR(IF(INDEX('Base Exámenes'!$D$5:$D$1000, MATCH(A14&"|"&J14, 'Base Exámenes'!$I$5:$I$1000, 0))="", "", INDEX('Base Exámenes'!$D$5:$D$1000, MATCH(A14&"|"&J14, 'Base Exámenes'!$I$5:$I$1000, 0))), ""), "") -> 46304.407 | H14: =IF(F14="Completado", IFERROR(IF(INDEX('Base Exámenes'!$E$5:$E$1000, MATCH(A14&"|"&J14, 'Base Exámenes'!$I$5:$I$1000, 0))="", "", INDEX('Base Exámenes'!$E$5:$E$1000, MATCH(A14&"|"&J14, 'Base Exámenes'!$I$5:$I$1000, 0))), ""), "") -> 46304.41 | I14: =IF(F14="Completado", IFERROR(IF(INDEX('Base Exámenes'!$F$5:$F$1000, MATCH(A14&"|"&J14, 'Base Exámenes'!$I$5:$I$1000, 0))="", "", INDEX('Base Exámenes'!$F$5:$F$1000, MATCH(A14&"|"&J14, 'Base Exámenes'!$I$5:$I$1000, 0))), ""), "") -> 3.9666667 | J14: =IF(F14="Completado", IF(COUNTIFS('Base Exámenes'!$C$5:$C$1000, A14, 'Base Exámenes'!$G$5:$G$1000, "<>")=0, "", _xlfn.MAXIFS('Base Exámenes'!$G$5:$G$1000, 'Base Exámenes'!$C$5:$C$1000, A14)), "") -> 100 | K14: =IF(F14="Completado", IFERROR(IF(INDEX('Base Exámenes'!$H$5:$H$1000, MATCH(A14&"|"&J14, 'Base Exámenes'!$I$5:$I$1000, 0))="", "", INDEX('Base Exámenes'!$H$5:$H$1000, MATCH(A14&"|"&J14, 'Base Exámenes'!$I$5:$I$1000, 0))), ""), "") -> anonymous | L14: =IF($A14="","",COUNTIF('Base Exámenes'!$C$5:$C$1000, A14)) -> 1 | M14: =IF($A14="","",IF(COUNTIF('Base Exámenes'!$C$5:$C$1000, A14)>0, "", TRIM('Base Oficial'!H14)))
A15: =IF('Base Oficial'!A15="","",TRIM('Base Oficial'!A15)) -> 408 | B15: =IF($A15="","",TRIM('Base Oficial'!B15)) -> SARA PATRICIA GONZALEZ JIMENEZ | C15: =IF($A15="","",TRIM('Base Oficial'!F15)) -> ADMINISTRACION DE RIESGOS | D15: =IF($A15="","",TRIM('Base Oficial'!G15)) -> Gerencia General | E15: =IF($A15="","",TRIM('Base Oficial'!D15)) -> ASISTENTE TECNICO DE RIESGOS | F15: =IF($A15="","",IF(COUNTIF('Base Exámenes'!$C$5:$C$1000, A15)>0, "Completado", IF(M15<>"", M15, "Pendiente"))) -> Completado | G15: =IF(F15="Completado", IFERROR(IF(INDEX('Base Exámenes'!$D$5:$D$1000, MATCH(A15&"|"&J15, 'Base Exámenes'!$I$5:$I$1000, 0))="", "", INDEX('Base Exámenes'!$D$5:$D$1000, MATCH(A15&"|"&J15, 'Base Exámenes'!$I$5:$I$1000, 0))), ""), "") -> 46296.437 | H15: =IF(F15="Completado", IFERROR(IF(INDEX('Base Exámenes'!$E$5:$E$1000, MATCH(A15&"|"&J15, 'Base Exámenes'!$I$5:$I$1000, 0))="", "", INDEX('Base Exámenes'!$E$5:$E$1000, MATCH(A15&"|"&J15, 'Base Exámenes'!$I$5:$I$1000, 0))), ""), "") -> 46296.439 | I15: =IF(F15="Completado", IFERROR(IF(INDEX('Base Exámenes'!$F$5:$F$1000, MATCH(A15&"|"&J15, 'Base Exámenes'!$I$5:$I$1000, 0))="", "", INDEX('Base Exámenes'!$F$5:$F$1000, MATCH(A15&"|"&J15, 'Base Exámenes'!$I$5:$I$1000, 0))), ""), "") -> 3.05 | J15: =IF(F15="Completado", IF(COUNTIFS('Base Exámenes'!$C$5:$C$1000, A15, 'Base Exámenes'!$G$5:$G$1000, "<>")=0, "", _xlfn.MAXIFS('Base Exámenes'!$G$5:$G$1000, 'Base Exámenes'!$C$5:$C$1000, A15)), "") -> 100 | K15: =IF(F15="Completado", IFERROR(IF(INDEX('Base Exámenes'!$H$5:$H$1000, MATCH(A15&"|"&J15, 'Base Exámenes'!$I$5:$I$1000, 0))="", "", INDEX('Base Exámenes'!$H$5:$H$1000, MATCH(A15&"|"&J15, 'Base Exámenes'!$I$5:$I$1000, 0))), ""), "") -> anonymous | L15: =IF($A15="","",COUNTIF('Base Exámenes'!$C$5:$C$1000, A15)) -> 1 | M15: =IF($A15="","",IF(COUNTIF('Base Exámenes'!$C$5:$C$1000, A15)>0, "", TRIM('Base Oficial'!H15)))
A16: =IF('Base Oficial'!A16="","",TRIM('Base Oficial'!A16)) -> 433 | B16: =IF($A16="","",TRIM('Base Oficial'!B16)) -> SILVIA IVETH MARTINEZ RAMIREZ | C16: =IF($A16="","",TRIM('Base Oficial'!F16)) -> ADMINISTRACION DE RIESGOS | D16: =IF($A16="","",TRIM('Base Oficial'!G16)) -> Gerencia General | E16: =IF($A16="","",TRIM('Base Oficial'!D16)) -> ANALISTA DE RIESGO OPERACIONAL | F16: =IF($A16="","",IF(COUNTIF('Base Exámenes'!$C$5:$C$1000, A16)>0, "Completado", IF(M16<>"", M16, "Pendiente"))) -> Completado | G16: =IF(F16="Completado", IFERROR(IF(INDEX('Base Exámenes'!$D$5:$D$1000, MATCH(A16&"|"&J16, 'Base Exámenes'!$I$5:$I$1000, 0))="", "", INDEX('Base Exámenes'!$D$5:$D$1000, MATCH(A16&"|"&J16, 'Base Exámenes'!$I$5:$I$1000, 0))), ""), "") -> 46300.622 | H16: =IF(F16="Completado", IFERROR(IF(INDEX('Base Exámenes'!$E$5:$E$1000, MATCH(A16&"|"&J16, 'Base Exámenes'!$I$5:$I$1000, 0))="", "", INDEX('Base Exámenes'!$E$5:$E$1000, MATCH(A16&"|"&J16, 'Base Exámenes'!$I$5:$I$1000, 0))), ""), "") -> 46300.631 | I16: =IF(F16="Completado", IFERROR(IF(INDEX('Base Exámenes'!$F$5:$F$1000, MATCH(A16&"|"&J16, 'Base Exámenes'!$I$5:$I$1000, 0))="", "", INDEX('Base Exámenes'!$F$5:$F$1000, MATCH(A16&"|"&J16, 'Base Exámenes'!$I$5:$I$1000, 0))), ""), "") -> 13.633333 | J16: =IF(F16="Completado", IF(COUNTIFS('Base Exámenes'!$C$5:$C$1000, A16, 'Base Exámenes'!$G$5:$G$1000, "<>")=0, "", _xlfn.MAXIFS('Base Exámenes'!$G$5:$G$1000, 'Base Exámenes'!$C$5:$C$1000, A16)), "") -> 100 | K16: =IF(F16="Completado", IFERROR(IF(INDEX('Base Exámenes'!$H$5:$H$1000, MATCH(A16&"|"&J16, 'Base Exámenes'!$I$5:$I$1000, 0))="", "", INDEX('Base Exámenes'!$H$5:$H$1000, MATCH(A16&"|"&J16, 'Base Exámenes'!$I$5:$I$1000, 0))), ""), "") -> anonymous | L16: =IF($A16="","",COUNTIF('Base Exámenes'!$C$5:$C$1000, A16)) -> 1 | M16: =IF($A16="","",IF(COUNTIF('Base Exámenes'!$C$5:$C$1000, A16)>0, "", TRIM('Base Oficial'!H16)))
... A1000: =IF('Base Oficial'!A1000="","",TRIM('Base Oficial'!A1000)) | B1000: =IF($A1000="","",TRIM('Base Oficial'!B1000)) | C1000: =IF($A1000="","",TRIM('Base Oficial'!F1000)) | D1000: =IF($A1000="","",TRIM('Base Oficial'!G1000)) | E1000: =IF($A1000="","",TRIM('Base Oficial'!D1000)) | F1000: =IF($A1000="","",IF(COUNTIF('Base Exámenes'!$C$5:$C$1000, A1000)>0, "Completado", IF(M1000<>"", M1000, "Pendiente"))) | G1000: =IF(F1000="Completado", IFERROR(IF(INDEX('Base Exámenes'!$D$5:$D$1000, MATCH(A1000&"|"&J1000, 'Base Exámenes'!$I$5:$I$1000, 0))="", "", INDEX('Base Exámenes'!$D$5:$D$1000, MATCH(A1000&"|"&J1000, 'Base Exámenes'!$I$5:$I$1000, 0))), ""), "") | H1000: =IF(F1000="Completado", IFERROR(IF(INDEX('Base Exámenes'!$E$5:$E$1000, MATCH(A1000&"|"&J1000, 'Base Exámenes'!$I$5:$I$1000, 0))="", "", INDEX('Base Exámenes'!$E$5:$E$1000, MATCH(A1000&"|"&J1000, 'Base Exámenes'!$I$5:$I$1000, 0))), ""), "") | I1000: =IF(F1000="Completado", IFERROR(IF(INDEX('Base Exámenes'!$F$5:$F$1000, MATCH(A1000&"|"&J1000, 'Base Exámenes'!$I$5:$I$1000, 0))="", "", INDEX('Base Exámenes'!$F$5:$F$1000, MATCH(A1000&"|"&J1000, 'Base Exámenes'!$I$5:$I$1000, 0))), ""), "") | J1000: =IF(F1000="Completado", IF(COUNTIFS('Base Exámenes'!$C$5:$C$1000, A1000, 'Base Exámenes'!$G$5:$G$1000, "<>")=0, "", _xlfn.MAXIFS('Base Exámenes'!$G$5:$G$1000, 'Base Exámenes'!$C$5:$C$1000, A1000)), "") | K1000: =IF(F1000="Completado", IFERROR(IF(INDEX('Base Exámenes'!$H$5:$H$1000, MATCH(A1000&"|"&J1000, 'Base Exámenes'!$I$5:$I$1000, 0))="", "", INDEX('Base Exámenes'!$H$5:$H$1000, MATCH(A1000&"|"&J1000, 'Base Exámenes'!$I$5:$I$1000, 0))), ""), "") | L1000: =IF($A1000="","",COUNTIF('Base Exámenes'!$C$5:$C$1000, A1000)) | M1000: =IF($A1000="","",IF(COUNTIF('Base Exámenes'!$C$5:$C$1000, A1000)>0, "", TRIM('Base Oficial'!H1000)))

Sheet Consolidado por área
A1: CONSOLIDADO DE EVALUACIÓN POR ÁREA / DEPARTAMENTO
A2: Cálculos automáticos basados en la hoja 'Detalle individual'
A4: Área / Departamento | B4: Gerencia Asignada | C4: Personal Esperado | D4: Personas Completadas | E4: Pendientes | F4: % Cumplimiento | G4: Estado | H4: Promedio Nota | I4: Nota Máxima | J4: Nota Mínima | K4: Primer Inicio | L4: Última Finalización | M4: Menor Duración (min) | N4: Promedio Duración (min) | O4: Justificados (no cuentan)
A5: =IF(Cálculos!$AE5="","",INDEX('Detalle individual'!$C:$C,Cálculos!$AE5)) -> ADMINISTRACION DE BASE DE DATOS | B5: =IF($A5="","",INDEX('Detalle individual'!$D:$D,Cálculos!$AE5)) -> Gerencia de Sistemas | C5: =IF($A5="","",COUNTIFS('Detalle individual'!$C$5:$C$1000, A5, 'Detalle individual'!$F$5:$F$1000, "Completado")+COUNTIFS('Detalle individual'!$C$5:$C$1000, A5, 'Detalle individual'!$F$5:$F$1000, "Pendiente")) -> 1 | D5: =IF($A5="","",COUNTIFS('Detalle individual'!$C$5:$C$1000, A5, 'Detalle individual'!$F$5:$F$1000, "Completado")) -> 1 | E5: =IF($A5="","",C5-D5) -> 0 | F5: =IF($A5="","",IF(C5>0, D5/C5, 0)) -> 1 | G5: =IF($A5="","",IF(AND(C5>0, D5=C5), "Completo", "Pendiente")) -> Completo | H5: =IF($A5="","",IF(D5>0, IFERROR(AVERAGEIFS('Detalle individual'!$J$5:$J$1000, 'Detalle individual'!$C$5:$C$1000, A5), ""), "")) -> 95 | I5: =IF($A5="","",IF(D5>0, IFERROR(_xlfn.MAXIFS('Detalle individual'!$J$5:$J$1000, 'Detalle individual'!$C$5:$C$1000, A5), ""), "")) -> 95 | J5: =IF($A5="","",IF(D5>0, IFERROR(_xlfn.MINIFS('Detalle individual'!$J$5:$J$1000, 'Detalle individual'!$C$5:$C$1000, A5), ""), "")) -> 95 | K5: =IF($A5="","",IF(D5>0, IFERROR(_xlfn.MINIFS('Detalle individual'!$G$5:$G$1000, 'Detalle individual'!$C$5:$C$1000, A5), ""), "")) -> 46300.685 | L5: =IF($A5="","",IF(D5>0, IFERROR(_xlfn.MAXIFS('Detalle individual'!$H$5:$H$1000, 'Detalle individual'!$C$5:$C$1000, A5), ""), "")) -> 46300.696 | M5: =IF($A5="","",IF(D5>0, IFERROR(_xlfn.MINIFS('Detalle individual'!$I$5:$I$1000, 'Detalle individual'!$C$5:$C$1000, A5), ""), "")) -> 15.383333 | N5: =IF($A5="","",IF(D5>0, IFERROR(AVERAGEIFS('Detalle individual'!$I$5:$I$1000, 'Detalle individual'!$C$5:$C$1000, A5), ""), "")) -> 15.383333 | O5: =IF($A5="","",COUNTIF('Detalle individual'!$C$5:$C$1000, A5)-C5) -> 0
A6: =IF(Cálculos!$AE6="","",INDEX('Detalle individual'!$C:$C,Cálculos!$AE6)) -> ADMINISTRACIÓN DE CARTERAS | B6: =IF($A6="","",INDEX('Detalle individual'!$D:$D,Cálculos!$AE6)) -> Gerencia de Operaciones | C6: =IF($A6="","",COUNTIFS('Detalle individual'!$C$5:$C$1000, A6, 'Detalle individual'!$F$5:$F$1000, "Completado")+COUNTIFS('Detalle individual'!$C$5:$C$1000, A6, 'Detalle individual'!$F$5:$F$1000, "Pendiente")) -> 5 | D6: =IF($A6="","",COUNTIFS('Detalle individual'!$C$5:$C$1000, A6, 'Detalle individual'!$F$5:$F$1000, "Completado")) -> 5 | E6: =IF($A6="","",C6-D6) -> 0 | F6: =IF($A6="","",IF(C6>0, D6/C6, 0)) -> 1 | G6: =IF($A6="","",IF(AND(C6>0, D6=C6), "Completo", "Pendiente")) -> Completo | H6: =IF($A6="","",IF(D6>0, IFERROR(AVERAGEIFS('Detalle individual'!$J$5:$J$1000, 'Detalle individual'!$C$5:$C$1000, A6), ""), "")) -> 100 | I6: =IF($A6="","",IF(D6>0, IFERROR(_xlfn.MAXIFS('Detalle individual'!$J$5:$J$1000, 'Detalle individual'!$C$5:$C$1000, A6), ""), "")) -> 100 | J6: =IF($A6="","",IF(D6>0, IFERROR(_xlfn.MINIFS('Detalle individual'!$J$5:$J$1000, 'Detalle individual'!$C$5:$C$1000, A6), ""), "")) -> 100 | K6: =IF($A6="","",IF(D6>0, IFERROR(_xlfn.MINIFS('Detalle individual'!$G$5:$G$1000, 'Detalle individual'!$C$5:$C$1000, A6), ""), "")) -> 46304.494 | L6: =IF($A6="","",IF(D6>0, IFERROR(_xlfn.MAXIFS('Detalle individual'!$H$5:$H$1000, 'Detalle individual'!$C$5:$C$1000, A6), ""), "")) -> 46311.676 | M6: =IF($A6="","",IF(D6>0, IFERROR(_xlfn.MINIFS('Detalle individual'!$I$5:$I$1000, 'Detalle individual'!$C$5:$C$1000, A6), ""), "")) -> 3.65 | N6: =IF($A6="","",IF(D6>0, IFERROR(AVERAGEIFS('Detalle individual'!$I$5:$I$1000, 'Detalle individual'!$C$5:$C$1000, A6), ""), "")) -> 9.53 | O6: =IF($A6="","",COUNTIF('Detalle individual'!$C$5:$C$1000, A6)-C6) -> 0
A7: =IF(Cálculos!$AE7="","",INDEX('Detalle individual'!$C:$C,Cálculos!$AE7)) -> ADMINISTRACION DE RIESGOS | B7: =IF($A7="","",INDEX('Detalle individual'!$D:$D,Cálculos!$AE7)) -> Gerencia General | C7: =IF($A7="","",COUNTIFS('Detalle individual'!$C$5:$C$1000, A7, 'Detalle individual'!$F$5:$F$1000, "Completado")+COUNTIFS('Detalle individual'!$C$5:$C$1000, A7, 'Detalle individual'!$F$5:$F$1000, "Pendiente")) -> 4 | D7: =IF($A7="","",COUNTIFS('Detalle individual'!$C$5:$C$1000, A7, 'Detalle individual'!$F$5:$F$1000, "Completado")) -> 4 | E7: =IF($A7="","",C7-D7) -> 0 | F7: =IF($A7="","",IF(C7>0, D7/C7, 0)) -> 1 | G7: =IF($A7="","",IF(AND(C7>0, D7=C7), "Completo", "Pendiente")) -> Completo | H7: =IF($A7="","",IF(D7>0, IFERROR(AVERAGEIFS('Detalle individual'!$J$5:$J$1000, 'Detalle individual'!$C$5:$C$1000, A7), ""), "")) -> 100 | I7: =IF($A7="","",IF(D7>0, IFERROR(_xlfn.MAXIFS('Detalle individual'!$J$5:$J$1000, 'Detalle individual'!$C$5:$C$1000, A7), ""), "")) -> 100 | J7: =IF($A7="","",IF(D7>0, IFERROR(_xlfn.MINIFS('Detalle individual'!$J$5:$J$1000, 'Detalle individual'!$C$5:$C$1000, A7), ""), "")) -> 100 | K7: =IF($A7="","",IF(D7>0, IFERROR(_xlfn.MINIFS('Detalle individual'!$G$5:$G$1000, 'Detalle individual'!$C$5:$C$1000, A7), ""), "")) -> 46296.437 | L7: =IF($A7="","",IF(D7>0, IFERROR(_xlfn.MAXIFS('Detalle individual'!$H$5:$H$1000, 'Detalle individual'!$C$5:$C$1000, A7), ""), "")) -> 46305.399 | M7: =IF($A7="","",IF(D7>0, IFERROR(_xlfn.MINIFS('Detalle individual'!$I$5:$I$1000, 'Detalle individual'!$C$5:$C$1000, A7), ""), "")) -> 3.05 | N7: =IF($A7="","",IF(D7>0, IFERROR(AVERAGEIFS('Detalle individual'!$I$5:$I$1000, 'Detalle individual'!$C$5:$C$1000, A7), ""), "")) -> 6.2458333 | O7: =IF($A7="","",COUNTIF('Detalle individual'!$C$5:$C$1000, A7)-C7) -> 0
A8: =IF(Cálculos!$AE8="","",INDEX('Detalle individual'!$C:$C,Cálculos!$AE8)) -> AGENCIA CENTRAL | B8: =IF($A8="","",INDEX('Detalle individual'!$D:$D,Cálculos!$AE8)) -> Gerencia de Negocios | C8: =IF($A8="","",COUNTIFS('Detalle individual'!$C$5:$C$1000, A8, 'Detalle individual'!$F$5:$F$1000, "Completado")+COUNTIFS('Detalle individual'!$C$5:$C$1000, A8, 'Detalle individual'!$F$5:$F$1000, "Pendiente")) -> 16 | D8: =IF($A8="","",COUNTIFS('Detalle individual'!$C$5:$C$1000, A8, 'Detalle individual'!$F$5:$F$1000, "Completado")) -> 16 | E8: =IF($A8="","",C8-D8) -> 0 | F8: =IF($A8="","",IF(C8>0, D8/C8, 0)) -> 1 | G8: =IF($A8="","",IF(AND(C8>0, D8=C8), "Completo", "Pendiente")) -> Completo | H8: =IF($A8="","",IF(D8>0, IFERROR(AVERAGEIFS('Detalle individual'!$J$5:$J$1000, 'Detalle individual'!$C$5:$C$1000, A8), ""), "")) -> 96.25 | I8: =IF($A8="","",IF(D8>0, IFERROR(_xlfn.MAXIFS('Detalle individual'!$J$5:$J$1000, 'Detalle individual'!$C$5:$C$1000, A8), ""), "")) -> 100 | J8: =IF($A8="","",IF(D8>0, IFERROR(_xlfn.MINIFS('Detalle individual'!$J$5:$J$1000, 'Detalle individual'!$C$5:$C$1000, A8), ""), "")) -> 75 | K8: =IF($A8="","",IF(D8>0, IFERROR(_xlfn.MINIFS('Detalle individual'!$G$5:$G$1000, 'Detalle individual'!$C$5:$C$1000, A8), ""), "")) -> 46302.47 | L8: =IF($A8="","",IF(D8>0, IFERROR(_xlfn.MAXIFS('Detalle individual'!$H$5:$H$1000, 'Detalle individual'!$C$5:$C$1000, A8), ""), "")) -> 46311.72 | M8: =IF($A8="","",IF(D8>0, IFERROR(_xlfn.MINIFS('Detalle individual'!$I$5:$I$1000, 'Detalle individual'!$C$5:$C$1000, A8), ""), "")) -> 1.75 | N8: =IF($A8="","",IF(D8>0, IFERROR(AVERAGEIFS('Detalle individual'!$I$5:$I$1000, 'Detalle individual'!$C$5:$C$1000, A8), ""), "")) -> 16.236458 | O8: =IF($A8="","",COUNTIF('Detalle individual'!$C$5:$C$1000, A8)-C8) -> 2
A9: =IF(Cálculos!$AE9="","",INDEX('Detalle individual'!$C:$C,Cálculos!$AE9)) -> AGENCIA COLEGIO MEDICO | B9: =IF($A9="","",INDEX('Detalle individual'!$D:$D,Cálculos!$AE9)) -> Gerencia de Negocios | C9: =IF($A9="","",COUNTIFS('Detalle individual'!$C$5:$C$1000, A9, 'Detalle individual'!$F$5:$F$1000, "Completado")+COUNTIFS('Detalle individual'!$C$5:$C$1000, A9, 'Detalle individual'!$F$5:$F$1000, "Pendiente")) -> 11 | D9: =IF($A9="","",COUNTIFS('Detalle individual'!$C$5:$C$1000, A9, 'Detalle individual'!$F$5:$F$1000, "Completado")) -> 11 | E9: =IF($A9="","",C9-D9) -> 0 | F9: =IF($A9="","",IF(C9>0, D9/C9, 0)) -> 1 | G9: =IF($A9="","",IF(AND(C9>0, D9=C9), "Completo", "Pendiente")) -> Completo | H9: =IF($A9="","",IF(D9>0, IFERROR(AVERAGEIFS('Detalle individual'!$J$5:$J$1000, 'Detalle individual'!$C$5:$C$1000, A9), ""), "")) -> 97.272727 | I9: =IF($A9="","",IF(D9>0, IFERROR(_xlfn.MAXIFS('Detalle individual'!$J$5:$J$1000, 'Detalle individual'!$C$5:$C$1000, A9), ""), "")) -> 100 | J9: =IF($A9="","",IF(D9>0, IFERROR(_xlfn.MINIFS('Detalle individual'!$J$5:$J$1000, 'Detalle individual'!$C$5:$C$1000, A9), ""), "")) -> 90 | K9: =IF($A9="","",IF(D9>0, IFERROR(_xlfn.MINIFS('Detalle individual'!$G$5:$G$1000, 'Detalle individual'!$C$5:$C$1000, A9), ""), "")) -> 46296.471 | L9: =IF($A9="","",IF(D9>0, IFERROR(_xlfn.MAXIFS('Detalle individual'!$H$5:$H$1000, 'Detalle individual'!$C$5:$C$1000, A9), ""), "")) -> 46310.516 | M9: =IF($A9="","",IF(D9>0, IFERROR(_xlfn.MINIFS('Detalle individual'!$I$5:$I$1000, 'Detalle individual'!$C$5:$C$1000, A9), ""), "")) -> 3.1 | N9: =IF($A9="","",IF(D9>0, IFERROR(AVERAGEIFS('Detalle individual'!$I$5:$I$1000, 'Detalle individual'!$C$5:$C$1000, A9), ""), "")) -> 9.569697 | O9: =IF($A9="","",COUNTIF('Detalle individual'!$C$5:$C$1000, A9)-C9) -> 1
A10: =IF(Cálculos!$AE10="","",INDEX('Detalle individual'!$C:$C,Cálculos!$AE10)) -> AGENCIA COLONIA MEDICA | B10: =IF($A10="","",INDEX('Detalle individual'!$D:$D,Cálculos!$AE10)) -> Gerencia de Negocios | C10: =IF($A10="","",COUNTIFS('Detalle individual'!$C$5:$C$1000, A10, 'Detalle individual'!$F$5:$F$1000, "Completado")+COUNTIFS('Detalle individual'!$C$5:$C$1000, A10, 'Detalle individual'!$F$5:$F$1000, "Pendiente")) -> 16 | D10: =IF($A10="","",COUNTIFS('Detalle individual'!$C$5:$C$1000, A10, 'Detalle individual'!$F$5:$F$1000, "Completado")) -> 16 | E10: =IF($A10="","",C10-D10) -> 0 | F10: =IF($A10="","",IF(C10>0, D10/C10, 0)) -> 1 | G10: =IF($A10="","",IF(AND(C10>0, D10=C10), "Completo", "Pendiente")) -> Completo | H10: =IF($A10="","",IF(D10>0, IFERROR(AVERAGEIFS('Detalle individual'!$J$5:$J$1000, 'Detalle individual'!$C$5:$C$1000, A10), ""), "")) -> 97.8125 | I10: =IF($A10="","",IF(D10>0, IFERROR(_xlfn.MAXIFS('Detalle individual'!$J$5:$J$1000, 'Detalle individual'!$C$5:$C$1000, A10), ""), "")) -> 100 | J10: =IF($A10="","",IF(D10>0, IFERROR(_xlfn.MINIFS('Detalle individual'!$J$5:$J$1000, 'Detalle individual'!$C$5:$C$1000, A10), ""), "")) -> 90 | K10: =IF($A10="","",IF(D10>0, IFERROR(_xlfn.MINIFS('Detalle individual'!$G$5:$G$1000, 'Detalle individual'!$C$5:$C$1000, A10), ""), "")) -> 46297.712 | L10: =IF($A10="","",IF(D10>0, IFERROR(_xlfn.MAXIFS('Detalle individual'!$H$5:$H$1000, 'Detalle individual'!$C$5:$C$1000, A10), ""), "")) -> 46311.71 | M10: =IF($A10="","",IF(D10>0, IFERROR(_xlfn.MINIFS('Detalle individual'!$I$5:$I$1000, 'Detalle individual'!$C$5:$C$1000, A10), ""), "")) -> 1.6 | N10: =IF($A10="","",IF(D10>0, IFERROR(AVERAGEIFS('Detalle individual'!$I$5:$I$1000, 'Detalle individual'!$C$5:$C$1000, A10), ""), "")) -> 17.919792 | O10: =IF($A10="","",COUNTIF('Detalle individual'!$C$5:$C$1000, A10)-C10) -> 0
A11: =IF(Cálculos!$AE11="","",INDEX('Detalle individual'!$C:$C,Cálculos!$AE11)) -> AGENCIA MERLIOT | B11: =IF($A11="","",INDEX('Detalle individual'!$D:$D,Cálculos!$AE11)) -> Gerencia de Negocios | C11: =IF($A11="","",COUNTIFS('Detalle individual'!$C$5:$C$1000, A11, 'Detalle individual'!$F$5:$F$1000, "Completado")+COUNTIFS('Detalle individual'!$C$5:$C$1000, A11, 'Detalle individual'!$F$5:$F$1000, "Pendiente")) -> 13 | D11: =IF($A11="","",COUNTIFS('Detalle individual'!$C$5:$C$1000, A11, 'Detalle individual'!$F$5:$F$1000, "Completado")) -> 13 | E11: =IF($A11="","",C11-D11) -> 0 | F11: =IF($A11="","",IF(C11>0, D11/C11, 0)) -> 1 | G11: =IF($A11="","",IF(AND(C11>0, D11=C11), "Completo", "Pendiente")) -> Completo | H11: =IF($A11="","",IF(D11>0, IFERROR(AVERAGEIFS('Detalle individual'!$J$5:$J$1000, 'Detalle individual'!$C$5:$C$1000, A11), ""), "")) -> 95.769231 | I11: =IF($A11="","",IF(D11>0, IFERROR(_xlfn.MAXIFS('Detalle individual'!$J$5:$J$1000, 'Detalle individual'!$C$5:$C$1000, A11), ""), "")) -> 100 | J11: =IF($A11="","",IF(D11>0, IFERROR(_xlfn.MINIFS('Detalle individual'!$J$5:$J$1000, 'Detalle individual'!$C$5:$C$1000, A11), ""), "")) -> 70 | K11: =IF($A11="","",IF(D11>0, IFERROR(_xlfn.MINIFS('Detalle individual'!$G$5:$G$1000, 'Detalle individual'!$C$5:$C$1000, A11), ""), "")) -> 46296.547 | L11: =IF($A11="","",IF(D11>0, IFERROR(_xlfn.MAXIFS('Detalle individual'!$H$5:$H$1000, 'Detalle individual'!$C$5:$C$1000, A11), ""), "")) -> 46310.525 | M11: =IF($A11="","",IF(D11>0, IFERROR(_xlfn.MINIFS('Detalle individual'!$I$5:$I$1000, 'Detalle individual'!$C$5:$C$1000, A11), ""), "")) -> 1.7833333 | N11: =IF($A11="","",IF(D11>0, IFERROR(AVERAGEIFS('Detalle individual'!$I$5:$I$1000, 'Detalle individual'!$C$5:$C$1000, A11), ""), "")) -> 8.7564103 | O11: =IF($A11="","",COUNTIF('Detalle individual'!$C$5:$C$1000, A11)-C11) -> 0
A12: =IF(Cálculos!$AE12="","",INDEX('Detalle individual'!$C:$C,Cálculos!$AE12)) -> AGENCIA PLAZA MUNDO | B12: =IF($A12="","",INDEX('Detalle individual'!$D:$D,Cálculos!$AE12)) -> Gerencia de Negocios | C12: =IF($A12="","",COUNTIFS('Detalle individual'!$C$5:$C$1000, A12, 'Detalle individual'!$F$5:$F$1000, "Completado")+COUNTIFS('Detalle individual'!$C$5:$C$1000, A12, 'Detalle individual'!$F$5:$F$1000, "Pendiente")) -> 8 | D12: =IF($A12="","",COUNTIFS('Detalle individual'!$C$5:$C$1000, A12, 'Detalle individual'!$F$5:$F$1000, "Completado")) -> 8 | E12: =IF($A12="","",C12-D12) -> 0 | F12: =IF($A12="","",IF(C12>0, D12/C12, 0)) -> 1 | G12: =IF($A12="","",IF(AND(C12>0, D12=C12), "Completo", "Pendiente")) -> Completo | H12: =IF($A12="","",IF(D12>0, IFERROR(AVERAGEIFS('Detalle individual'!$J$5:$J$1000, 'Detalle individual'!$C$5:$C$1000, A12), ""), "")) -> 98.75 | I12: =IF($A12="","",IF(D12>0, IFERROR(_xlfn.MAXIFS('Detalle individual'!$J$5:$J$1000, 'Detalle individual'!$C$5:$C$1000, A12), ""), "")) -> 100 | J12: =IF($A12="","",IF(D12>0, IFERROR(_xlfn.MINIFS('Detalle individual'!$J$5:$J$1000, 'Detalle individual'!$C$5:$C$1000, A12), ""), "")) -> 90 | K12: =IF($A12="","",IF(D12>0, IFERROR(_xlfn.MINIFS('Detalle individual'!$G$5:$G$1000, 'Detalle individual'!$C$5:$C$1000, A12), ""), "")) -> 46307.4 | L12: =IF($A12="","",IF(D12>0, IFERROR(_xlfn.MAXIFS('Detalle individual'!$H$5:$H$1000, 'Detalle individual'!$C$5:$C$1000, A12), ""), "")) -> 46310.646 | M12: =IF($A12="","",IF(D12>0, IFERROR(_xlfn.MINIFS('Detalle individual'!$I$5:$I$1000, 'Detalle individual'!$C$5:$C$1000, A12), ""), "")) -> 2.8166667 | N12: =IF($A12="","",IF(D12>0, IFERROR(AVERAGEIFS('Detalle individual'!$I$5:$I$1000, 'Detalle individual'!$C$5:$C$1000, A12), ""), "")) -> 6.2770833 | O12: =IF($A12="","",COUNTIF('Detalle individual'!$C$5:$C$1000, A12)-C12) -> 0
A13: =IF(Cálculos!$AE13="","",INDEX('Detalle individual'!$C:$C,Cálculos!$AE13)) -> AGENCIA SAN MIGUEL | B13: =IF($A13="","",INDEX('Detalle individual'!$D:$D,Cálculos!$AE13)) -> Gerencia de Negocios | C13: =IF($A13="","",COUNTIFS('Detalle individual'!$C$5:$C$1000, A13, 'Detalle individual'!$F$5:$F$1000, "Completado")+COUNTIFS('Detalle individual'!$C$5:$C$1000, A13, 'Detalle individual'!$F$5:$F$1000, "Pendiente")) -> 7 | D13: =IF($A13="","",COUNTIFS('Detalle individual'!$C$5:$C$1000, A13, 'Detalle individual'!$F$5:$F$1000, "Completado")) -> 7 | E13: =IF($A13="","",C13-D13) -> 0 | F13: =IF($A13="","",IF(C13>0, D13/C13, 0)) -> 1 | G13: =IF($A13="","",IF(AND(C13>0, D13=C13), "Completo", "Pendiente")) -> Completo | H13: =IF($A13="","",IF(D13>0, IFERROR(AVERAGEIFS('Detalle individual'!$J$5:$J$1000, 'Detalle individual'!$C$5:$C$1000, A13), ""), "")) -> 98.571429 | I13: =IF($A13="","",IF(D13>0, IFERROR(_xlfn.MAXIFS('Detalle individual'!$J$5:$J$1000, 'Detalle individual'!$C$5:$C$1000, A13), ""), "")) -> 100 | J13: =IF($A13="","",IF(D13>0, IFERROR(_xlfn.MINIFS('Detalle individual'!$J$5:$J$1000, 'Detalle individual'!$C$5:$C$1000, A13), ""), "")) -> 90 | K13: =IF($A13="","",IF(D13>0, IFERROR(_xlfn.MINIFS('Detalle individual'!$G$5:$G$1000, 'Detalle individual'!$C$5:$C$1000, A13), ""), "")) -> 46296.435 | L13: =IF($A13="","",IF(D13>0, IFERROR(_xlfn.MAXIFS('Detalle individual'!$H$5:$H$1000, 'Detalle individual'!$C$5:$C$1000, A13), ""), "")) -> 46296.492 | M13: =IF($A13="","",IF(D13>0, IFERROR(_xlfn.MINIFS('Detalle individual'!$I$5:$I$1000, 'Detalle individual'!$C$5:$C$1000, A13), ""), "")) -> 2.95 | N13: =IF($A13="","",IF(D13>0, IFERROR(AVERAGEIFS('Detalle individual'!$I$5:$I$1000, 'Detalle individual'!$C$5:$C$1000, A13), ""), "")) -> 5.1666667 | O13: =IF($A13="","",COUNTIF('Detalle individual'!$C$5:$C$1000, A13)-C13) -> 1
A14: =IF(Cálculos!$AE14="","",INDEX('Detalle individual'!$C:$C,Cálculos!$AE14)) -> AGENCIA SANTA ANA | B14: =IF($A14="","",INDEX('Detalle individual'!$D:$D,Cálculos!$AE14)) -> Gerencia de Negocios | C14: =IF($A14="","",COUNTIFS('Detalle individual'!$C$5:$C$1000, A14, 'Detalle individual'!$F$5:$F$1000, "Completado")+COUNTIFS('Detalle individual'!$C$5:$C$1000, A14, 'Detalle individual'!$F$5:$F$1000, "Pendiente")) -> 8 | D14: =IF($A14="","",COUNTIFS('Detalle individual'!$C$5:$C$1000, A14, 'Detalle individual'!$F$5:$F$1000, "Completado")) -> 8 | E14: =IF($A14="","",C14-D14) -> 0 | F14: =IF($A14="","",IF(C14>0, D14/C14, 0)) -> 1 | G14: =IF($A14="","",IF(AND(C14>0, D14=C14), "Completo", "Pendiente")) -> Completo | H14: =IF($A14="","",IF(D14>0, IFERROR(AVERAGEIFS('Detalle individual'!$J$5:$J$1000, 'Detalle individual'!$C$5:$C$1000, A14), ""), "")) -> 97.5 | I14: =IF($A14="","",IF(D14>0, IFERROR(_xlfn.MAXIFS('Detalle individual'!$J$5:$J$1000, 'Detalle individual'!$C$5:$C$1000, A14), ""), "")) -> 100 | J14: =IF($A14="","",IF(D14>0, IFERROR(_xlfn.MINIFS('Detalle individual'!$J$5:$J$1000, 'Detalle individual'!$C$5:$C$1000, A14), ""), "")) -> 90 | K14: =IF($A14="","",IF(D14>0, IFERROR(_xlfn.MINIFS('Detalle individual'!$G$5:$G$1000, 'Detalle individual'!$C$5:$C$1000, A14), ""), "")) -> 46309.337 | L14: =IF($A14="","",IF(D14>0, IFERROR(_xlfn.MAXIFS('Detalle individual'!$H$5:$H$1000, 'Detalle individual'!$C$5:$C$1000, A14), ""), "")) -> 46311.494 | M14: =IF($A14="","",IF(D14>0, IFERROR(_xlfn.MINIFS('Detalle individual'!$I$5:$I$1000, 'Detalle individual'!$C$5:$C$1000, A14), ""), "")) -> 2.2833333 | N14: =IF($A14="","",IF(D14>0, IFERROR(AVERAGEIFS('Detalle individual'!$I$5:$I$1000, 'Detalle individual'!$C$5:$C$1000, A14), ""), "")) -> 7.99375 | O14: =IF($A14="","",COUNTIF('Detalle individual'!$C$5:$C$1000, A14)-C14) -> 0
