Workbook

Sheet Resumen Riesgos
A1: ¿QUÉ ME AUDITAN REPETIDO? – RESUMEN DE RECURRENCIA POR REQUERIMIENTO
A2: Año a analizar: | C2: Todos | D2: ← elija "Todos" o un año. Columna "¿Se repite?" = "Sí" cuando el mismo tema lo piden 2 o más orígenes (p. ej., SSF y Auditoría Interna).
A4: N° | B4: Requerimiento | C4: Norma | D4: Interna | E4: Externa | F4: SSF | G4: Comité Sup. | H4: Consejo Adm. | I4: Otros | J4: Total Veces | K4: Auditorías / visitas distintas | L4: N° de orígenes | M4: ¿Se repite? | N4: Ranking | O4: Ene | P4: Feb | Q4: Mar | R4: Abr | S4: May | T4: Jun | U4: Jul | V4: Ago | W4: Sep | X4: Oct | Y4: Nov | Z4: Dic
A5: 1 | B5: =Catálogos!C2 -> Actas Comité de Riesgos | C5: =Catálogos!D2 -> NRP-20 | D5: =SUMPRODUCT((Consolidado!$E$5:$E$1000=$B5)*(Consolidado!$C$5:$C$1000="Auditoría Interna")*((($C$2="Todos")+(Consolidado!$I$5:$I$1000&""=$C$2&""))>0)) -> 4 | E5: =SUMPRODUCT((Consolidado!$E$5:$E$1000=$B5)*(Consolidado!$C$5:$C$1000="Auditoría Externa")*((($C$2="Todos")+(Consolidado!$I$5:$I$1000&""=$C$2&""))>0)) -> 1 | F5: =SUMPRODUCT((Consolidado!$E$5:$E$1000=$B5)*(Consolidado!$C$5:$C$1000="SSF")*((($C$2="Todos")+(Consolidado!$I$5:$I$1000&""=$C$2&""))>0)) -> 0 | G5: =SUMPRODUCT((Consolidado!$E$5:$E$1000=$B5)*(Consolidado!$C$5:$C$1000="Comité de Supervisión")*((($C$2="Todos")+(Consolidado!$I$5:$I$1000&""=$C$2&""))>0)) -> 0 | H5: =SUMPRODUCT((Consolidado!$E$5:$E$1000=$B5)*(Consolidado!$C$5:$C$1000="Consejo de Administración")*((($C$2="Todos")+(Consolidado!$I$5:$I$1000&""=$C$2&""))>0)) -> 0 | I5: =SUMPRODUCT((Consolidado!$E$5:$E$1000=$B5)*(Consolidado!$C$5:$C$1000="Otros")*((($C$2="Todos")+(Consolidado!$I$5:$I$1000&""=$C$2&""))>0)) -> 0 | J5: =SUM(D5:I5) -> 5 | K5: =SUMPRODUCT((Consolidado!$E$5:$E$1000=$B5)*(Consolidado!$AE$5:$AE$1000)*((($C$2="Todos")+(Consolidado!$I$5:$I$1000&""=$C$2&""))>0)) -> 4 | L5: =COUNTIF(D5:I5,">0") -> 2 | M5: =IF(L5>=2,"Sí","No") -> Sí | N5: =IF(J5=0,"",RANK(J5,$J$5:$J$33)) -> 5 | O5: =SUMPRODUCT((Consolidado!$E$5:$E$1000=$B5)*(MONTH(Consolidado!$B$5:$B$1000+0*(Consolidado!$B$5:$B$1000=""))=1)*(Consolidado!$B$5:$B$1000<>"")*((($C$2="Todos")+(Consolidado!$I$5:$I$1000&""=$C$2&""))>0)) -> 0 | P5: =SUMPRODUCT((Consolidado!$E$5:$E$1000=$B5)*(MONTH(Consolidado!$B$5:$B$1000+0*(Consolidado!$B$5:$B$1000=""))=2)*(Consolidado!$B$5:$B$1000<>"")*((($C$2="Todos")+(Consolidado!$I$5:$I$1000&""=$C$2&""))>0)) -> 0 | Q5: =SUMPRODUCT((Consolidado!$E$5:$E$1000=$B5)*(MONTH(Consolidado!$B$5:$B$1000+0*(Consolidado!$B$5:$B$1000=""))=3)*(Consolidado!$B$5:$B$1000<>"")*((($C$2="Todos")+(Consolidado!$I$5:$I$1000&""=$C$2&""))>0)) -> 0 | R5: =SUMPRODUCT((Consolidado!$E$5:$E$1000=$B5)*(MONTH(Consolidado!$B$5:$B$1000+0*(Consolidado!$B$5:$B$1000=""))=4)*(Consolidado!$B$5:$B$1000<>"")*((($C$2="Todos")+(Consolidado!$I$5:$I$1000&""=$C$2&""))>0)) -> 0 | S5: =SUMPRODUCT((Consolidado!$E$5:$E$1000=$B5)*(MONTH(Consolidado!$B$5:$B$1000+0*(Consolidado!$B$5:$B$1000=""))=5)*(Consolidado!$B$5:$B$1000<>"")*((($C$2="Todos")+(Consolidado!$I$5:$I$1000&""=$C$2&""))>0)) -> 1 | T5: =SUMPRODUCT((Consolidado!$E$5:$E$1000=$B5)*(MONTH(Consolidado!$B$5:$B$1000+0*(Consolidado!$B$5:$B$1000=""))=6)*(Consolidado!$B$5:$B$1000<>"")*((($C$2="Todos")+(Consolidado!$I$5:$I$1000&""=$C$2&""))>0)) -> 0 | U5: =SUMPRODUCT((Consolidado!$E$5:$E$1000=$B5)*(MONTH(Consolidado!$B$5:$B$1000+0*(Consolidado!$B$5:$B$1000=""))=7)*(Consolidado!$B$5:$B$1000<>"")*((($C$2="Todos")+(Consolidado!$I$5:$I$1000&""=$C$2&""))>0)) -> 0 | V5: =SUMPRODUCT((Consolidado!$E$5:$E$1000=$B5)*(MONTH(Consolidado!$B$5:$B$1000+0*(Consolidado!$B$5:$B$1000=""))=8)*(Consolidado!$B$5:$B$1000<>"")*((($C$2="Todos")+(Consolidado!$I$5:$I$1000&""=$C$2&""))>0)) -> 2 | W5: =SUMPRODUCT((Consolidado!$E$5:$E$1000=$B5)*(MONTH(Consolidado!$B$5:$B$1000+0*(Consolidado!$B$5:$B$1000=""))=9)*(Consolidado!$B$5:$B$1000<>"")*((($C$2="Todos")+(Consolidado!$I$5:$I$1000&""=$C$2&""))>0)) -> 0 | X5: =SUMPRODUCT((Consolidado!$E$5:$E$1000=$B5)*(MONTH(Consolidado!$B$5:$B$1000+0*(Consolidado!$B$5:$B$1000=""))=10)*(Consolidado!$B$5:$B$1000<>"")*((($C$2="Todos")+(Consolidado!$I$5:$I$1000&""=$C$2&""))>0)) -> 2 | Y5: =SUMPRODUCT((Consolidado!$E$5:$E$1000=$B5)*(MONTH(Consolidado!$B$5:$B$1000+0*(Consolidado!$B$5:$B$1000=""))=11)*(Consolidado!$B$5:$B$1000<>"")*((($C$2="Todos")+(Consolidado!$I$5:$I$1000&""=$C$2&""))>0)) -> 0 | Z5: =SUMPRODUCT((Consolidado!$E$5:$E$1000=$B5)*(MONTH(Consolidado!$B$5:$B$1000+0*(Consolidado!$B$5:$B$1000=""))=12)*(Consolidado!$B$5:$B$1000<>"")*((($C$2="Todos")+(Consolidado!$I$5:$I$1000&""=$C$2&""))>0)) -> 0
A6: 2 | B6: =Catálogos!C3 -> Informe GIR / informes al Comité y Consejo | C6: =Catálogos!D3 -> NRP-20 | D6: =SUMPRODUCT((Consolidado!$E$5:$E$1000=$B6)*(Consolidado!$C$5:$C$1000="Auditoría Interna")*((($C$2="Todos")+(Consolidado!$I$5:$I$1000&""=$C$2&""))>0)) -> 5 | E6: =SUMPRODUCT((Consolidado!$E$5:$E$1000=$B6)*(Consolidado!$C$5:$C$1000="Auditoría Externa")*((($C$2="Todos")+(Consolidado!$I$5:$I$1000&""=$C$2&""))>0)) -> 0 | F6: =SUMPRODUCT((Consolidado!$E$5:$E$1000=$B6)*(Consolidado!$C$5:$C$1000="SSF")*((($C$2="Todos")+(Consolidado!$I$5:$I$1000&""=$C$2&""))>0)) -> 0 | G6: =SUMPRODUCT((Consolidado!$E$5:$E$1000=$B6)*(Consolidado!$C$5:$C$1000="Comité de Supervisión")*((($C$2="Todos")+(Consolidado!$I$5:$I$1000&""=$C$2&""))>0)) -> 0 | H6: =SUMPRODUCT((Consolidado!$E$5:$E$1000=$B6)*(Consolidado!$C$5:$C$1000="Consejo de Administración")*((($C$2="Todos")+(Consolidado!$I$5:$I$1000&""=$C$2&""))>0)) -> 0 | I6: =SUMPRODUCT((Consolidado!$E$5:$E$1000=$B6)*(Consolidado!$C$5:$C$1000="Otros")*((($C$2="Todos")+(Consolidado!$I$5:$I$1000&""=$C$2&""))>0)) -> 0 | J6: =SUM(D6:I6) -> 5 | K6: =SUMPRODUCT((Consolidado!$E$5:$E$1000=$B6)*(Consolidado!$AE$5:$AE$1000)*((($C$2="Todos")+(Consolidado!$I$5:$I$1000&""=$C$2&""))>0)) -> 2 | L6: =COUNTIF(D6:I6,">0") -> 1 | M6: =IF(L6>=2,"Sí","No") -> No | N6: =IF(J6=0,"",RANK(J6,$J$5:$J$33)) -> 5 | O6: =SUMPRODUCT((Consolidado!$E$5:$E$1000=$B6)*(MONTH(Consolidado!$B$5:$B$1000+0*(Consolidado!$B$5:$B$1000=""))=1)*(Consolidado!$B$5:$B$1000<>"")*((($C$2="Todos")+(Consolidado!$I$5:$I$1000&""=$C$2&""))>0)) -> 0 | P6: =SUMPRODUCT((Consolidado!$E$5:$E$1000=$B6)*(MONTH(Consolidado!$B$5:$B$1000+0*(Consolidado!$B$5:$B$1000=""))=2)*(Consolidado!$B$5:$B$1000<>"")*((($C$2="Todos")+(Consolidado!$I$5:$I$1000&""=$C$2&""))>0)) -> 0 | Q6: =SUMPRODUCT((Consolidado!$E$5:$E$1000=$B6)*(MONTH(Consolidado!$B$5:$B$1000+0*(Consolidado!$B$5:$B$1000=""))=3)*(Consolidado!$B$5:$B$1000<>"")*((($C$2="Todos")+(Consolidado!$I$5:$I$1000&""=$C$2&""))>0)) -> 0 | R6: =SUMPRODUCT((Consolidado!$E$5:$E$1000=$B6)*(MONTH(Consolidado!$B$5:$B$1000+0*(Consolidado!$B$5:$B$1000=""))=4)*(Consolidado!$B$5:$B$1000<>"")*((($C$2="Todos")+(Consolidado!$I$5:$I$1000&""=$C$2&""))>0)) -> 0 | S6: =SUMPRODUCT((Consolidado!$E$5:$E$1000=$B6)*(MONTH(Consolidado!$B$5:$B$1000+0*(Consolidado!$B$5:$B$1000=""))=5)*(Consolidado!$B$5:$B$1000<>"")*((($C$2="Todos")+(Consolidado!$I$5:$I$1000&""=$C$2&""))>0)) -> 1 | T6: =SUMPRODUCT((Consolidado!$E$5:$E$1000=$B6)*(MONTH(Consolidado!$B$5:$B$1000+0*(Consolidado!$B$5:$B$1000=""))=6)*(Consolidado!$B$5:$B$1000<>"")*((($C$2="Todos")+(Consolidado!$I$5:$I$1000&""=$C$2&""))>0)) -> 0 | U6: =SUMPRODUCT((Consolidado!$E$5:$E$1000=$B6)*(MONTH(Consolidado!$B$5:$B$1000+0*(Consolidado!$B$5:$B$1000=""))=7)*(Consolidado!$B$5:$B$1000<>"")*((($C$2="Todos")+(Consolidado!$I$5:$I$1000&""=$C$2&""))>0)) -> 0 | V6: =SUMPRODUCT((Consolidado!$E$5:$E$1000=$B6)*(MONTH(Consolidado!$B$5:$B$1000+0*(Consolidado!$B$5:$B$1000=""))=8)*(Consolidado!$B$5:$B$1000<>"")*((($C$2="Todos")+(Consolidado!$I$5:$I$1000&""=$C$2&""))>0)) -> 4 | W6: =SUMPRODUCT((Consolidado!$E$5:$E$1000=$B6)*(MONTH(Consolidado!$B$5:$B$1000+0*(Consolidado!$B$5:$B$1000=""))=9)*(Consolidado!$B$5:$B$1000<>"")*((($C$2="Todos")+(Consolidado!$I$5:$I$1000&""=$C$2&""))>0)) -> 0 | X6: =SUMPRODUCT((Consolidado!$E$5:$E$1000=$B6)*(MONTH(Consolidado!$B$5:$B$1000+0*(Consolidado!$B$5:$B$1000=""))=10)*(Consolidado!$B$5:$B$1000<>"")*((($C$2="Todos")+(Consolidado!$I$5:$I$1000&""=$C$2&""))>0)) -> 0 | Y6: =SUMPRODUCT((Consolidado!$E$5:$E$1000=$B6)*(MONTH(Consolidado!$B$5:$B$1000+0*(Consolidado!$B$5:$B$1000=""))=11)*(Consolidado!$B$5:$B$1000<>"")*((($C$2="Todos")+(Consolidado!$I$5:$I$1000&""=$C$2&""))>0)) -> 0 | Z6: =SUMPRODUCT((Consolidado!$E$5:$E$1000=$B6)*(MONTH(Consolidado!$B$5:$B$1000+0*(Consolidado!$B$5:$B$1000=""))=12)*(Consolidado!$B$5:$B$1000<>"")*((($C$2="Todos")+(Consolidado!$I$5:$I$1000&""=$C$2&""))>0)) -> 0
A7: 3 | B7: =Catálogos!C4 -> Plan de trabajo y capacitaciones de riesgos | C7: =Catálogos!D4 -> NRP-20 | D7: =SUMPRODUCT((Consolidado!$E$5:$E$1000=$B7)*(Consolidado!$C$5:$C$1000="Auditoría Interna")*((($C$2="Todos")+(Consolidado!$I$5:$I$1000&""=$C$2&""))>0)) -> 7 | E7: =SUMPRODUCT((Consolidado!$E$5:$E$1000=$B7)*(Consolidado!$C$5:$C$1000="Auditoría Externa")*((($C$2="Todos")+(Consolidado!$I$5:$I$1000&""=$C$2&""))>0)) -> 0 | F7: =SUMPRODUCT((Consolidado!$E$5:$E$1000=$B7)*(Consolidado!$C$5:$C$1000="SSF")*((($C$2="Todos")+(Consolidado!$I$5:$I$1000&""=$C$2&""))>0)) -> 0 | G7: =SUMPRODUCT((Consolidado!$E$5:$E$1000=$B7)*(Consolidado!$C$5:$C$1000="Comité de Supervisión")*((($C$2="Todos")+(Consolidado!$I$5:$I$1000&""=$C$2&""))>0)) -> 0 | H7: =SUMPRODUCT((Consolidado!$E$5:$E$1000=$B7)*(Consolidado!$C$5:$C$1000="Consejo de Administración")*((($C$2="Todos")+(Consolidado!$I$5:$I$1000&""=$C$2&""))>0)) -> 0 | I7: =SUMPRODUCT((Consolidado!$E$5:$E$1000=$B7)*(Consolidado!$C$5:$C$1000="Otros")*((($C$2="Todos")+(Consolidado!$I$5:$I$1000&""=$C$2&""))>0)) -> 0 | J7: =SUM(D7:I7) -> 7 | K7: =SUMPRODUCT((Consolidado!$E$5:$E$1000=$B7)*(Consolidado!$AE$5:$AE$1000)*((($C$2="Todos")+(Consolidado!$I$5:$I$1000&""=$C$2&""))>0)) -> 2 | L7: =COUNTIF(D7:I7,">0") -> 1 | M7: =IF(L7>=2,"Sí","No") -> No | N7: =IF(J7=0,"",RANK(J7,$J$5:$J$33)) -> 3 | O7: =SUMPRODUCT((Consolidado!$E$5:$E$1000=$B7)*(MONTH(Consolidado!$B$5:$B$1000+0*(Consolidado!$B$5:$B$1000=""))=1)*(Consolidado!$B$5:$B$1000<>"")*((($C$2="Todos")+(Consolidado!$I$5:$I$1000&""=$C$2&""))>0)) -> 0 | P7: =SUMPRODUCT((Consolidado!$E$5:$E$1000=$B7)*(MONTH(Consolidado!$B$5:$B$1000+0*(Consolidado!$B$5:$B$1000=""))=2)*(Consolidado!$B$5:$B$1000<>"")*((($C$2="Todos")+(Consolidado!$I$5:$I$1000&""=$C$2&""))>0)) -> 0 | Q7: =SUMPRODUCT((Consolidado!$E$5:$E$1000=$B7)*(MONTH(Consolidado!$B$5:$B$1000+0*(Consolidado!$B$5:$B$1000=""))=3)*(Consolidado!$B$5:$B$1000<>"")*((($C$2="Todos")+(Consolidado!$I$5:$I$1000&""=$C$2&""))>0)) -> 0 | R7: =SUMPRODUCT((Consolidado!$E$5:$E$1000=$B7)*(MONTH(Consolidado!$B$5:$B$1000+0*(Consolidado!$B$5:$B$1000=""))=4)*(Consolidado!$B$5:$B$1000<>"")*((($C$2="Todos")+(Consolidado!$I$5:$I$1000&""=$C$2&""))>0)) -> 0 | S7: =SUMPRODUCT((Consolidado!$E$5:$E$1000=$B7)*(MONTH(Consolidado!$B$5:$B$1000+0*(Consolidado!$B$5:$B$1000=""))=5)*(Consolidado!$B$5:$B$1000<>"")*((($C$2="Todos")+(Consolidado!$I$5:$I$1000&""=$C$2&""))>0)) -> 1 | T7: =SUMPRODUCT((Consolidado!$E$5:$E$1000=$B7)*(MONTH(Consolidado!$B$5:$B$1000+0*(Consolidado!$B$5:$B$1000=""))=6)*(Consolidado!$B$5:$B$1000<>"")*((($C$2="Todos")+(Consolidado!$I$5:$I$1000&""=$C$2&""))>0)) -> 0 | U7: =SUMPRODUCT((Consolidado!$E$5:$E$1000=$B7)*(MONTH(Consolidado!$B$5:$B$1000+0*(Consolidado!$B$5:$B$1000=""))=7)*(Consolidado!$B$5:$B$1000<>"")*((($C$2="Todos")+(Consolidado!$I$5:$I$1000&""=$C$2&""))>0)) -> 0 | V7: =SUMPRODUCT((Consolidado!$E$5:$E$1000=$B7)*(MONTH(Consolidado!$B$5:$B$1000+0*(Consolidado!$B$5:$B$1000=""))=8)*(Consolidado!$B$5:$B$1000<>"")*((($C$2="Todos")+(Consolidado!$I$5:$I$1000&""=$C$2&""))>0)) -> 6 | W7: =SUMPRODUCT((Consolidado!$E$5:$E$1000=$B7)*(MONTH(Consolidado!$B$5:$B$1000+0*(Consolidado!$B$5:$B$1000=""))=9)*(Consolidado!$B$5:$B$1000<>"")*((($C$2="Todos")+(Consolidado!$I$5:$I$1000&""=$C$2&""))>0)) -> 0 | X7: =SUMPRODUCT((Consolidado!$E$5:$E$1000=$B7)*(MONTH(Consolidado!$B$5:$B$1000+0*(Consolidado!$B$5:$B$1000=""))=10)*(Consolidado!$B$5:$B$1000<>"")*((($C$2="Todos")+(Consolidado!$I$5:$I$1000&""=$C$2&""))>0)) -> 0 | Y7: =SUMPRODUCT((Consolidado!$E$5:$E$1000=$B7)*(MONTH(Consolidado!$B$5:$B$1000+0*(Consolidado!$B$5:$B$1000=""))=11)*(Consolidado!$B$5:$B$1000<>"")*((($C$2="Todos")+(Consolidado!$I$5:$I$1000&""=$C$2&""))>0)) -> 0 | Z7: =SUMPRODUCT((Consolidado!$E$5:$E$1000=$B7)*(MONTH(Consolidado!$B$5:$B$1000+0*(Consolidado!$B$5:$B$1000=""))=12)*(Consolidado!$B$5:$B$1000<>"")*((($C$2="Todos")+(Consolidado!$I$5:$I$1000&""=$C$2&""))>0)) -> 0
A8: 4 | B8: =Catálogos!C5 -> Políticas, manuales y divulgación GIR | C8: =Catálogos!D5 -> NRP-20 | D8: =SUMPRODUCT((Consolidado!$E$5:$E$1000=$B8)*(Consolidado!$C$5:$C$1000="Auditoría Interna")*((($C$2="Todos")+(Consolidado!$I$5:$I$1000&""=$C$2&""))>0)) -> 2 | E8: =SUMPRODUCT((Consolidado!$E$5:$E$1000=$B8)*(Consolidado!$C$5:$C$1000="Auditoría Externa")*((($C$2="Todos")+(Consolidado!$I$5:$I$1000&""=$C$2&""))>0)) -> 0 | F8: =SUMPRODUCT((Consolidado!$E$5:$E$1000=$B8)*(Consolidado!$C$5:$C$1000="SSF")*((($C$2="Todos")+(Consolidado!$I$5:$I$1000&""=$C$2&""))>0)) -> 0 | G8: =SUMPRODUCT((Consolidado!$E$5:$E$1000=$B8)*(Consolidado!$C$5:$C$1000="Comité de Supervisión")*((($C$2="Todos")+(Consolidado!$I$5:$I$1000&""=$C$2&""))>0)) -> 0 | H8: =SUMPRODUCT((Consolidado!$E$5:$E$1000=$B8)*(Consolidado!$C$5:$C$1000="Consejo de Administración")*((($C$2="Todos")+(Consolidado!$I$5:$I$1000&""=$C$2&""))>0)) -> 0 | I8: =SUMPRODUCT((Consolidado!$E$5:$E$1000=$B8)*(Consolidado!$C$5:$C$1000="Otros")*((($C$2="Todos")+(Consolidado!$I$5:$I$1000&""=$C$2&""))>0)) -> 0 | J8: =SUM(D8:I8) -> 2 | K8: =SUMPRODUCT((Consolidado!$E$5:$E$1000=$B8)*(Consolidado!$AE$5:$AE$1000)*((($C$2="Todos")+(Consolidado!$I$5:$I$1000&""=$C$2&""))>0)) -> 1 | L8: =COUNTIF(D8:I8,">0") -> 1 | M8: =IF(L8>=2,"Sí","No") -> No | N8: =IF(J8=0,"",RANK(J8,$J$5:$J$33)) -> 12 | O8: =SUMPRODUCT((Consolidado!$E$5:$E$1000=$B8)*(MONTH(Consolidado!$B$5:$B$1000+0*(Consolidado!$B$5:$B$1000=""))=1)*(Consolidado!$B$5:$B$1000<>"")*((($C$2="Todos")+(Consolidado!$I$5:$I$1000&""=$C$2&""))>0)) -> 0 | P8: =SUMPRODUCT((Consolidado!$E$5:$E$1000=$B8)*(MONTH(Consolidado!$B$5:$B$1000+0*(Consolidado!$B$5:$B$1000=""))=2)*(Consolidado!$B$5:$B$1000<>"")*((($C$2="Todos")+(Consolidado!$I$5:$I$1000&""=$C$2&""))>0)) -> 0 | Q8: =SUMPRODUCT((Consolidado!$E$5:$E$1000=$B8)*(MONTH(Consolidado!$B$5:$B$1000+0*(Consolidado!$B$5:$B$1000=""))=3)*(Consolidado!$B$5:$B$1000<>"")*((($C$2="Todos")+(Consolidado!$I$5:$I$1000&""=$C$2&""))>0)) -> 0 | R8: =SUMPRODUCT((Consolidado!$E$5:$E$1000=$B8)*(MONTH(Consolidado!$B$5:$B$1000+0*(Consolidado!$B$5:$B$1000=""))=4)*(Consolidado!$B$5:$B$1000<>"")*((($C$2="Todos")+(Consolidado!$I$5:$I$1000&""=$C$2&""))>0)) -> 0 | S8: =SUMPRODUCT((Consolidado!$E$5:$E$1000=$B8)*(MONTH(Consolidado!$B$5:$B$1000+0*(Consolidado!$B$5:$B$1000=""))=5)*(Consolidado!$B$5:$B$1000<>"")*((($C$2="Todos")+(Consolidado!$I$5:$I$1000&""=$C$2&""))>0)) -> 0 | T8: =SUMPRODUCT((Consolidado!$E$5:$E$1000=$B8)*(MONTH(Consolidado!$B$5:$B$1000+0*(Consolidado!$B$5:$B$1000=""))=6)*(Consolidado!$B$5:$B$1000<>"")*((($C$2="Todos")+(Consolidado!$I$5:$I$1000&""=$C$2&""))>0)) -> 0 | U8: =SUMPRODUCT((Consolidado!$E$5:$E$1000=$B8)*(MONTH(Consolidado!$B$5:$B$1000+0*(Consolidado!$B$5:$B$1000=""))=7)*(Consolidado!$B$5:$B$1000<>"")*((($C$2="Todos")+(Consolidado!$I$5:$I$1000&""=$C$2&""))>0)) -> 0 | V8: =SUMPRODUCT((Consolidado!$E$5:$E$1000=$B8)*(MONTH(Consolidado!$B$5:$B$1000+0*(Consolidado!$B$5:$B$1000=""))=8)*(Consolidado!$B$5:$B$1000<>"")*((($C$2="Todos")+(Consolidado!$I$5:$I$1000&""=$C$2&""))>0)) -> 2 | W8: =SUMPRODUCT((Consolidado!$E$5:$E$1000=$B8)*(MONTH(Consolidado!$B$5:$B$1000+0*(Consolidado!$B$5:$B$1000=""))=9)*(Consolidado!$B$5:$B$1000<>"")*((($C$2="Todos")+(Consolidado!$I$5:$I$1000&""=$C$2&""))>0)) -> 0 | X8: =SUMPRODUCT((Consolidado!$E$5:$E$1000=$B8)*(MONTH(Consolidado!$B$5:$B$1000+0*(Consolidado!$B$5:$B$1000=""))=10)*(Consolidado!$B$5:$B$1000<>"")*((($C$2="Todos")+(Consolidado!$I$5:$I$1000&""=$C$2&""))>0)) -> 0 | Y8: =SUMPRODUCT((Consolidado!$E$5:$E$1000=$B8)*(MONTH(Consolidado!$B$5:$B$1000+0*(Consolidado!$B$5:$B$1000=""))=11)*(Consolidado!$B$5:$B$1000<>"")*((($C$2="Todos")+(Consolidado!$I$5:$I$1000&""=$C$2&""))>0)) -> 0 | Z8: =SUMPRODUCT((Consolidado!$E$5:$E$1000=$B8)*(MONTH(Consolidado!$B$5:$B$1000+0*(Consolidado!$B$5:$B$1000=""))=12)*(Consolidado!$B$5:$B$1000<>"")*((($C$2="Todos")+(Consolidado!$I$5:$I$1000&""=$C$2&""))>0)) -> 0
A9: 5 | B9: =Catálogos!C6 -> Pérdida Esperada | C9: =Catálogos!D6 -> NCB-022 | D9: =SUMPRODUCT((Consolidado!$E$5:$E$1000=$B9)*(Consolidado!$C$5:$C$1000="Auditoría Interna")*((($C$2="Todos")+(Consolidado!$I$5:$I$1000&""=$C$2&""))>0)) -> 1 | E9: =SUMPRODUCT((Consolidado!$E$5:$E$1000=$B9)*(Consolidado!$C$5:$C$1000="Auditoría Externa")*((($C$2="Todos")+(Consolidado!$I$5:$I$1000&""=$C$2&""))>0)) -> 2 | F9: =SUMPRODUCT((Consolidado!$E$5:$E$1000=$B9)*(Consolidado!$C$5:$C$1000="SSF")*((($C$2="Todos")+(Consolidado!$I$5:$I$1000&""=$C$2&""))>0)) -> 0 | G9: =SUMPRODUCT((Consolidado!$E$5:$E$1000=$B9)*(Consolidado!$C$5:$C$1000="Comité de Supervisión")*((($C$2="Todos")+(Consolidado!$I$5:$I$1000&""=$C$2&""))>0)) -> 0 | H9: =SUMPRODUCT((Consolidado!$E$5:$E$1000=$B9)*(Consolidado!$C$5:$C$1000="Consejo de Administración")*((($C$2="Todos")+(Consolidado!$I$5:$I$1000&""=$C$2&""))>0)) -> 0 | I9: =SUMPRODUCT((Consolidado!$E$5:$E$1000=$B9)*(Consolidado!$C$5:$C$1000="Otros")*((($C$2="Todos")+(Consolidado!$I$5:$I$1000&""=$C$2&""))>0)) -> 0 | J9: =SUM(D9:I9) -> 3 | K9: =SUMPRODUCT((Consolidado!$E$5:$E$1000=$B9)*(Consolidado!$AE$5:$AE$1000)*((($C$2="Todos")+(Consolidado!$I$5:$I$1000&""=$C$2&""))>0)) -> 2 | L9: =COUNTIF(D9:I9,">0") -> 2 | M9: =IF(L9>=2,"Sí","No") -> Sí | N9: =IF(J9=0,"",RANK(J9,$J$5:$J$33)) -> 8 | O9: =SUMPRODUCT((Consolidado!$E$5:$E$1000=$B9)*(MONTH(Consolidado!$B$5:$B$1000+0*(Consolidado!$B$5:$B$1000=""))=1)*(Consolidado!$B$5:$B$1000<>"")*((($C$2="Todos")+(Consolidado!$I$5:$I$1000&""=$C$2&""))>0)) -> 0 | P9: =SUMPRODUCT((Consolidado!$E$5:$E$1000=$B9)*(MONTH(Consolidado!$B$5:$B$1000+0*(Consolidado!$B$5:$B$1000=""))=2)*(Consolidado!$B$5:$B$1000<>"")*((($C$2="Todos")+(Consolidado!$I$5:$I$1000&""=$C$2&""))>0)) -> 0 | Q9: =SUMPRODUCT((Consolidado!$E$5:$E$1000=$B9)*(MONTH(Consolidado!$B$5:$B$1000+0*(Consolidado!$B$5:$B$1000=""))=3)*(Consolidado!$B$5:$B$1000<>"")*((($C$2="Todos")+(Consolidado!$I$5:$I$1000&""=$C$2&""))>0)) -> 0 | R9: =SUMPRODUCT((Consolidado!$E$5:$E$1000=$B9)*(MONTH(Consolidado!$B$5:$B$1000+0*(Consolidado!$B$5:$B$1000=""))=4)*(Consolidado!$B$5:$B$1000<>"")*((($C$2="Todos")+(Consolidado!$I$5:$I$1000&""=$C$2&""))>0)) -> 0 | S9: =SUMPRODUCT((Consolidado!$E$5:$E$1000=$B9)*(MONTH(Consolidado!$B$5:$B$1000+0*(Consolidado!$B$5:$B$1000=""))=5)*(Consolidado!$B$5:$B$1000<>"")*((($C$2="Todos")+(Consolidado!$I$5:$I$1000&""=$C$2&""))>0)) -> 1 | T9: =SUMPRODUCT((Consolidado!$E$5:$E$1000=$B9)*(MONTH(Consolidado!$B$5:$B$1000+0*(Consolidado!$B$5:$B$1000=""))=6)*(Consolidado!$B$5:$B$1000<>"")*((($C$2="Todos")+(Consolidado!$I$5:$I$1000&""=$C$2&""))>0)) -> 0 | U9: =SUMPRODUCT((Consolidado!$E$5:$E$1000=$B9)*(MONTH(Consolidado!$B$5:$B$1000+0*(Consolidado!$B$5:$B$1000=""))=7)*(Consolidado!$B$5:$B$1000<>"")*((($C$2="Todos")+(Consolidado!$I$5:$I$1000&""=$C$2&""))>0)) -> 0 | V9: =SUMPRODUCT((Consolidado!$E$5:$E$1000=$B9)*(MONTH(Consolidado!$B$5:$B$1000+0*(Consolidado!$B$5:$B$1000=""))=8)*(Consolidado!$B$5:$B$1000<>"")*((($C$2="Todos")+(Consolidado!$I$5:$I$1000&""=$C$2&""))>0)) -> 0 | W9: =SUMPRODUCT((Consolidado!$E$5:$E$1000=$B9)*(MONTH(Consolidado!$B$5:$B$1000+0*(Consolidado!$B$5:$B$1000=""))=9)*(Consolidado!$B$5:$B$1000<>"")*((($C$2="Todos")+(Consolidado!$I$5:$I$1000&""=$C$2&""))>0)) -> 0 | X9: =SUMPRODUCT((Consolidado!$E$5:$E$1000=$B9)*(MONTH(Consolidado!$B$5:$B$1000+0*(Consolidado!$B$5:$B$1000=""))=10)*(Consolidado!$B$5:$B$1000<>"")*((($C$2="Todos")+(Consolidado!$I$5:$I$1000&""=$C$2&""))>0)) -> 2 | Y9: =SUMPRODUCT((Consolidado!$E$5:$E$1000=$B9)*(MONTH(Consolidado!$B$5:$B$1000+0*(Consolidado!$B$5:$B$1000=""))=11)*(Consolidado!$B$5:$B$1000<>"")*((($C$2="Todos")+(Consolidado!$I$5:$I$1000&""=$C$2&""))>0)) -> 0 | Z9: =SUMPRODUCT((Consolidado!$E$5:$E$1000=$B9)*(MONTH(Consolidado!$B$5:$B$1000+0*(Consolidado!$B$5:$B$1000=""))=12)*(Consolidado!$B$5:$B$1000<>"")*((($C$2="Todos")+(Consolidado!$I$5:$I$1000&""=$C$2&""))>0)) -> 0
A10: 6 | B10: =Catálogos!C7 -> Clasificación de cartera, mora y reservas | C10: =Catálogos!D7 -> NCB-022 | D10: =SUMPRODUCT((Consolidado!$E$5:$E$1000=$B10)*(Consolidado!$C$5:$C$1000="Auditoría Interna")*((($C$2="Todos")+(Consolidado!$I$5:$I$1000&""=$C$2&""))>0)) -> 1 | E10: =SUMPRODUCT((Consolidado!$E$5:$E$1000=$B10)*(Consolidado!$C$5:$C$1000="Auditoría Externa")*((($C$2="Todos")+(Consolidado!$I$5:$I$1000&""=$C$2&""))>0)) -> 3 | F10: =SUMPRODUCT((Consolidado!$E$5:$E$1000=$B10)*(Consolidado!$C$5:$C$1000="SSF")*((($C$2="Todos")+(Consolidado!$I$5:$I$1000&""=$C$2&""))>0)) -> 2 | G10: =SUMPRODUCT((Consolidado!$E$5:$E$1000=$B10)*(Consolidado!$C$5:$C$1000="Comité de Supervisión")*((($C$2="Todos")+(Consolidado!$I$5:$I$1000&""=$C$2&""))>0)) -> 0 | H10: =SUMPRODUCT((Consolidado!$E$5:$E$1000=$B10)*(Consolidado!$C$5:$C$1000="Consejo de Administración")*((($C$2="Todos")+(Consolidado!$I$5:$I$1000&""=$C$2&""))>0)) -> 0 | I10: =SUMPRODUCT((Consolidado!$E$5:$E$1000=$B10)*(Consolidado!$C$5:$C$1000="Otros")*((($C$2="Todos")+(Consolidado!$I$5:$I$1000&""=$C$2&""))>0)) -> 0 | J10: =SUM(D10:I10) -> 6 | K10: =SUMPRODUCT((Consolidado!$E$5:$E$1000=$B10)*(Consolidado!$AE$5:$AE$1000)*((($C$2="Todos")+(Consolidado!$I$5:$I$1000&""=$C$2&""))>0)) -> 4 | L10: =COUNTIF(D10:I10,">0") -> 3 | M10: =IF(L10>=2,"Sí","No") -> Sí | N10: =IF(J10=0,"",RANK(J10,$J$5:$J$33)) -> 4 | O10: =SUMPRODUCT((Consolidado!$E$5:$E$1000=$B10)*(MONTH(Consolidado!$B$5:$B$1000+0*(Consolidado!$B$5:$B$1000=""))=1)*(Consolidado!$B$5:$B$1000<>"")*((($C$2="Todos")+(Consolidado!$I$5:$I$1000&""=$C$2&""))>0)) -> 1 | P10: =SUMPRODUCT((Consolidado!$E$5:$E$1000=$B10)*(MONTH(Consolidado!$B$5:$B$1000+0*(Consolidado!$B$5:$B$1000=""))=2)*(Consolidado!$B$5:$B$1000<>"")*((($C$2="Todos")+(Consolidado!$I$5:$I$1000&""=$C$2&""))>0)) -> 0 | Q10: =SUMPRODUCT((Consolidado!$E$5:$E$1000=$B10)*(MONTH(Consolidado!$B$5:$B$1000+0*(Consolidado!$B$5:$B$1000=""))=3)*(Consolidado!$B$5:$B$1000<>"")*((($C$2="Todos")+(Consolidado!$I$5:$I$1000&""=$C$2&""))>0)) -> 0 | R10: =SUMPRODUCT((Consolidado!$E$5:$E$1000=$B10)*(MONTH(Consolidado!$B$5:$B$1000+0*(Consolidado!$B$5:$B$1000=""))=4)*(Consolidado!$B$5:$B$1000<>"")*((($C$2="Todos")+(Consolidado!$I$5:$I$1000&""=$C$2&""))>0)) -> 0 | S10: =SUMPRODUCT((Consolidado!$E$5:$E$1000=$B10)*(MONTH(Consolidado!$B$5:$B$1000+0*(Consolidado!$B$5:$B$1000=""))=5)*(Consolidado!$B$5:$B$1000<>"")*((($C$2="Todos")+(Consolidado!$I$5:$I$1000&""=$C$2&""))>0)) -> 1 | T10: =SUMPRODUCT((Consolidado!$E$5:$E$1000=$B10)*(MONTH(Consolidado!$B$5:$B$1000+0*(Consolidado!$B$5:$B$1000=""))=6)*(Consolidado!$B$5:$B$1000<>"")*((($C$2="Todos")+(Consolidado!$I$5:$I$1000&""=$C$2&""))>0)) -> 0 | U10: =SUMPRODUCT((Consolidado!$E$5:$E$1000=$B10)*(MONTH(Consolidado!$B$5:$B$1000+0*(Consolidado!$B$5:$B$1000=""))=7)*(Consolidado!$B$5:$B$1000<>"")*((($C$2="Todos")+(Consolidado!$I$5:$I$1000&""=$C$2&""))>0)) -> 0 | V10: =SUMPRODUCT((Consolidado!$E$5:$E$1000=$B10)*(MONTH(Consolidado!$B$5:$B$1000+0*(Consolidado!$B$5:$B$1000=""))=8)*(Consolidado!$B$5:$B$1000<>"")*((($C$2="Todos")+(Consolidado!$I$5:$I$1000&""=$C$2&""))>0)) -> 1 | W10: =SUMPRODUCT((Consolidado!$E$5:$E$1000=$B10)*(MONTH(Consolidado!$B$5:$B$1000+0*(Consolidado!$B$5:$B$1000=""))=9)*(Consolidado!$B$5:$B$1000<>"")*((($C$2="Todos")+(Consolidado!$I$5:$I$1000&""=$C$2&""))>0)) -> 0 | X10: =SUMPRODUCT((Consolidado!$E$5:$E$1000=$B10)*(MONTH(Consolidado!$B$5:$B$1000+0*(Consolidado!$B$5:$B$1000=""))=10)*(Consolidado!$B$5:$B$1000<>"")*((($C$2="Todos")+(Consolidado!$I$5:$I$1000&""=$C$2&""))>0)) -> 3 | Y10: =SUMPRODUCT((Consolidado!$E$5:$E$1000=$B10)*(MONTH(Consolidado!$B$5:$B$1000+0*(Consolidado!$B$5:$B$1000=""))=11)*(Consolidado!$B$5:$B$1000<>"")*((($C$2="Todos")+(Consolidado!$I$5:$I$1000&""=$C$2&""))>0)) -> 0 | Z10: =SUMPRODUCT((Consolidado!$E$5:$E$1000=$B10)*(MONTH(Consolidado!$B$5:$B$1000+0*(Consolidado!$B$5:$B$1000=""))=12)*(Consolidado!$B$5:$B$1000<>"")*((($C$2="Todos")+(Consolidado!$I$5:$I$1000&""=$C$2&""))>0)) -> 0
A11: 7 | B11: =Catálogos!C8 -> Concentración crediticia | C11: =Catálogos!D8 -> NPB4-49 | D11: =SUMPRODUCT((Consolidado!$E$5:$E$1000=$B11)*(Consolidado!$C$5:$C$1000="Auditoría Interna")*((($C$2="Todos")+(Consolidado!$I$5:$I$1000&""=$C$2&""))>0)) -> 0 | E11: =SUMPRODUCT((Consolidado!$E$5:$E$1000=$B11)*(Consolidado!$C$5:$C$1000="Auditoría Externa")*((($C$2="Todos")+(Consolidado!$I$5:$I$1000&""=$C$2&""))>0)) -> 3 | F11: =SUMPRODUCT((Consolidado!$E$5:$E$1000=$B11)*(Consolidado!$C$5:$C$1000="SSF")*((($C$2="Todos")+(Consolidado!$I$5:$I$1000&""=$C$2&""))>0)) -> 0 | G11: =SUMPRODUCT((Consolidado!$E$5:$E$1000=$B11)*(Consolidado!$C$5:$C$1000="Comité de Supervisión")*((($C$2="Todos")+(Consolidado!$I$5:$I$1000&""=$C$2&""))>0)) -> 0 | H11: =SUMPRODUCT((Consolidado!$E$5:$E$1000=$B11)*(Consolidado!$C$5:$C$1000="Consejo de Administración")*((($C$2="Todos")+(Consolidado!$I$5:$I$1000&""=$C$2&""))>0)) -> 0 | I11: =SUMPRODUCT((Consolidado!$E$5:$E$1000=$B11)*(Consolidado!$C$5:$C$1000="Otros")*((($C$2="Todos")+(Consolidado!$I$5:$I$1000&""=$C$2&""))>0)) -> 0 | J11: =SUM(D11:I11) -> 3 | K11: =SUMPRODUCT((Consolidado!$E$5:$E$1000=$B11)*(Consolidado!$AE$5:$AE$1000)*((($C$2="Todos")+(Consolidado!$I$5:$I$1000&""=$C$2&""))>0)) -> 1 | L11: =COUNTIF(D11:I11,">0") -> 1 | M11: =IF(L11>=2,"Sí","No") -> No | N11: =IF(J11=0,"",RANK(J11,$J$5:$J$33)) -> 8 | O11: =SUMPRODUCT((Consolidado!$E$5:$E$1000=$B11)*(MONTH(Consolidado!$B$5:$B$1000+0*(Consolidado!$B$5:$B$1000=""))=1)*(Consolidado!$B$5:$B$1000<>"")*((($C$2="Todos")+(Consolidado!$I$5:$I$1000&""=$C$2&""))>0)) -> 0 | P11: =SUMPRODUCT((Consolidado!$E$5:$E$1000=$B11)*(MONTH(Consolidado!$B$5:$B$1000+0*(Consolidado!$B$5:$B$1000=""))=2)*(Consolidado!$B$5:$B$1000<>"")*((($C$2="Todos")+(Consolidado!$I$5:$I$1000&""=$C$2&""))>0)) -> 0 | Q11: =SUMPRODUCT((Consolidado!$E$5:$E$1000=$B11)*(MONTH(Consolidado!$B$5:$B$1000+0*(Consolidado!$B$5:$B$1000=""))=3)*(Consolidado!$B$5:$B$1000<>"")*((($C$2="Todos")+(Consolidado!$I$5:$I$1000&""=$C$2&""))>0)) -> 0 | R11: =SUMPRODUCT((Consolidado!$E$5:$E$1000=$B11)*(MONTH(Consolidado!$B$5:$B$1000+0*(Consolidado!$B$5:$B$1000=""))=4)*(Consolidado!$B$5:$B$1000<>"")*((($C$2="Todos")+(Consolidado!$I$5:$I$1000&""=$C$2&""))>0)) -> 0 | S11: =SUMPRODUCT((Consolidado!$E$5:$E$1000=$B11)*(MONTH(Consolidado!$B$5:$B$1000+0*(Consolidado!$B$5:$B$1000=""))=5)*(Consolidado!$B$5:$B$1000<>"")*((($C$2="Todos")+(Consolidado!$I$5:$I$1000&""=$C$2&""))>0)) -> 0 | T11: =SUMPRODUCT((Consolidado!$E$5:$E$1000=$B11)*(MONTH(Consolidado!$B$5:$B$1000+0*(Consolidado!$B$5:$B$1000=""))=6)*(Consolidado!$B$5:$B$1000<>"")*((($C$2="Todos")+(Consolidado!$I$5:$I$1000&""=$C$2&""))>0)) -> 0 | U11: =SUMPRODUCT((Consolidado!$E$5:$E$1000=$B11)*(MONTH(Consolidado!$B$5:$B$1000+0*(Consolidado!$B$5:$B$1000=""))=7)*(Consolidado!$B$5:$B$1000<>"")*((($C$2="Todos")+(Consolidado!$I$5:$I$1000&""=$C$2&""))>0)) -> 0 | V11: =SUMPRODUCT((Consolidado!$E$5:$E$1000=$B11)*(MONTH(Consolidado!$B$5:$B$1000+0*(Consolidado!$B$5:$B$1000=""))=8)*(Consolidado!$B$5:$B$1000<>"")*((($C$2="Todos")+(Consolidado!$I$5:$I$1000&""=$C$2&""))>0)) -> 0 | W11: =SUMPRODUCT((Consolidado!$E$5:$E$1000=$B11)*(MONTH(Consolidado!$B$5:$B$1000+0*(Consolidado!$B$5:$B$1000=""))=9)*(Consolidado!$B$5:$B$1000<>"")*((($C$2="Todos")+(Consolidado!$I$5:$I$1000&""=$C$2&""))>0)) -> 0 | X11: =SUMPRODUCT((Consolidado!$E$5:$E$1000=$B11)*(MONTH(Consolidado!$B$5:$B$1000+0*(Consolidado!$B$5:$B$1000=""))=10)*(Consolidado!$B$5:$B$1000<>"")*((($C$2="Todos")+(Consolidado!$I$5:$I$1000&""=$C$2&""))>0)) -> 3 | Y11: =SUMPRODUCT((Consolidado!$E$5:$E$1000=$B11)*(MONTH(Consolidado!$B$5:$B$1000+0*(Consolidado!$B$5:$B$1000=""))=11)*(Consolidado!$B$5:$B$1000<>"")*((($C$2="Todos")+(Consolidado!$I$5:$I$1000&""=$C$2&""))>0)) -> 0 | Z11: =SUMPRODUCT((Consolidado!$E$5:$E$1000=$B11)*(MONTH(Consolidado!$B$5:$B$1000+0*(Consolidado!$B$5:$B$1000=""))=12)*(Consolidado!$B$5:$B$1000<>"")*((($C$2="Todos")+(Consolidado!$I$5:$I$1000&""=$C$2&""))>0)) -> 0
A12: 8 | B12: =Catálogos!C9 -> Créditos a personas relacionadas | C12: =Catálogos!D9 -> Por validar | D12: =SUMPRODUCT((Consolidado!$E$5:$E$1000=$B12)*(Consolidado!$C$5:$C$1000="Auditoría Interna")*((($C$2="Todos")+(Consolidado!$I$5:$I$1000&""=$C$2&""))>0)) -> 0 | E12: =SUMPRODUCT((Consolidado!$E$5:$E$1000=$B12)*(Consolidado!$C$5:$C$1000="Auditoría Externa")*((($C$2="Todos")+(Consolidado!$I$5:$I$1000&""=$C$2&""))>0)) -> 1 | F12: =SUMPRODUCT((Consolidado!$E$5:$E$1000=$B12)*(Consolidado!$C$5:$C$1000="SSF")*((($C$2="Todos")+(Consolidado!$I$5:$I$1000&""=$C$2&""))>0)) -> 0 | G12: =SUMPRODUCT((Consolidado!$E$5:$E$1000=$B12)*(Consolidado!$C$5:$C$1000="Comité de Supervisión")*((($C$2="Todos")+(Consolidado!$I$5:$I$1000&""=$C$2&""))>0)) -> 0 | H12: =SUMPRODUCT((Consolidado!$E$5:$E$1000=$B12)*(Consolidado!$C$5:$C$1000="Consejo de Administración")*((($C$2="Todos")+(Consolidado!$I$5:$I$1000&""=$C$2&""))>0)) -> 0 | I12: =SUMPRODUCT((Consolidado!$E$5:$E$1000=$B12)*(Consolidado!$C$5:$C$1000="Otros")*((($C$2="Todos")+(Consolidado!$I$5:$I$1000&""=$C$2&""))>0)) -> 0 | J12: =SUM(D12:I12) -> 1 | K12: =SUMPRODUCT((Consolidado!$E$5:$E$1000=$B12)*(Consolidado!$AE$5:$AE$1000)*((($C$2="Todos")+(Consolidado!$I$5:$I$1000&""=$C$2&""))>0)) -> 1 | L12: =COUNTIF(D12:I12,">0") -> 1 | M12: =IF(L12>=2,"Sí","No") -> No | N12: =IF(J12=0,"",RANK(J12,$J$5:$J$33)) -> 17 | O12: =SUMPRODUCT((Consolidado!$E$5:$E$1000=$B12)*(MONTH(Consolidado!$B$5:$B$1000+0*(Consolidado!$B$5:$B$1000=""))=1)*(Consolidado!$B$5:$B$1000<>"")*((($C$2="Todos")+(Consolidado!$I$5:$I$1000&""=$C$2&""))>0)) -> 0 | P12: =SUMPRODUCT((Consolidado!$E$5:$E$1000=$B12)*(MONTH(Consolidado!$B$5:$B$1000+0*(Consolidado!$B$5:$B$1000=""))=2)*(Consolidado!$B$5:$B$1000<>"")*((($C$2="Todos")+(Consolidado!$I$5:$I$1000&""=$C$2&""))>0)) -> 0 | Q12: =SUMPRODUCT((Consolidado!$E$5:$E$1000=$B12)*(MONTH(Consolidado!$B$5:$B$1000+0*(Consolidado!$B$5:$B$1000=""))=3)*(Consolidado!$B$5:$B$1000<>"")*((($C$2="Todos")+(Consolidado!$I$5:$I$1000&""=$C$2&""))>0)) -> 0 | R12: =SUMPRODUCT((Consolidado!$E$5:$E$1000=$B12)*(MONTH(Consolidado!$B$5:$B$1000+0*(Consolidado!$B$5:$B$1000=""))=4)*(Consolidado!$B$5:$B$1000<>"")*((($C$2="Todos")+(Consolidado!$I$5:$I$1000&""=$C$2&""))>0)) -> 0 | S12: =SUMPRODUCT((Consolidado!$E$5:$E$1000=$B12)*(MONTH(Consolidado!$B$5:$B$1000+0*(Consolidado!$B$5:$B$1000=""))=5)*(Consolidado!$B$5:$B$1000<>"")*((($C$2="Todos")+(Consolidado!$I$5:$I$1000&""=$C$2&""))>0)) -> 0 | T12: =SUMPRODUCT((Consolidado!$E$5:$E$1000=$B12)*(MONTH(Consolidado!$B$5:$B$1000+0*(Consolidado!$B$5:$B$1000=""))=6)*(Consolidado!$B$5:$B$1000<>"")*((($C$2="Todos")+(Consolidado!$I$5:$I$1000&""=$C$2&""))>0)) -> 0 | U12: =SUMPRODUCT((Consolidado!$E$5:$E$1000=$B12)*(MONTH(Consolidado!$B$5:$B$1000+0*(Consolidado!$B$5:$B$1000=""))=7)*(Consolidado!$B$5:$B$1000<>"")*((($C$2="Todos")+(Consolidado!$I$5:$I$1000&""=$C$2&""))>0)) -> 0 | V12: =SUMPRODUCT((Consolidado!$E$5:$E$1000=$B12)*(MONTH(Consolidado!$B$5:$B$1000+0*(Consolidado!$B$5:$B$1000=""))=8)*(Consolidado!$B$5:$B$1000<>"")*((($C$2="Todos")+(Consolidado!$I$5:$I$1000&""=$C$2&""))>0)) -> 0 | W12: =SUMPRODUCT((Consolidado!$E$5:$E$1000=$B12)*(MONTH(Consolidado!$B$5:$B$1000+0*(Consolidado!$B$5:$B$1000=""))=9)*(Consolidado!$B$5:$B$1000<>"")*((($C$2="Todos")+(Consolidado!$I$5:$I$1000&""=$C$2&""))>0)) -> 0 | X12: =SUMPRODUCT((Consolidado!$E$5:$E$1000=$B12)*(MONTH(Consolidado!$B$5:$B$1000+0*(Consolidado!$B$5:$B$1000=""))=10)*(Consolidado!$B$5:$B$1000<>"")*((($C$2="Todos")+(Consolidado!$I$5:$I$1000&""=$C$2&""))>0)) -> 1 | Y12: =SUMPRODUCT((Consolidado!$E$5:$E$1000=$B12)*(MONTH(Consolidado!$B$5:$B$1000+0*(Consolidado!$B$5:$B$1000=""))=11)*(Consolidado!$B$5:$B$1000<>"")*((($C$2="Todos")+(Consolidado!$I$5:$I$1000&""=$C$2&""))>0)) -> 0 | Z12: =SUMPRODUCT((Consolidado!$E$5:$E$1000=$B12)*(MONTH(Consolidado!$B$5:$B$1000+0*(Consolidado!$B$5:$B$1000=""))=12)*(Consolidado!$B$5:$B$1000<>"")*((($C$2="Todos")+(Consolidado!$I$5:$I$1000&""=$C$2&""))>0)) -> 0
A13: 9 | B13: =Catálogos!C10 -> Valúos y garantías | C13: =Catálogos!D10 -> NRP-25 | D13: =SUMPRODUCT((Consolidado!$E$5:$E$1000=$B13)*(Consolidado!$C$5:$C$1000="Auditoría Interna")*((($C$2="Todos")+(Consolidado!$I$5:$I$1000&""=$C$2&""))>0)) -> 1 | E13: =SUMPRODUCT((Consolidado!$E$5:$E$1000=$B13)*(Consolidado!$C$5:$C$1000="Auditoría Externa")*((($C$2="Todos")+(Consolidado!$I$5:$I$1000&""=$C$2&""))>0)) -> 0 | F13: =SUMPRODUCT((Consolidado!$E$5:$E$1000=$B13)*(Consolidado!$C$5:$C$1000="SSF")*((($C$2="Todos")+(Consolidado!$I$5:$I$1000&""=$C$2&""))>0)) -> 1 | G13: =SUMPRODUCT((Consolidado!$E$5:$E$1000=$B13)*(Consolidado!$C$5:$C$1000="Comité de Supervisión")*((($C$2="Todos")+(Consolidado!$I$5:$I$1000&""=$C$2&""))>0)) -> 0 | H13: =SUMPRODUCT((Consolidado!$E$5:$E$1000=$B13)*(Consolidado!$C$5:$C$1000="Consejo de Administración")*((($C$2="Todos")+(Consolidado!$I$5:$I$1000&""=$C$2&""))>0)) -> 0 | I13: =SUMPRODUCT((Consolidado!$E$5:$E$1000=$B13)*(Consolidado!$C$5:$C$1000="Otros")*((($C$2="Todos")+(Consolidado!$I$5:$I$1000&""=$C$2&""))>0)) -> 0 | J13: =SUM(D13:I13) -> 2 | K13: =SUMPRODUCT((Consolidado!$E$5:$E$1000=$B13)*(Consolidado!$AE$5:$AE$1000)*((($C$2="Todos")+(Consolidado!$I$5:$I$1000&""=$C$2&""))>0)) -> 2 | L13: =COUNTIF(D13:I13,">0") -> 2 | M13: =IF(L13>=2,"Sí","No") -> Sí | N13: =IF(J13=0,"",RANK(J13,$J$5:$J$33)) -> 12 | O13: =SUMPRODUCT((Consolidado!$E$5:$E$1000=$B13)*(MONTH(Consolidado!$B$5:$B$1000+0*(Consolidado!$B$5:$B$1000=""))=1)*(Consolidado!$B$5:$B$1000<>"")*((($C$2="Todos")+(Consolidado!$I$5:$I$1000&""=$C$2&""))>0)) -> 0 | P13: =SUMPRODUCT((Consolidado!$E$5:$E$1000=$B13)*(MONTH(Consolidado!$B$5:$B$1000+0*(Consolidado!$B$5:$B$1000=""))=2)*(Consolidado!$B$5:$B$1000<>"")*((($C$2="Todos")+(Consolidado!$I$5:$I$1000&""=$C$2&""))>0)) -> 0 | Q13: =SUMPRODUCT((Consolidado!$E$5:$E$1000=$B13)*(MONTH(Consolidado!$B$5:$B$1000+0*(Consolidado!$B$5:$B$1000=""))=3)*(Consolidado!$B$5:$B$1000<>"")*((($C$2="Todos")+(Consolidado!$I$5:$I$1000&""=$C$2&""))>0)) -> 0 | R13: =SUMPRODUCT((Consolidado!$E$5:$E$1000=$B13)*(MONTH(Consolidado!$B$5:$B$1000+0*(Consolidado!$B$5:$B$1000=""))=4)*(Consolidado!$B$5:$B$1000<>"")*((($C$2="Todos")+(Consolidado!$I$5:$I$1000&""=$C$2&""))>0)) -> 1 | S13: =SUMPRODUCT((Consolidado!$E$5:$E$1000=$B13)*(MONTH(Consolidado!$B$5:$B$1000+0*(Consolidado!$B$5:$B$1000=""))=5)*(Consolidado!$B$5:$B$1000<>"")*((($C$2="Todos")+(Consolidado!$I$5:$I$1000&""=$C$2&""))>0)) -> 1 | T13: =SUMPRODUCT((Consolidado!$E$5:$E$1000=$B13)*(MONTH(Consolidado!$B$5:$B$1000+0*(Consolidado!$B$5:$B$1000=""))=6)*(Consolidado!$B$5:$B$1000<>"")*((($C$2="Todos")+(Consolidado!$I$5:$I$1000&""=$C$2&""))>0)) -> 0 | U13: =SUMPRODUCT((Consolidado!$E$5:$E$1000=$B13)*(MONTH(Consolidado!$B$5:$B$1000+0*(Consolidado!$B$5:$B$1000=""))=7)*(Consolidado!$B$5:$B$1000<>"")*((($C$2="Todos")+(Consolidado!$I$5:$I$1000&""=$C$2&""))>0)) -> 0 | V13: =SUMPRODUCT((Consolidado!$E$5:$E$1000=$B13)*(MONTH(Consolidado!$B$5:$B$1000+0*(Consolidado!$B$5:$B$1000=""))=8)*(Consolidado!$B$5:$B$1000<>"")*((($C$2="Todos")+(Consolidado!$I$5:$I$1000&""=$C$2&""))>0)) -> 0 | W13: =SUMPRODUCT((Consolidado!$E$5:$E$1000=$B13)*(MONTH(Consolidado!$B$5:$B$1000+0*(Consolidado!$B$5:$B$1000=""))=9)*(Consolidado!$B$5:$B$1000<>"")*((($C$2="Todos")+(Consolidado!$I$5:$I$1000&""=$C$2&""))>0)) -> 0 | X13: =SUMPRODUCT((Consolidado!$E$5:$E$1000=$B13)*(MONTH(Consolidado!$B$5:$B$1000+0*(Consolidado!$B$5:$B$1000=""))=10)*(Consolidado!$B$5:$B$1000<>"")*((($C$2="Todos")+(Consolidado!$I$5:$I$1000&""=$C$2&""))>0)) -> 0 | Y13: =SUMPRODUCT((Consolidado!$E$5:$E$1000=$B13)*(MONTH(Consolidado!$B$5:$B$1000+0*(Consolidado!$B$5:$B$1000=""))=11)*(Consolidado!$B$5:$B$1000<>"")*((($C$2="Todos")+(Consolidado!$I$5:$I$1000&""=$C$2&""))>0)) -> 0 | Z13: =SUMPRODUCT((Consolidado!$E$5:$E$1000=$B13)*(MONTH(Consolidado!$B$5:$B$1000+0*(Consolidado!$B$5:$B$1000=""))=12)*(Consolidado!$B$5:$B$1000<>"")*((($C$2="Todos")+(Consolidado!$I$5:$I$1000&""=$C$2&""))>0)) -> 0
A14: 10 | B14: =Catálogos!C11 -> Escenarios de estrés de crédito | C14: =Catálogos!D11 -> NPB4-49 | D14: =SUMPRODUCT((Consolidado!$E$5:$E$1000=$B14)*(Consolidado!$C$5:$C$1000="Auditoría Interna")*((($C$2="Todos")+(Consolidado!$I$5:$I$1000&""=$C$2&""))>0)) -> 1 | E14: =SUMPRODUCT((Consolidado!$E$5:$E$1000=$B14)*(Consolidado!$C$5:$C$1000="Auditoría Externa")*((($C$2="Todos")+(Consolidado!$I$5:$I$1000&""=$C$2&""))>0)) -> 0 | F14: =SUMPRODUCT((Consolidado!$E$5:$E$1000=$B14)*(Consolidado!$C$5:$C$1000="SSF")*((($C$2="Todos")+(Consolidado!$I$5:$I$1000&""=$C$2&""))>0)) -> 0 | G14: =SUMPRODUCT((Consolidado!$E$5:$E$1000=$B14)*(Consolidado!$C$5:$C$1000="Comité de Supervisión")*((($C$2="Todos")+(Consolidado!$I$5:$I$1000&""=$C$2&""))>0)) -> 0 | H14: =SUMPRODUCT((Consolidado!$E$5:$E$1000=$B14)*(Consolidado!$C$5:$C$1000="Consejo de Administración")*((($C$2="Todos")+(Consolidado!$I$5:$I$1000&""=$C$2&""))>0)) -> 0 | I14: =SUMPRODUCT((Consolidado!$E$5:$E$1000=$B14)*(Consolidado!$C$5:$C$1000="Otros")*((($C$2="Todos")+(Consolidado!$I$5:$I$1000&""=$C$2&""))>0)) -> 0 | J14: =SUM(D14:I14) -> 1 | K14: =SUMPRODUCT((Consolidado!$E$5:$E$1000=$B14)*(Consolidado!$AE$5:$AE$1000)*((($C$2="Todos")+(Consolidado!$I$5:$I$1000&""=$C$2&""))>0)) -> 1 | L14: =COUNTIF(D14:I14,">0") -> 1 | M14: =IF(L14>=2,"Sí","No") -> No | N14: =IF(J14=0,"",RANK(J14,$J$5:$J$33)) -> 17 | O14: =SUMPRODUCT((Consolidado!$E$5:$E$1000=$B14)*(MONTH(Consolidado!$B$5:$B$1000+0*(Consolidado!$B$5:$B$1000=""))=1)*(Consolidado!$B$5:$B$1000<>"")*((($C$2="Todos")+(Consolidado!$I$5:$I$1000&""=$C$2&""))>0)) -> 0 | P14: =SUMPRODUCT((Consolidado!$E$5:$E$1000=$B14)*(MONTH(Consolidado!$B$5:$B$1000+0*(Consolidado!$B$5:$B$1000=""))=2)*(Consolidado!$B$5:$B$1000<>"")*((($C$2="Todos")+(Consolidado!$I$5:$I$1000&""=$C$2&""))>0)) -> 0 | Q14: =SUMPRODUCT((Consolidado!$E$5:$E$1000=$B14)*(MONTH(Consolidado!$B$5:$B$1000+0*(Consolidado!$B$5:$B$1000=""))=3)*(Consolidado!$B$5:$B$1000<>"")*((($C$2="Todos")+(Consolidado!$I$5:$I$1000&""=$C$2&""))>0)) -> 0 | R14: =SUMPRODUCT((Consolidado!$E$5:$E$1000=$B14)*(MONTH(Consolidado!$B$5:$B$1000+0*(Consolidado!$B$5:$B$1000=""))=4)*(Consolidado!$B$5:$B$1000<>"")*((($C$2="Todos")+(Consolidado!$I$5:$I$1000&""=$C$2&""))>0)) -> 0 | S14: =SUMPRODUCT((Consolidado!$E$5:$E$1000=$B14)*(MONTH(Consolidado!$B$5:$B$1000+0*(Consolidado!$B$5:$B$1000=""))=5)*(Consolidado!$B$5:$B$1000<>"")*((($C$2="Todos")+(Consolidado!$I$5:$I$1000&""=$C$2&""))>0)) -> 1 | T14: =SUMPRODUCT((Consolidado!$E$5:$E$1000=$B14)*(MONTH(Consolidado!$B$5:$B$1000+0*(Consolidado!$B$5:$B$1000=""))=6)*(Consolidado!$B$5:$B$1000<>"")*((($C$2="Todos")+(Consolidado!$I$5:$I$1000&""=$C$2&""))>0)) -> 0 | U14: =SUMPRODUCT((Consolidado!$E$5:$E$1000=$B14)*(MONTH(Consolidado!$B$5:$B$1000+0*(Consolidado!$B$5:$B$1000=""))=7)*(Consolidado!$B$5:$B$1000<>"")*((($C$2="Todos")+(Consolidado!$I$5:$I$1000&""=$C$2&""))>0)) -> 0 | V14: =SUMPRODUCT((Consolidado!$E$5:$E$1000=$B14)*(MONTH(Consolidado!$B$5:$B$1000+0*(Consolidado!$B$5:$B$1000=""))=8)*(Consolidado!$B$5:$B$1000<>"")*((($C$2="Todos")+(Consolidado!$I$5:$I$1000&""=$C$2&""))>0)) -> 0 | W14: =SUMPRODUCT((Consolidado!$E$5:$E$1000=$B14)*(MONTH(Consolidado!$B$5:$B$1000+0*(Consolidado!$B$5:$B$1000=""))=9)*(Consolidado!$B$5:$B$1000<>"")*((($C$2="Todos")+(Consolidado!$I$5:$I$1000&""=$C$2&""))>0)) -> 0 | X14: =SUMPRODUCT((Consolidado!$E$5:$E$1000=$B14)*(MONTH(Consolidado!$B$5:$B$1000+0*(Consolidado!$B$5:$B$1000=""))=10)*(Consolidado!$B$5:$B$1000<>"")*((($C$2="Todos")+(Consolidado!$I$5:$I$1000&""=$C$2&""))>0)) -> 0 | Y14: =SUMPRODUCT((Consolidado!$E$5:$E$1000=$B14)*(MONTH(Consolidado!$B$5:$B$1000+0*(Consolidado!$B$5:$B$1000=""))=11)*(Consolidado!$B$5:$B$1000<>"")*((($C$2="Todos")+(Consolidado!$I$5:$I$1000&""=$C$2&""))>0)) -> 0 | Z14: =SUMPRODUCT((Consolidado!$E$5:$E$1000=$B14)*(MONTH(Consolidado!$B$5:$B$1000+0*(Consolidado!$B$5:$B$1000=""))=12)*(Consolidado!$B$5:$B$1000<>"")*((($C$2="Todos")+(Consolidado!$I$5:$I$1000&""=$C$2&""))>0)) -> 0
A15: 11 | B15: =Catálogos!C12 -> Matriz de migración / bases de cartera | C15: =Catálogos!D12 -> NCB-022 | D15: =SUMPRODUCT((Consolidado!$E$5:$E$1000=$B15)*(Consolidado!$C$5:$C$1000="Auditoría Interna")*((($C$2="Todos")+(Consolidado!$I$5:$I$1000&""=$C$2&""))>0)) -> 1 | E15: =SUMPRODUCT((Consolidado!$E$5:$E$1000=$B15)*(Consolidado!$C$5:$C$1000="Auditoría Externa")*((($C$2="Todos")+(Consolidado!$I$5:$I$1000&""=$C$2&""))>0)) -> 0 | F15: =SUMPRODUCT((Consolidado!$E$5:$E$1000=$B15)*(Consolidado!$C$5:$C$1000="SSF")*((($C$2="Todos")+(Consolidado!$I$5:$I$1000&""=$C$2&""))>0)) -> 0 | G15: =SUMPRODUCT((Consolidado!$E$5:$E$1000=$B15)*(Consolidado!$C$5:$C$1000="Comité de Supervisión")*((($C$2="Todos")+(Consolidado!$I$5:$I$1000&""=$C$2&""))>0)) -> 0 | H15: =SUMPRODUCT((Consolidado!$E$5:$E$1000=$B15)*(Consolidado!$C$5:$C$1000="Consejo de Administración")*((($C$2="Todos")+(Consolidado!$I$5:$I$1000&""=$C$2&""))>0)) -> 0 | I15: =SUMPRODUCT((Consolidado!$E$5:$E$1000=$B15)*(Consolidado!$C$5:$C$1000="Otros")*((($C$2="Todos")+(Consolidado!$I$5:$I$1000&""=$C$2&""))>0)) -> 0 | J15: =SUM(D15:I15) -> 1 | K15: =SUMPRODUCT((Consolidado!$E$5:$E$1000=$B15)*(Consolidado!$AE$5:$AE$1000)*((($C$2="Todos")+(Consolidado!$I$5:$I$1000&""=$C$2&""))>0)) -> 1 | L15: =COUNTIF(D15:I15,">0") -> 1 | M15: =IF(L15>=2,"Sí","No") -> No | N15: =IF(J15=0,"",RANK(J15,$J$5:$J$33)) -> 17 | O15: =SUMPRODUCT((Consolidado!$E$5:$E$1000=$B15)*(MONTH(Consolidado!$B$5:$B$1000+0*(Consolidado!$B$5:$B$1000=""))=1)*(Consolidado!$B$5:$B$1000<>"")*((($C$2="Todos")+(Consolidado!$I$5:$I$1000&""=$C$2&""))>0)) -> 0 | P15: =SUMPRODUCT((Consolidado!$E$5:$E$1000=$B15)*(MONTH(Consolidado!$B$5:$B$1000+0*(Consolidado!$B$5:$B$1000=""))=2)*(Consolidado!$B$5:$B$1000<>"")*((($C$2="Todos")+(Consolidado!$I$5:$I$1000&""=$C$2&""))>0)) -> 0 | Q15: =SUMPRODUCT((Consolidado!$E$5:$E$1000=$B15)*(MONTH(Consolidado!$B$5:$B$1000+0*(Consolidado!$B$5:$B$1000=""))=3)*(Consolidado!$B$5:$B$1000<>"")*((($C$2="Todos")+(Consolidado!$I$5:$I$1000&""=$C$2&""))>0)) -> 0 | R15: =SUMPRODUCT((Consolidado!$E$5:$E$1000=$B15)*(MONTH(Consolidado!$B$5:$B$1000+0*(Consolidado!$B$5:$B$1000=""))=4)*(Consolidado!$B$5:$B$1000<>"")*((($C$2="Todos")+(Consolidado!$I$5:$I$1000&""=$C$2&""))>0)) -> 0 | S15: =SUMPRODUCT((Consolidado!$E$5:$E$1000=$B15)*(MONTH(Consolidado!$B$5:$B$1000+0*(Consolidado!$B$5:$B$1000=""))=5)*(Consolidado!$B$5:$B$1000<>"")*((($C$2="Todos")+(Consolidado!$I$5:$I$1000&""=$C$2&""))>0)) -> 1 | T15: =SUMPRODUCT((Consolidado!$E$5:$E$1000=$B15)*(MONTH(Consolidado!$B$5:$B$1000+0*(Consolidado!$B$5:$B$1000=""))=6)*(Consolidado!$B$5:$B$1000<>"")*((($C$2="Todos")+(Consolidado!$I$5:$I$1000&""=$C$2&""))>0)) -> 0 | U15: =SUMPRODUCT((Consolidado!$E$5:$E$1000=$B15)*(MONTH(Consolidado!$B$5:$B$1000+0*(Consolidado!$B$5:$B$1000=""))=7)*(Consolidado!$B$5:$B$1000<>"")*((($C$2="Todos")+(Consolidado!$I$5:$I$1000&""=$C$2&""))>0)) -> 0 | V15: =SUMPRODUCT((Consolidado!$E$5:$E$1000=$B15)*(MONTH(Consolidado!$B$5:$B$1000+0*(Consolidado!$B$5:$B$1000=""))=8)*(Consolidado!$B$5:$B$1000<>"")*((($C$2="Todos")+(Consolidado!$I$5:$I$1000&""=$C$2&""))>0)) -> 0 | W15: =SUMPRODUCT((Consolidado!$E$5:$E$1000=$B15)*(MONTH(Consolidado!$B$5:$B$1000+0*(Consolidado!$B$5:$B$1000=""))=9)*(Consolidado!$B$5:$B$1000<>"")*((($C$2="Todos")+(Consolidado!$I$5:$I$1000&""=$C$2&""))>0)) -> 0 | X15: =SUMPRODUCT((Consolidado!$E$5:$E$1000=$B15)*(MONTH(Consolidado!$B$5:$B$1000+0*(Consolidado!$B$5:$B$1000=""))=10)*(Consolidado!$B$5:$B$1000<>"")*((($C$2="Todos")+(Consolidado!$I$5:$I$1000&""=$C$2&""))>0)) -> 0 | Y15: =SUMPRODUCT((Consolidado!$E$5:$E$1000=$B15)*(MONTH(Consolidado!$B$5:$B$1000+0*(Consolidado!$B$5:$B$1000=""))=11)*(Consolidado!$B$5:$B$1000<>"")*((($C$2="Todos")+(Consolidado!$I$5:$I$1000&""=$C$2&""))>0)) -> 0 | Z15: =SUMPRODUCT((Consolidado!$E$5:$E$1000=$B15)*(MONTH(Consolidado!$B$5:$B$1000+0*(Consolidado!$B$5:$B$1000=""))=12)*(Consolidado!$B$5:$B$1000<>"")*((($C$2="Todos")+(Consolidado!$I$5:$I$1000&""=$C$2&""))>0)) -> 0
A16: 12 | B16: =Catálogos!C13 -> Remisiones a SSF / central de riesgos | C16: =Catálogos!D13 -> NCB-022 | D16: =SUMPRODUCT((Consolidado!$E$5:$E$1000=$B16)*(Consolidado!$C$5:$C$1000="Auditoría Interna")*((($C$2="Todos")+(Consolidado!$I$5:$I$1000&""=$C$2&""))>0)) -> 2 | E16: =SUMPRODUCT((Consolidado!$E$5:$E$1000=$B16)*(Consolidado!$C$5:$C$1000="Auditoría Externa")*((($C$2="Todos")+(Consolidado!$I$5:$I$1000&""=$C$2&""))>0)) -> 1 | F16: =SUMPRODUCT((Consolidado!$E$5:$E$1000=$B16)*(Consolidado!$C$5:$C$1000="SSF")*((($C$2="Todos")+(Consolidado!$I$5:$I$1000&""=$C$2&""))>0)) -> 0 | G16: =SUMPRODUCT((Consolidado!$E$5:$E$1000=$B16)*(Consolidado!$C$5:$C$1000="Comité de Supervisión")*((($C$2="Todos")+(Consolidado!$I$5:$I$1000&""=$C$2&""))>0)) -> 0 | H16: =SUMPRODUCT((Consolidado!$E$5:$E$1000=$B16)*(Consolidado!$C$5:$C$1000="Consejo de Administración")*((($C$2="Todos")+(Consolidado!$I$5:$I$1000&""=$C$2&""))>0)) -> 0 | I16: =SUMPRODUCT((Consolidado!$E$5:$E$1000=$B16)*(Consolidado!$C$5:$C$1000="Otros")*((($C$2="Todos")+(Consolidado!$I$5:$I$1000&""=$C$2&""))>0)) -> 0 | J16: =SUM(D16:I16) -> 3 | K16: =SUMPRODUCT((Consolidado!$E$5:$E$1000=$B16)*(Consolidado!$AE$5:$AE$1000)*((($C$2="Todos")+(Consolidado!$I$5:$I$1000&""=$C$2&""))>0)) -> 2 | L16: =COUNTIF(D16:I16,">0") -> 2 | M16: =IF(L16>=2,"Sí","No") -> Sí | N16: =IF(J16=0,"",RANK(J16,$J$5:$J$33)) -> 8 | O16: =SUMPRODUCT((Consolidado!$E$5:$E$1000=$B16)*(MONTH(Consolidado!$B$5:$B$1000+0*(Consolidado!$B$5:$B$1000=""))=1)*(Consolidado!$B$5:$B$1000<>"")*((($C$2="Todos")+(Consolidado!$I$5:$I$1000&""=$C$2&""))>0)) -> 0 | P16: =SUMPRODUCT((Consolidado!$E$5:$E$1000=$B16)*(MONTH(Consolidado!$B$5:$B$1000+0*(Consolidado!$B$5:$B$1000=""))=2)*(Consolidado!$B$5:$B$1000<>"")*((($C$2="Todos")+(Consolidado!$I$5:$I$1000&""=$C$2&""))>0)) -> 0 | Q16: =SUMPRODUCT((Consolidado!$E$5:$E$1000=$B16)*(MONTH(Consolidado!$B$5:$B$1000+0*(Consolidado!$B$5:$B$1000=""))=3)*(Consolidado!$B$5:$B$1000<>"")*((($C$2="Todos")+(Consolidado!$I$5:$I$1000&""=$C$2&""))>0)) -> 0 | R16: =SUMPRODUCT((Consolidado!$E$5:$E$1000=$B16)*(MONTH(Consolidado!$B$5:$B$1000+0*(Consolidado!$B$5:$B$1000=""))=4)*(Consolidado!$B$5:$B$1000<>"")*((($C$2="Todos")+(Consolidado!$I$5:$I$1000&""=$C$2&""))>0)) -> 0 | S16: =SUMPRODUCT((Consolidado!$E$5:$E$1000=$B16)*(MONTH(Consolidado!$B$5:$B$1000+0*(Consolidado!$B$5:$B$1000=""))=5)*(Consolidado!$B$5:$B$1000<>"")*((($C$2="Todos")+(Consolidado!$I$5:$I$1000&""=$C$2&""))>0)) -> 2 | T16: =SUMPRODUCT((Consolidado!$E$5:$E$1000=$B16)*(MONTH(Consolidado!$B$5:$B$1000+0*(Consolidado!$B$5:$B$1000=""))=6)*(Consolidado!$B$5:$B$1000<>"")*((($C$2="Todos")+(Consolidado!$I$5:$I$1000&""=$C$2&""))>0)) -> 0 | U16: =SUMPRODUCT((Consolidado!$E$5:$E$1000=$B16)*(MONTH(Consolidado!$B$5:$B$1000+0*(Consolidado!$B$5:$B$1000=""))=7)*(Consolidado!$B$5:$B$1000<>"")*((($C$2="Todos")+(Consolidado!$I$5:$I$1000&""=$C$2&""))>0)) -> 0 | V16: =SUMPRODUCT((Consolidado!$E$5:$E$1000=$B16)*(MONTH(Consolidado!$B$5:$B$1000+0*(Consolidado!$B$5:$B$1000=""))=8)*(Consolidado!$B$5:$B$1000<>"")*((($C$2="Todos")+(Consolidado!$I$5:$I$1000&""=$C$2&""))>0)) -> 0 | W16: =SUMPRODUCT((Consolidado!$E$5:$E$1000=$B16)*(MONTH(Consolidado!$B$5:$B$1000+0*(Consolidado!$B$5:$B$1000=""))=9)*(Consolidado!$B$5:$B$1000<>"")*((($C$2="Todos")+(Consolidado!$I$5:$I$1000&""=$C$2&""))>0)) -> 0 | X16: =SUMPRODUCT((Consolidado!$E$5:$E$1000=$B16)*(MONTH(Consolidado!$B$5:$B$1000+0*(Consolidado!$B$5:$B$1000=""))=10)*(Consolidado!$B$5:$B$1000<>"")*((($C$2="Todos")+(Consolidado!$I$5:$I$1000&""=$C$2&""))>0)) -> 1 | Y16: =SUMPRODUCT((Consolidado!$E$5:$E$1000=$B16)*(MONTH(Consolidado!$B$5:$B$1000+0*(Consolidado!$B$5:$B$1000=""))=11)*(Consolidado!$B$5:$B$1000<>"")*((($C$2="Todos")+(Consolidado!$I$5:$I$1000&""=$C$2&""))>0)) -> 0 | Z16: =SUMPRODUCT((Consolidado!$E$5:$E$1000=$B16)*(MONTH(Consolidado!$B$5:$B$1000+0*(Consolidado!$B$5:$B$1000=""))=12)*(Consolidado!$B$5:$B$1000<>"")*((($C$2="Todos")+(Consolidado!$I$5:$I$1000&""=$C$2&""))>0)) -> 0
... A33: 29 | B33: =Catálogos!C30 -> Declaraciones juradas | C33: =Catálogos!D30 -> Ley Bancos Coop. Art. 15 | D33: =SUMPRODUCT((Consolidado!$E$5:$E$1000=$B33)*(Consolidado!$C$5:$C$1000="Auditoría Interna")*((($C$2="Todos")+(Consolidado!$I$5:$I$1000&""=$C$2&""))>0)) -> 0 | E33: =SUMPRODUCT((Consolidado!$E$5:$E$1000=$B33)*(Consolidado!$C$5:$C$1000="Auditoría Externa")*((($C$2="Todos")+(Consolidado!$I$5:$I$1000&""=$C$2&""))>0)) -> 0 | F33: =SUMPRODUCT((Consolidado!$E$5:$E$1000=$B33)*(Consolidado!$C$5:$C$1000="SSF")*((($C$2="Todos")+(Consolidado!$I$5:$I$1000&""=$C$2&""))>0)) -> 1 | G33: =SUMPRODUCT((Consolidado!$E$5:$E$1000=$B33)*(Consolidado!$C$5:$C$1000="Comité de Supervisión")*((($C$2="Todos")+(Consolidado!$I$5:$I$1000&""=$C$2&""))>0)) -> 0 | H33: =SUMPRODUCT((Consolidado!$E$5:$E$1000=$B33)*(Consolidado!$C$5:$C$1000="Consejo de Administración")*((($C$2="Todos")+(Consolidado!$I$5:$I$1000&""=$C$2&""))>0)) -> 0 | I33: =SUMPRODUCT((Consolidado!$E$5:$E$1000=$B33)*(Consolidado!$C$5:$C$1000="Otros")*((($C$2="Todos")+(Consolidado!$I$5:$I$1000&""=$C$2&""))>0)) -> 0 | J33: =SUM(D33:I33) -> 1 | K33: =SUMPRODUCT((Consolidado!$E$5:$E$1000=$B33)*(Consolidado!$AE$5:$AE$1000)*((($C$2="Todos")+(Consolidado!$I$5:$I$1000&""=$C$2&""))>0)) -> 1 | L33: =COUNTIF(D33:I33,">0") -> 1 | M33: =IF(L33>=2,"Sí","No") -> No | N33: =IF(J33=0,"",RANK(J33,$J$5:$J$33)) -> 17 | O33: =SUMPRODUCT((Consolidado!$E$5:$E$1000=$B33)*(MONTH(Consolidado!$B$5:$B$1000+0*(Consolidado!$B$5:$B$1000=""))=1)*(Consolidado!$B$5:$B$1000<>"")*((($C$2="Todos")+(Consolidado!$I$5:$I$1000&""=$C$2&""))>0)) -> 0 | P33: =SUMPRODUCT((Consolidado!$E$5:$E$1000=$B33)*(MONTH(Consolidado!$B$5:$B$1000+0*(Consolidado!$B$5:$B$1000=""))=2)*(Consolidado!$B$5:$B$1000<>"")*((($C$2="Todos")+(Consolidado!$I$5:$I$1000&""=$C$2&""))>0)) -> 0 | Q33: =SUMPRODUCT((Consolidado!$E$5:$E$1000=$B33)*(MONTH(Consolidado!$B$5:$B$1000+0*(Consolidado!$B$5:$B$1000=""))=3)*(Consolidado!$B$5:$B$1000<>"")*((($C$2="Todos")+(Consolidado!$I$5:$I$1000&""=$C$2&""))>0)) -> 0 | R33: =SUMPRODUCT((Consolidado!$E$5:$E$1000=$B33)*(MONTH(Consolidado!$B$5:$B$1000+0*(Consolidado!$B$5:$B$1000=""))=4)*(Consolidado!$B$5:$B$1000<>"")*((($C$2="Todos")+(Consolidado!$I$5:$I$1000&""=$C$2&""))>0)) -> 0 | S33: =SUMPRODUCT((Consolidado!$E$5:$E$1000=$B33)*(MONTH(Consolidado!$B$5:$B$1000+0*(Consolidado!$B$5:$B$1000=""))=5)*(Consolidado!$B$5:$B$1000<>"")*((($C$2="Todos")+(Consolidado!$I$5:$I$1000&""=$C$2&""))>0)) -> 0 | T33: =SUMPRODUCT((Consolidado!$E$5:$E$1000=$B33)*(MONTH(Consolidado!$B$5:$B$1000+0*(Consolidado!$B$5:$B$1000=""))=6)*(Consolidado!$B$5:$B$1000<>"")*((($C$2="Todos")+(Consolidado!$I$5:$I$1000&""=$C$2&""))>0)) -> 0 | U33: =SUMPRODUCT((Consolidado!$E$5:$E$1000=$B33)*(MONTH(Consolidado!$B$5:$B$1000+0*(Consolidado!$B$5:$B$1000=""))=7)*(Consolidado!$B$5:$B$1000<>"")*((($C$2="Todos")+(Consolidado!$I$5:$I$1000&""=$C$2&""))>0)) -> 1 | V33: =SUMPRODUCT((Consolidado!$E$5:$E$1000=$B33)*(MONTH(Consolidado!$B$5:$B$1000+0*(Consolidado!$B$5:$B$1000=""))=8)*(Consolidado!$B$5:$B$1000<>"")*((($C$2="Todos")+(Consolidado!$I$5:$I$1000&""=$C$2&""))>0)) -> 0 | W33: =SUMPRODUCT((Consolidado!$E$5:$E$1000=$B33)*(MONTH(Consolidado!$B$5:$B$1000+0*(Consolidado!$B$5:$B$1000=""))=9)*(Consolidado!$B$5:$B$1000<>"")*((($C$2="Todos")+(Consolidado!$I$5:$I$1000&""=$C$2&""))>0)) -> 0 | X33: =SUMPRODUCT((Consolidado!$E$5:$E$1000=$B33)*(MONTH(Consolidado!$B$5:$B$1000+0*(Consolidado!$B$5:$B$1000=""))=10)*(Consolidado!$B$5:$B$1000<>"")*((($C$2="Todos")+(Consolidado!$I$5:$I$1000&""=$C$2&""))>0)) -> 0 | Y33: =SUMPRODUCT((Consolidado!$E$5:$E$1000=$B33)*(MONTH(Consolidado!$B$5:$B$1000+0*(Consolidado!$B$5:$B$1000=""))=11)*(Consolidado!$B$5:$B$1000<>"")*((($C$2="Todos")+(Consolidado!$I$5:$I$1000&""=$C$2&""))>0)) -> 0 | Z33: =SUMPRODUCT((Consolidado!$E$5:$E$1000=$B33)*(MONTH(Consolidado!$B$5:$B$1000+0*(Consolidado!$B$5:$B$1000=""))=12)*(Consolidado!$B$5:$B$1000<>"")*((($C$2="Todos")+(Consolidado!$I$5:$I$1000&""=$C$2&""))>0)) -> 0
B34: TOTAL | D34: =SUM(D5:D33) -> 52 | E34: =SUM(E5:E33) -> 15 | F34: =SUM(F5:F33) -> 23 | G34: =SUM(G5:G33) -> 0 | H34: =SUM(H5:H33) -> 0 | I34: =SUM(I5:I33) -> 0 | J34: =SUM(J5:J33) -> 90 | K34: =SUM(K5:K33) -> 51 | L34: =SUM(L5:L33) -> 39 | M34: =COUNTIF(M5:M33,"Sí")&" repetidos" -> 8 repetidos | O34: =SUM(O5:O33) -> 2 | P34: =SUM(P5:P33) -> 3 | Q34: =SUM(Q5:Q33) -> 1 | R34: =SUM(R5:R33) -> 4 | S34: =SUM(S5:S33) -> 12 | T34: =SUM(T5:T33) -> 1 | U34: =SUM(U5:U33) -> 2 | V34: =SUM(V5:V33) -> 26 | ... Z34: =SUM(Z5:Z33) -> 0
A36: Notas:
A37: • Los conteos salen de la hoja Consolidado; cada requerimiento se agrupa en un solo "Tema" (columna E). Si un requerimiento cubre dos temas, se asignó al principal.
A38: • "Total Veces" cuenta ítems pedidos; "Auditorías / visitas distintas" cuenta cuántas auditorías o visitas diferentes tocaron el tema (p. ej., Continuidad: 18 ítems de una sola auditoría interna).
A39: • Columnas Ene–Dic: mes de recepción del requerimiento, del año elegido en C2 (con "Todos" se suman todos los años).
A40: • SSF: se omitieron 6 filas repetidas en la hoja "Resumen visita presencialSSF" (filas 21, 23, 25, 26, 27 y 30 de esa hoja).
A41: • Auditoría Interna 3 (NRP-24) no trae fecha; se usó 12/10/2026, la fecha del título de esa matriz. La visita SSF de seguimiento NRP-32 no trae fecha y no cuenta en los meses.
A42: • La norma por tema es una referencia; las marcadas "Por validar" deben confirmarse. Puede editarlas en la hoja Catálogos.

Sheet Cruce
A1: ¿QUIÉN MÁS ME PIDIÓ LO MISMO? – CRUCE DE UN REQUERIMIENTO
A2: Escriba en la celda amarilla el N° del requerimiento (columna A de la hoja Consolidado). Abajo verá todos los que piden el mismo tema, de qué origen y en qué mes.
B3: N° en Consolidado | C3: 53 | K3: Veces que me piden este tema
B4: Origen | C4: =IFERROR(INDEX(Consolidado!$C$5:$C$1000,MATCH($C$3,Consolidado!$A$5:$A$1000,0)),"") -> SSF | K4: Interna | M4: =IF($C$5="",0,COUNTIFS(Consolidado!$E$5:$E$1000,$C$5,Consolidado!$C$5:$C$1000,"Auditoría Interna")) -> 6
B5: Tema | C5: =IFERROR(INDEX(Consolidado!$E$5:$E$1000,MATCH($C$3,Consolidado!$A$5:$A$1000,0)),"") -> Gobierno Corporativo | K5: Externa | M5: =IF($C$5="",0,COUNTIFS(Consolidado!$E$5:$E$1000,$C$5,Consolidado!$C$5:$C$1000,"Auditoría Externa")) -> 0
B6: Fecha recibida | C6: =IFERROR(INDEX(Consolidado!$B$5:$B$1000,MATCH($C$3,Consolidado!$A$5:$A$1000,0)),"") -> 46255 | K6: SSF | M6: =IF($C$5="",0,COUNTIFS(Consolidado!$E$5:$E$1000,$C$5,Consolidado!$C$5:$C$1000,"SSF")) -> 2
B7: Norma | C7: =IFERROR(INDEX(Consolidado!$D$5:$D$1000,MATCH($C$3,Consolidado!$A$5:$A$1000,0)),"") -> NRP-17 | K7: Comité Sup. | M7: =IF($C$5="",0,COUNTIFS(Consolidado!$E$5:$E$1000,$C$5,Consolidado!$C$5:$C$1000,"Comité de Supervisión")) -> 0
B8: Requerimiento | C8: =IFERROR(INDEX(Consolidado!$F$5:$F$1000,MATCH($C$3,Consolidado!$A$5:$A$1000,0)),"") -> Visita de supervisión ampliada para evaluar el Gobierno Corporativo. SABAO-BCS-BC-18432 | K8: Consejo | M8: =IF($C$5="",0,COUNTIFS(Consolidado!$E$5:$E$1000,$C$5,Consolidado!$C$5:$C$1000,"Consejo de Administración")) -> 0
K9: Otros | M9: =IF($C$5="",0,COUNTIFS(Consolidado!$E$5:$E$1000,$C$5,Consolidado!$C$5:$C$1000,"Otros")) -> 0
K10: Total | M10: =SUM(M4:M9) -> 8
K11: Otros orígenes en el MISMO mes | M11: =IFERROR(INDEX(Consolidado!$X$5:$X$1000,MATCH($C$3,Consolidado!$A$5:$A$1000,0)),"") -> 6
A13: # | B13: N° | C13: Origen | D13: Fecha | E13: Mes | F13: Año | G13: Relación con el seleccionado | H13: Requerimiento | I13: Responsable | J13: Estado
A14: =IF(B14="","",1) -> 1 | B14: =IFERROR(INDEX(Consolidado!$A$5:$A$1000,MATCH(1,Consolidado!$AC$5:$AC$1000,0)),"") -> 8 | C14: =IFERROR(INDEX(Consolidado!$C$5:$C$1000,MATCH(1,Consolidado!$AC$5:$AC$1000,0))&"","") -> SSF | D14: =IFERROR(INDEX(Consolidado!$B$5:$B$1000,MATCH(1,Consolidado!$AC$5:$AC$1000,0)),"") -> 45796 | E14: =IF(OR(D14="",D14=0),"",CHOOSE(MONTH(D14),"Ene","Feb","Mar","Abr","May","Jun","Jul","Ago","Sep","Oct","Nov","Dic")) -> May | F14: =IF(OR(D14="",D14=0),"",YEAR(D14)) -> 2025 | G14: =IF(B14="","",IF(B14=$C$3,"◄ SELECCIONADO",IF(OR(D14="",D14=0,$C$6="",$C$6=0),"Sin fecha",IF(AND(YEAR(D14)=YEAR($C$6),MONTH(D14)=MONTH($C$6)),"MISMO MES",ABS((YEAR(D14)-YEAR($C$6))*12+MONTH(D14)-MONTH($C$6))&" meses "&IF(D14<$C$6,"antes","después"))))) -> 15 meses antes | H14: =IFERROR(INDEX(Consolidado!$F$5:$F$1000,MATCH(1,Consolidado!$AC$5:$AC$1000,0))&"","") -> Visita de supervision ampliada para evaluar el Gobierno Corporativo SABAO- BCS- BC-9337 | I14: =IFERROR(INDEX(Consolidado!$G$5:$G$1000,MATCH(1,Consolidado!$AC$5:$AC$1000,0))&"","") | J14: =IFERROR(INDEX(Consolidado!$H$5:$H$1000,MATCH(1,Consolidado!$AC$5:$AC$1000,0))&"","")
A15: =IF(B15="","",2) -> 2 | B15: =IFERROR(INDEX(Consolidado!$A$5:$A$1000,MATCH(2,Consolidado!$AC$5:$AC$1000,0)),"") -> 39 | C15: =IFERROR(INDEX(Consolidado!$C$5:$C$1000,MATCH(2,Consolidado!$AC$5:$AC$1000,0))&"","") -> Auditoría Interna | D15: =IFERROR(INDEX(Consolidado!$B$5:$B$1000,MATCH(2,Consolidado!$AC$5:$AC$1000,0)),"") -> 46249 | E15: =IF(OR(D15="",D15=0),"",CHOOSE(MONTH(D15),"Ene","Feb","Mar","Abr","May","Jun","Jul","Ago","Sep","Oct","Nov","Dic")) -> Ago | F15: =IF(OR(D15="",D15=0),"",YEAR(D15)) -> 2026 | G15: =IF(B15="","",IF(B15=$C$3,"◄ SELECCIONADO",IF(OR(D15="",D15=0,$C$6="",$C$6=0),"Sin fecha",IF(AND(YEAR(D15)=YEAR($C$6),MONTH(D15)=MONTH($C$6)),"MISMO MES",ABS((YEAR(D15)-YEAR($C$6))*12+MONTH(D15)-MONTH($C$6))&" meses "&IF(D15<$C$6,"antes","después"))))) -> MISMO MES | H15: =IFERROR(INDEX(Consolidado!$F$5:$F$1000,MATCH(2,Consolidado!$AC$5:$AC$1000,0))&"","") -> Informe anual de gobierno corporativo remisión y recepción de la SSF (ejecución de enero a marzo 2026) | I15: =IFERROR(INDEX(Consolidado!$G$5:$G$1000,MATCH(2,Consolidado!$AC$5:$AC$1000,0))&"","") -> Silvita | J15: =IFERROR(INDEX(Consolidado!$H$5:$H$1000,MATCH(2,Consolidado!$AC$5:$AC$1000,0))&"","")
A16: =IF(B16="","",3) -> 3 | B16: =IFERROR(INDEX(Consolidado!$A$5:$A$1000,MATCH(3,Consolidado!$AC$5:$AC$1000,0)),"") -> 40 | C16: =IFERROR(INDEX(Consolidado!$C$5:$C$1000,MATCH(3,Consolidado!$AC$5:$AC$1000,0))&"","") -> Auditoría Interna | D16: =IFERROR(INDEX(Consolidado!$B$5:$B$1000,MATCH(3,Consolidado!$AC$5:$AC$1000,0)),"") -> 46249 | E16: =IF(OR(D16="",D16=0),"",CHOOSE(MONTH(D16),"Ene","Feb","Mar","Abr","May","Jun","Jul","Ago","Sep","Oct","Nov","Dic")) -> Ago | F16: =IF(OR(D16="",D16=0),"",YEAR(D16)) -> 2026 | G16: =IF(B16="","",IF(B16=$C$3,"◄ SELECCIONADO",IF(OR(D16="",D16=0,$C$6="",$C$6=0),"Sin fecha",IF(AND(YEAR(D16)=YEAR($C$6),MONTH(D16)=MONTH($C$6)),"MISMO MES",ABS((YEAR(D16)-YEAR($C$6))*12+MONTH(D16)-MONTH($C$6))&" meses "&IF(D16<$C$6,"antes","después"))))) -> MISMO MES | H16: =IFERROR(INDEX(Consolidado!$F$5:$F$1000,MATCH(3,Consolidado!$AC$5:$AC$1000,0))&"","") -> Remisión de anexo 2 información de gobierno corporativo desagregada por sexo los primeros 30 días posteriores a cada semestre (Ejecución en Julio 2025, Enero y julio 2026) | I16: =IFERROR(INDEX(Consolidado!$G$5:$G$1000,MATCH(3,Consolidado!$AC$5:$AC$1000,0))&"","") | J16: =IFERROR(INDEX(Consolidado!$H$5:$H$1000,MATCH(3,Consolidado!$AC$5:$AC$1000,0))&"","")
A17: =IF(B17="","",4) -> 4 | B17: =IFERROR(INDEX(Consolidado!$A$5:$A$1000,MATCH(4,Consolidado!$AC$5:$AC$1000,0)),"") -> 41 | C17: =IFERROR(INDEX(Consolidado!$C$5:$C$1000,MATCH(4,Consolidado!$AC$5:$AC$1000,0))&"","") -> Auditoría Interna | D17: =IFERROR(INDEX(Consolidado!$B$5:$B$1000,MATCH(4,Consolidado!$AC$5:$AC$1000,0)),"") -> 46249 | E17: =IF(OR(D17="",D17=0),"",CHOOSE(MONTH(D17),"Ene","Feb","Mar","Abr","May","Jun","Jul","Ago","Sep","Oct","Nov","Dic")) -> Ago | F17: =IF(OR(D17="",D17=0),"",YEAR(D17)) -> 2026 | G17: =IF(B17="","",IF(B17=$C$3,"◄ SELECCIONADO",IF(OR(D17="",D17=0,$C$6="",$C$6=0),"Sin fecha",IF(AND(YEAR(D17)=YEAR($C$6),MONTH(D17)=MONTH($C$6)),"MISMO MES",ABS((YEAR(D17)-YEAR($C$6))*12+MONTH(D17)-MONTH($C$6))&" meses "&IF(D17<$C$6,"antes","después"))))) -> MISMO MES | H17: =IFERROR(INDEX(Consolidado!$F$5:$F$1000,MATCH(4,Consolidado!$AC$5:$AC$1000,0))&"","") -> Publicación en el sitio web de la información citada en el artículo 29 de la NRP-17 (ejecución de enero, marzo y julio 2026) | I17: =IFERROR(INDEX(Consolidado!$G$5:$G$1000,MATCH(4,Consolidado!$AC$5:$AC$1000,0))&"","") -> Silvita | J17: =IFERROR(INDEX(Consolidado!$H$5:$H$1000,MATCH(4,Consolidado!$AC$5:$AC$1000,0))&"","")
